Workbook

Sheet R_STUDIO EINGABE
A1: Number | B1: NAME | C1: Code | D1: YEAR | E1: ESGC | F1: NET INCOM | G1: EBITD | H1: EQUITY | I1: DEBT | J1: REVENUE | K1: RoA | L1: RoE | M1: ASSET | N1: MCCAP | O1: MB
A2: =VLOOKUP(C2,'PORTFOLIO RAW'!C:D,2,FALSE) -> 323 | B2: VRTX.O | C2: 545310 | D2: 2007 | E2: 46.309199 | F2: -391279 | G2: -361535 | H2: 271295 | I2: 19997 | J2: 199012 | K2: -51.19 | L2: -100.69 | M2: 601477 | N2: 3086699 | O2: 18.81
A3: =VLOOKUP(C3,'PORTFOLIO RAW'!C:D,2,FALSE) -> 7 | B3: AMD.O | C3: 936365 | D3: 2007 | E3: 66.492963 | F3: -3379000 | G3: -1494000 | H3: 2990000 | I3: 5269000 | J3: 6013000 | K3: -25.46 | L3: -77.01 | M3: 11523000 | N3: 4545000 | O3: 2.47
A4: =VLOOKUP(C4,'PORTFOLIO RAW'!C:D,2,FALSE) -> 232 | B4: MYL.O | C4: 906931 | D4: 2007 | E4: 39.734872 | F4: -1538695 | G4: -991803 | H4: 3402356 | I4: 5256449 | J4: 2905007 | K4: -20.63 | L4: -73.45 | M4: 11334473 | N4: 4279515 | O4: 1.12
A5: =VLOOKUP(C5,'PORTFOLIO RAW'!C:D,2,FALSE) -> 270 | B5: PHM | C5: 912518 | D5: 2007 | E5: 28.390501 | F5: -2274417 | G5: -1908031 | H5: 4320193 | I5: 4104542 | J5: 9263094 | K5: -17.74 | L5: -41.4 | M5: 10119797 | N5: 2709821 | O5: 0.95
A6: =VLOOKUP(C6,'PORTFOLIO RAW'!C:D,2,FALSE) -> 201 | B6: LEN | C6: 912219 | D6: 2007 | E6: 32.451224 | F6: -1941081 | G6: -2439945 | H6: 3822119 | I6: 2836873 | J6: 10186781 | K6: -17.67 | L6: -40.76 | M6: 8361149 | N6: 2860378 | O6: 1.07
A7: =VLOOKUP(C7,'PORTFOLIO RAW'!C:D,2,FALSE) -> 236 | B7: NEM | C7: 912160 | D7: 2007 | E7: 40.131477 | F7: -963000 | G7: 448000 | H7: 7548000 | I7: 2938000 | J7: 5526000 | K7: -12.38 | L7: -22.34 | M7: 14571000 | N7: 22105146 | O7: 2.81
A8: =VLOOKUP(C8,'PORTFOLIO RAW'!C:D,2,FALSE) -> 156 | B8: HRB | C8: 905596 | D8: 2007 | E8: 52.247727 | F8: -433653 | G8: 832933 | H8: 1414499 | I8: 2197293 | J8: 4021274 | K8: -5.98 | L8: -24.35 | M8: 7499493 | N8: 6002173 | O8: 6.84
A9: =VLOOKUP(C9,'PORTFOLIO RAW'!C:D,2,FALSE) -> 101 | B9: DHI | C9: 325922 | D9: 2007 | E9: 44.898601 | F9: -712500 | G9: -863200 | H9: 5586900 | I9: 4376800 | J9: 11296500 | K9: -5.55 | L9: -11.84 | M9: 10692500 | N9: 4147423 | O9: 0.79
A10: =VLOOKUP(C10,'PORTFOLIO RAW'!C:D,2,FALSE) -> 321 | B10: VRSN.O | C10: 674693 | D10: 2007 | E10: 32.069426 | F10: -140859 | G10: 121127 | H10: 1527865 | I10: 1265296 | J10: 1496289 | K10: -3.36 | L10: -7.15 | M10: 3792418 | N10: 8381364 | O10: 5.44
A11: =VLOOKUP(C11,'PORTFOLIO RAW'!C:D,2,FALSE) -> 187 | B11: JCI | C11: 545615 | D11: 2007 | E11: 77.544271 | F11: -2519000 | G11: -717000 | H11: 15624000 | I11: 4456000 | J11: 18781000 | K11: -3.3 | L11: -6.83 | M11: 31706000 | N11: 19678368 | O11: 1.42
A12: =VLOOKUP(C12,'PORTFOLIO RAW'!C:D,2,FALSE) -> 117 | B12: ETFC.O | C12: 883488 | D12: 2007 | E12: 49.936486 | F12: -1441754 | G12: -1887044 | H12: 2829065 | I12: 19401895 | J12: 2427286 | K12: -2.43 | L12: -41.04 | M12: 56295703 | N12: 1636187 | O12: 2.06
A13: =VLOOKUP(C13,'PORTFOLIO RAW'!C:D,2,FALSE) -> 223 | B13: MU.O | C13: 999506 | D13: 2007 | E13: 30.696688 | F13: -320000 | G13: 1590000 | H13: 7752000 | I13: 2544000 | J13: 5688000 | K13: -2.18 | L13: -4.03 | M13: 14753000 | N13: 5494775 | O13: 1.32
... A18: =VLOOKUP(C18,'PORTFOLIO RAW'!C:D,2,FALSE) -> 172 | B18: HBAN.O | C18: 951068 | D18: 2007 | E18: 36.710451 | F18: 75169 | G18: 427006 | H18: 5949140 | I18: 9798547 | J18: 3419566 | K18: 0.63 | L18: 1.68 | M18: 54697468 | N18: 5406022 | O18: 1.09
A19: =VLOOKUP(C19,'PORTFOLIO RAW'!C:D,2,FALSE) -> 263 | B19: PFG.O | C19: 14698C | D19: 2007 | E19: 34.242672 | F19: 807100 | G19: 1187600 | H19: 6854600 | I19: 1689600 | J19: 10800400 | K19: 0.63 | L19: 12.16 | M19: 154513700 | N19: 17836444 | O19: 2.32
A20: =VLOOKUP(C20,'PORTFOLIO RAW'!C:D,2,FALSE) -> 200 | B20: LEG | C20: 906487 | D20: 2007 | E20: 31.697727 | F20: 51000 | G20: 370400 | H20: 2132700 | I20: 1159300 | J20: 4306400 | K20: 0.65 | L20: -0.5 | M20: 4072500 | N20: 2942128 | O20: 1.59
A21: =VLOOKUP(C21,'PORTFOLIO RAW'!C:D,2,FALSE) -> 94 | B21: COO | C21: 938928 | D21: 2007 | E21: 42.179545 | F21: -11192 | G21: 126966 | H21: 1423589 | I21: 876630 | J21: 950641 | K21: 0.66 | L21: -0.8 | M21: 2540256 | N21: 1694116 | O21: 1.64
A22: =VLOOKUP(C22,'PORTFOLIO RAW'!C:D,2,FALSE) -> 81 | B22: C | C22: 741344 | D22: 2007 | E22: 42.623932 | F22: 3581000 | G22: 19813000 | H22: 113598000 | I22: 810759000 | J22: 159229000 | K22: 0.72 | L22: 3.08 | M22: 2187631000 | N22: 147041024 | O22: 2.07
A23: =VLOOKUP(C23,'PORTFOLIO RAW'!C:D,2,FALSE) -> 202 | B23: LNC | C23: 912402 | D23: 2007 | E23: 33.773253 | F23: 1321000 | G23: 2168000 | H23: 11579000 | I23: 5168000 | J23: 10594000 | K23: 0.81 | L23: 11.35 | M23: 191435000 | N23: 15383663 | O23: 1.52
A24: =VLOOKUP(C24,'PORTFOLIO RAW'!C:D,2,FALSE) -> 160 | B24: HIG | C24: 867871 | D24: 2007 | E24: 34.491325 | F24: 2949000 | G24: 5062000 | H24: 19563000 | I24: 5316000 | J24: 26399000 | K24: 0.91 | L24: 15.78 | M24: 360053000 | N24: 27363905 | O24: 1.47
A25: =VLOOKUP(C25,'PORTFOLIO RAW'!C:D,2,FALSE) -> 220 | B25: MET | C25: 286738 | D25: 2007 | E25: 29.15109 | F25: 4180000 | G25: 6543000 | H25: 32108000 | I25: 20501000 | J25: 51890000 | K25: 0.93 | L25: 12.9 | M25: 558562000 | N25: 44934748 | O25: 1.58
A26: =VLOOKUP(C26,'PORTFOLIO RAW'!C:D,2,FALSE) -> 25 | B26: AMP | C26: 31604H | D26: 2007 | E26: 54.302887 | F26: 814000 | G26: 2110000 | H26: 7810000 | I26: 2018000 | J26: 8909000 | K26: 0.99 | L26: 10.35 | M26: 109110000 | N26: 12551184 | O26: 1.85
A27: =VLOOKUP(C27,'PORTFOLIO RAW'!C:D,2,FALSE) -> 267 | B27: PRU | C27: 14861V | D27: 2007 | E27: 38.867331 | F27: 3704000 | G27: 6591000 | H27: 23057000 | I27: 47511000 | J27: 36034000 | K27: 1.02 | L27: 16.62 | M27: 485814000 | N27: 41809092 | O27: 1.86
A28: =VLOOKUP(C28,'PORTFOLIO RAW'!C:D,2,FALSE) -> 276 | B28: RF | C28: 951051 | D28: 2007 | E28: 41.784759 | F28: 1393163 | G28: 2620943 | H28: 19823029 | I28: 22444912 | J28: 10930498 | K28: 1.13 | L28: 6.17 | M28: 141041717 | N28: 16404491 | O28: 1.11
A29: =VLOOKUP(C29,'PORTFOLIO RAW'!C:D,2,FALSE) -> 296 | B29: STT | C29: 951052 | D29: 2007 | E29: 42.121227 | F29: 1261000 | G29: 2447000 | H29: 11299000 | I29: 24264000 | J29: 11818000 | K29: 1.13 | L29: 13.59 | M29: 142543000 | N29: 31366261 | O29: 2.29
A30: =VLOOKUP(C30,'PORTFOLIO RAW'!C:D,2,FALSE) -> 348 | B30: ZION.O | C30: 951584 | D30: 2007 | E30: 44.106225 | F30: 479422 | G30: 935352 | H30: 5052800 | I30: 10056547 | J30: 3775878 | K30: 1.19 | L30: 9.78 | M30: 52736159 | N30: 5001270 | O30: 1.51
A31: =VLOOKUP(C31,'PORTFOLIO RAW'!C:D,2,FALSE) -> 23 | B31: AIG | C31: 916305 | D31: 2007 | E31: 29.592648 | F31: 6200000 | G31: 21460000 | H31: 91513000 | I31: 176049000 | J31: 126251000 | K31: 1.23 | L31: 6.77 | M31: 1060505000 | N31: 147474750 | O31: 1.88
A32: =VLOOKUP(C32,'PORTFOLIO RAW'!C:D,2,FALSE) -> 254 | B32: PBCT.O | C32: 517465 | D32: 2007 | E32: 38.545229 | F32: 150700 | G32: 249900 | H32: 4445400 | I32: 65400 | J32: 892400 | K32: 1.28 | L32: 5.21 | M32: 13554800 | N32: 5309740 | O32: 1.18
A33: =VLOOKUP(C33,'PORTFOLIO RAW'!C:D,2,FALSE) -> 298 | B33: STI | C33: 922725 | D33: 2007 | E33: 44.531371 | F33: 1603740 | G33: 4033944 | H33: 17552518 | I33: 35157328 | J33: 13394224 | K33: 1.29 | L33: 9.2 | M33: 179573933 | N33: 21772214 | O33: 1.56
A34: =VLOOKUP(C34,'PORTFOLIO RAW'!C:D,2,FALSE) -> 47 | B34: BAC | C34: 923937 | D34: 2007 | E34: 44.270765 | F34: 14800000 | G34: 31451000 | H34: 142394000 | I34: 610032000 | J34: 119190000 | K34: 1.33 | L34: 10.77 | M34: 1715746000 | N34: 183107152 | O34: 1.58
A35: =VLOOKUP(C35,'PORTFOLIO RAW'!C:D,2,FALSE) -> 243 | B35: NTRS.O | C35: 905861 | D35: 2007 | E35: 62.034574 | F35: 726900 | G35: 1351800 | H35: 4509100 | I35: 8950800 | J35: 5393000 | K35: 1.34 | L35: 17.2 | M35: 67611200 | N35: 16894237 | O35: 3.19
A36: =VLOOKUP(C36,'PORTFOLIO RAW'!C:D,2,FALSE) -> 188 | B36: JPM | C36: 902242 | D36: 2007 | E36: 56.935394 | F36: 15365000 | G36: 31838000 | H36: 123221000 | I36: 431839000 | J36: 116353000 | K36: 1.35 | L36: 12.86 | M36: 1562147000 | N36: 146987010 | O36: 1.29
A37: =VLOOKUP(C37,'PORTFOLIO RAW'!C:D,2,FALSE) -> 140 | B37: FITB.O | C37: 997198 | D37: 2007 | E37: 26.93842 | F37: 1075000 | G37: 2429000 | H37: 9152000 | I37: 22031000 | J37: 8494000 | K37: 1.44 | L37: 11.22 | M37: 110962000 | N37: 13385532 | O37: 2.07
A38: =VLOOKUP(C38,'PORTFOLIO RAW'!C:D,2,FALSE) -> 191 | B38: KEY | C38: 916130 | D38: 2007 | E38: 28.776327 | F38: 941000 | G38: 2341000 | H38: 7746000 | I38: 22337000 | J38: 7609000 | K38: 1.44 | L38: 11.9 | M38: 99983000 | N38: 9117196 | O38: 1.72
A39: =VLOOKUP(C39,'PORTFOLIO RAW'!C:D,2,FALSE) -> 315 | B39: UPS | C39: 277487 | D39: 2007 | E39: 30.867602 | F39: 382000 | G39: 2422000 | H39: 12183000 | I39: 11018000 | J39: 49692000 | K39: 1.5 | L39: 2.76 | M39: 39042000 | N39: 73619520 | O39: 12.57
... A50: =VLOOKUP(C50,'PORTFOLIO RAW'!C:D,2,FALSE) -> 24 | B50: AMT | C50: 680902 | D50: 2007 | E50: 33.311468 | F50: 56316 | G50: 911592 | H50: 3022092 | I50: 4285284 | J50: 1456594 | K50: 2.66 | L50: 1.52 | M50: 7650603 | N50: 17018700 | O50: 5.68
A51: =VLOOKUP(C51,'PORTFOLIO RAW'!C:D,2,FALSE) -> 38 | B51: AIZ | C51: 28341F | D51: 2007 | E51: 30.024258 | F51: 653746 | G51: 1106527 | H51: 4065519 | I51: 993023 | J51: 8441701 | K51: 2.67 | L51: 16.82 | M51: 26750316 | N51: 7881356 | O51: 1.51
A52: =VLOOKUP(C52,'PORTFOLIO RAW'!C:D,2,FALSE) -> 180 | B52: IPG | C52: 923465 | D52: 2007 | E52: 39.540937 | F52: 131300 | G52: 649600 | H52: 1807200 | I52: 2349200 | J52: 6554200 | K52: 2.75 | L52: 8.15 | M52: 11978200 | N52: 3821432 | O52: 2.74
A53: =VLOOKUP(C53,'PORTFOLIO RAW'!C:D,2,FALSE) -> 33 | B53: AIV | C53: 132808 | D53: 2007 | E53: 48.750242 | F53: -114070 | G53: 894607 | H53: 1031645 | I53: 7531782 | J53: 1721184 | K53: 2.91 | L53: -2.83 | M53: 10597547 | N53: 3338615 | O53: 4.22
A54: =VLOOKUP(C54,'PORTFOLIO RAW'!C:D,2,FALSE) -> 76 | B54: CI | C54: 912278 | D54: 2007 | E54: 23.944604 | F54: 1115000 | G54: 1926000 | H54: 4620000 | I54: 1793000 | J54: 17663000 | K54: 2.92 | L54: 25.47 | M54: 39271000 | N54: 15022263 | O54: 3.18
...

Sheet PORTFOLIO RAW
A1: Number | B1: NAME | C1: Code
A2: 1 | B2: MMM | C2: 902172 | D2: =A2 -> 1
A3: 2 | B3: ABT | C3: 916328 | D3: =A3 -> 2
A4: 3 | B4: ACN | C4: 14352P | D4: =A4 -> 3
A5: 4 | B5: ATVI.O | C5: 312367 | D5: =A5 -> 4
A6: 5 | B6: ADBE.O | C6: 749382 | D6: =A6 -> 5
A7: 6 | B7: AAP | C7: 14806F | D7: =A7 -> 6
A8: 7 | B8: AMD.O | C8: 936365 | D8: =A8 -> 7
A9: 8 | B9: AES | C9: 545101 | D9: =A9 -> 8
A10: 9 | B10: AFL | C10: 933185 | D10: =A10 -> 9
A11: 10 | B11: A | C11: 277642 | D11: =A11 -> 10
A12: 11 | B12: APD | C12: 905271 | D12: =A12 -> 11
A13: 12 | B13: AKAM.O | C13: 277355 | D13: =A13 -> 12
A14: 13 | B14: ALB | C14: 130298 | D14: =A14 -> 13
A15: 14 | B15: AGN | C15: 325596 | D15: =A15 -> 14
A16: 15 | B16: LNT.O | C16: 906979 | D16: =A16 -> 15
A17: 16 | B17: ALL | C17: 322677 | D17: =A17 -> 16
A18: 17 | B18: GOOG.O | C18: 29026M | D18: =A18 -> 17
A19: 18 | B19: MO | C19: 904853 | D19: =A19 -> 18
A20: 19 | B20: AMZN.O | C20: 891399 | D20: =A20 -> 19
A21: 20 | B21: AEE | C21: 670942 | D21: =A21 -> 20
A22: 21 | B22: AEP | C22: 905425 | D22: =A22 -> 21
A23: 22 | B23: AXP | C23: 906156 | D23: =A23 -> 22
A24: 23 | B24: AIG | C24: 916305 | D24: =A24 -> 23
A25: 24 | B25: AMT | C25: 680902 | D25: =A25 -> 24
A26: 25 | B26: AMP | C26: 31604H | D26: =A26 -> 25
A27: 26 | B27: ABC | C27: 154680 | D27: =A27 -> 26
A28: 27 | B28: AMGN.O | C28: 938692 | D28: =A28 -> 27
A29: 28 | B29: APH | C29: 546075 | D29: =A29 -> 28
A30: 29 | B30: ADI.O | C30: 905276 | D30: =A30 -> 29
A31: 30 | B31: ANTM.K | C31: 14737P | D31: =A31 -> 30
A32: 31 | B32: AON | C32: 922817 | D32: =A32 -> 31
A33: 32 | B33: APA | C33: 921983 | D33: =A33 -> 32
A34: 33 | B34: AIV | C34: 132808 | D34: =A34 -> 33
A35: 34 | B35: AAPL.O | C35: 992816 | D35: =A35 -> 34
A36: 35 | B36: AMAT.O | C36: 905296 | D36: =A36 -> 35
A37: 36 | B37: ADM | C37: 921093 | D37: =A37 -> 36
A38: 37 | B38: ARNC.K | C38: 905113 | D38: =A38 -> 37
A39: 38 | B39: AIZ | C39: 28341F | D39: =A39 -> 38
A40: 39 | B40: T | C40: 945388 | D40: =A40 -> 39
...

Sheet ESGC
A1: ESGC PORTFOLIO
C2: 3 | D2: 4 | E2: 5 | F2: 6 | G2: 7 | H2: 8 | I2: 9 | J2: 10 | K2: 11 | L2: 12 | M2: 13
A3: Code | B3: Name | C3: 2007 | D3: 2008 | E3: 2009 | F3: 2010 | G3: 2011 | H3: 2012 | I3: 2013 | J3: 2014 | K3: 2015 | L3: 2016 | M3: 2017
A4: =VLOOKUP(B4,'PORTFOLIO RAW'!B:C,2,FALSE) -> 902172 | B4: MMM | C4: 87.196853 | D4: 50.382743 | E4: 47.140342 | F4: 46.539558 | G4: 50.033837 | H4: 47.442829 | I4: 55.273448 | J4: 88.864444 | K4: 50.953109 | L4: 87.126519 | M4: 50.687716
A5: =VLOOKUP(B5,'PORTFOLIO RAW'!B:C,2,FALSE) -> 916328 | B5: ABT | C5: 34.369681 | D5: 74.108803 | E5: 40.291636 | F5: 40.793148 | G5: 39.468559 | H5: 40.011399 | I5: 44.822485 | J5: 41.422324 | K5: 42.586139 | L5: 45.821979 | M5: 43.056786
A6: =VLOOKUP(B6,'PORTFOLIO RAW'!B:C,2,FALSE) -> 14352P | B6: ACN | C6: 51.685846 | D6: 72.464911 | E6: 44.880139 | F6: 82.828882 | G6: 84.107278 | H6: 49.473394 | I6: 47.959104 | J6: 88.985526 | K6: 86.6825 | L6: 92.692745 | M6: 91.716033
A7: =VLOOKUP(B7,'PORTFOLIO RAW'!B:C,2,FALSE) -> 312367 | B7: ATVI.O | C7: 34.591234 | D7: 36.641828 | E7: 34.06525 | F7: 33.580174 | G7: 23.221913 | H7: 25.839549 | I7: 18.424289 | J7: 50.753359 | K7: 33.499076 | L7: 35.063434 | M7: 55.24599
A8: =VLOOKUP(B8,'PORTFOLIO RAW'!B:C,2,FALSE) -> 749382 | B8: ADBE.O | C8: 37.092577 | D8: 38.053702 | E8: 38.053702 | F8: 44.299029 | G8: 35.393899 | H8: 48.863832 | I8: 48.863832 | J8: 43.561088 | K8: 47.51067 | L8: 45.014435 | M8: 45.519894
A9: =VLOOKUP(B9,'PORTFOLIO RAW'!B:C,2,FALSE) -> 14806F | B9: AAP | C9: 37.296212 | D9: 37.730194 | E9: 37.730194 | F9: 46.130315 | G9: 49.030131 | H9: 33.668147 | I9: 46.424335 | J9: 46.259533 | K9: 46.259533 | L9: 42.812791 | M9: 27.92945
A10: =VLOOKUP(B10,'PORTFOLIO RAW'!B:C,2,FALSE) -> 936365 | B10: AMD.O | C10: 66.492963 | D10: 62.677185 | E10: 36.2718 | F10: 38.761892 | G10: 35.158859 | H10: 43.250636 | I10: 41.235471 | J10: 41.235471 | K10: 78.280174 | L10: 39.892114 | M10: 43.134463
A11: =VLOOKUP(B11,'PORTFOLIO RAW'!B:C,2,FALSE) -> 545101 | B11: AES | C11: 50.503558 | D11: 34.33064 | E11: 33.561278 | F11: 33.561278 | G11: 44.781638 | H11: 44.781638 | I11: 53.84665 | J11: 53.84665 | K11: 32.588884 | L11: 58.433747 | M11: 66.98827
A12: =VLOOKUP(B12,'PORTFOLIO RAW'!B:C,2,FALSE) -> 933185 | B12: AFL | C12: 52.782483 | D12: 35.970888 | E12: 35.970888 | F12: 58.328972 | G12: 42.440133 | H12: 69.337764 | I12: 38.73711 | J12: 38.73711 | K12: 69.659623 | L12: 69.118896 | M12: 69.731359
A13: =VLOOKUP(B13,'PORTFOLIO RAW'!B:C,2,FALSE) -> 277642 | B13: A | C13: 47.935211 | D13: 47.935211 | E13: 50.429171 | F13: 49.67811 | G13: 83.594284 | H13: 83.594284 | I13: 84.716912 | J13: 84.716912 | K13: 82.687352 | L13: 82.000545 | M13: 89.222975
A14: =VLOOKUP(B14,'PORTFOLIO RAW'!B:C,2,FALSE) -> 905271 | B14: APD | C14: 66.565326 | D14: 78.888183 | E14: 72.150888 | F14: 77.437421 | G14: 40.825982 | H14: 84.362445 | I14: 83.578389 | J14: 45.614554 | K14: 46.770641 | L14: 79.926533 | M14: 76.728144
A15: =VLOOKUP(B15,'PORTFOLIO RAW'!B:C,2,FALSE) -> 277355 | B15: AKAM.O | C15: 44.900541 | D15: 44.900541 | E15: 36.647063 | F15: 37.96387 | G15: 37.96387 | H15: 41.334767 | I15: 27.501162 | J15: 35.535379 | K15: 58.519486 | L15: 66.453929 | M15: 35.587406
... A350: =VLOOKUP(B350,'PORTFOLIO RAW'!B:C,2,FALSE) -> 951584 | B350: ZION.O | C350: 44.106225 | D350: 43.228866 | E350: 43.228965 | F350: 35.866759 | G350: 24.717636 | H350: 26.053497 | I350: 33.482903 | J350: 31.583338 | K350: 35.871449 | L350: 39.735018 | M350: 40.503275

Sheet MB
A1: MARKET-TO-BOOK RATIO
E2: 4 | F2: 5 | G2: 6 | H2: 7 | I2: 8 | J2: 9 | K2: 10 | L2: 11 | M2: 12 | N2: 13 | O2: 14
B3: Code | C3: Name | D3: Code | E3: 2007 | F3: 2008 | G3: 2009 | H3: 2010 | I3: 2011 | J3: 2012 | K3: 2013 | L3: 2014 | M3: 2015 | N3: 2016 | O3: 2017
A4: =VLOOKUP(B4,'PORTFOLIO RAW'!C:C,1,FALSE) -> 891399 | B4: 891399 | C4: AMAZON.COM - MRKT VALUE TO BOOK | D4: 891399(MTBV) | E4: 30.96 | F4: 12.91 | G4: 7.42 | H4: 9.87 | I4: 13.65 | J4: 14.39 | K4: 14.83 | L4: 14.25 | M4: 18.88 | N4: 19.18 | O4: 16.87
A5: =VLOOKUP(B5,'PORTFOLIO RAW'!C:C,1,FALSE) -> 916328 | B5: 916328 | C5: ABBOTT LABORATORIES - MRKT VALUE TO BOOK | D5: 916328(MTBV) | E5: 4.67 | F5: 5.18 | G5: 3.11 | H5: 3.6 | I5: 3.36 | J5: 4.1 | K5: 2.18 | L5: 3.04 | M5: 3.04 | N5: 2.98 | O5: 2.92
A6: =VLOOKUP(B6,'PORTFOLIO RAW'!C:C,1,FALSE) -> 545101 | B6: 545101 | C6: AES - MRKT VALUE TO BOOK | D6: 545101(MTBV) | E6: 4.08 | F6: 2.42 | G6: 2.05 | H6: 1.4 | I6: 1.41 | J6: 1.83 | K6: 2.29 | L6: 2.49 | M6: 2.37 | N6: 3.01 | O6: 3.02
A7: =VLOOKUP(B7,'PORTFOLIO RAW'!C:C,1,FALSE) -> 906187 | B7: 906187 | C7: INTERNATIONAL BUS.MCHS. - MRKT VALUE TO BOOK | D7: 906187(MTBV) | E7: 5.58 | F7: 11.96 | G7: 7.07 | H7: 7.21 | I7: 10.36 | J7: 12.49 | K7: 9.13 | L7: 16.31 | M7: 9.93 | N7: 8.09 | O7: 7.73
A8: =VLOOKUP(B8,'PORTFOLIO RAW'!C:C,1,FALSE) -> 936365 | B8: 936365 | C8: ADVANCED MICRO DEVICES - MRKT VALUE TO BOOK | D8: 936365(MTBV) | E8: 2.47 | F8: -40.13 | G8: 5.87 | H8: 4.06 | I8: 2.93 | J8: 4.72 | K8: 5.07 | L8: 15.65 | M8: -3.54 | N8: 13.27 | O8: 21.29
A9: =VLOOKUP(B9,'PORTFOLIO RAW'!C:C,1,FALSE) -> 749382 | B9: 749382 | C9: ADOBE (NAS) - MRKT VALUE TO BOOK | D9: 749382(MTBV) | E9: 5.42 | F9: 4.92 | G9: 3.54 | H9: 3.35 | I9: 2.1 | J9: 2.55 | K9: 3.91 | L9: 4.93 | M9: 5.79 | N9: 6.75 | O9: 8.75
A10: =VLOOKUP(B10,'PORTFOLIO RAW'!C:C,1,FALSE) -> 905271 | B10: 905271 | C10: AIR PRDS.& CHEMS. - MRKT VALUE TO BOOK | D10: 905271(MTBV) | E10: 3.65 | F10: 3.51 | G10: 3.52 | H10: 3.18 | I10: 3.02 | J10: 2.78 | K10: 3.23 | L10: 3.89 | M10: 3.99 | N10: 4.5 | O10: 3.26
A11: =VLOOKUP(B11,'PORTFOLIO RAW'!C:C,1,FALSE) -> 894371 | B11: 894371 | C11: BOSTON PROPERTIES - MRKT VALUE TO BOOK | D11: 894371(MTBV) | E11: 3.36 | F11: 3.23 | G11: 2.2 | H11: 2.83 | I11: 3.01 | J11: 3.33 | K11: 3.01 | L11: 3.15 | M11: 3.19 | N11: 3.72 | O11: 3.32
A12: =VLOOKUP(B12,'PORTFOLIO RAW'!C:C,1,FALSE) -> 322677 | B12: 322677 | C12: ALLSTATE ORD SHS - MRKT VALUE TO BOOK | D12: 322677(MTBV) | E12: 1.56 | F12: 1.57 | G12: 0.94 | H12: 0.94 | I12: 0.73 | J12: 1.09 | K12: 1.26 | L12: 1.45 | M12: 1.31 | N12: 1.42 | O12: 1.73
A13: =VLOOKUP(B13,'PORTFOLIO RAW'!C:C,1,FALSE) -> 906191 | B13: 906191 | C13: HONEYWELL INTL. - MRKT VALUE TO BOOK | D13: 906191(MTBV) | E13: 4.72 | F13: 4.69 | G13: 3.42 | H13: 3.21 | I13: 3.39 | J13: 3.64 | K13: 3.84 | L13: 4.28 | M13: 4.19 | N13: 4.51 | O13: 6.11
A14: =VLOOKUP(B14,'PORTFOLIO RAW'!C:C,1,FALSE) -> 938692 | B14: 938692 | C14: AMGEN - MRKT VALUE TO BOOK | D14: 938692(MTBV) | E14: 3.36 | F14: 3.11 | G14: 2.72 | H14: 2.24 | I14: 2.79 | J14: 3.33 | K14: 3.98 | L14: 4.24 | M14: 4.07 | N14: 4.34 | O14: 5.44
A15: =VLOOKUP(B15,'PORTFOLIO RAW'!C:C,1,FALSE) -> 905802 | B15: 905802 | C15: HESS - MRKT VALUE TO BOOK | D15: 905802(MTBV) | E15: 2.16 | F15: 2.51 | G15: 1.36 | H15: 1.12 | I15: 1.1 | J15: 0.9 | K15: 1.09 | L15: 1.35 | M15: 0.78 | N15: 1 | O15: 1.25
... A109: =VLOOKUP(B109,'PORTFOLIO RAW'!C:C,1,FALSE) -> 905016 | B109: 905016 | C109: NEXTERA ENERGY - MRKT VALUE TO BOOK | D109: 905016(MTBV) | E109: 2.37 | F109: 1.96 | G109: 1.75 | H109: 1.57 | I109: 1.57 | J109: 1.77 | K109: 1.9 | L109: 2.08 | M109: 1.98 | N109: 2.37 | O109: 2.44
A110: =VLOOKUP(B110,'PORTFOLIO RAW'!C:C,1,FALSE) -> 28341F | B110: 28341F | C110: ASSURANT - MRKT VALUE TO BOOK | D110: 28341F(MTBV) | E110: 1.51 | F110: 1.54 | G110: 0.81 | H110: 0.99 | I110: 0.77 | J110: 0.59 | K110: 0.94 | L110: 1.09 | M110: 1.26 | N110: 1.49 | O110: 1.37
A111: =VLOOKUP(B111,'PORTFOLIO RAW'!C:C,1,FALSE) -> 755980 | B111: 755980 | C111: FASTENAL - MRKT VALUE TO BOOK | D111: 755980(MTBV) | E111: 6.65 | F111: 6.97 | G111: 4.86 | H111: 6 | I111: 7.41 | J111: 8.33 | K111: 8.4 | L111: 7.16 | M111: 5.99 | N111: 5.97 | O111: 6.12
A112: =VLOOKUP(B112,'PORTFOLIO RAW'!C:C,1,FALSE) -> 905994 | B112: 905994 | C112: FEDERAL REALTY INV.TST. - MRKT VALUE TO BOOK | D112: 905994(MTBV) | E112: 4.41 | F112: 4.71 | G112: 3.32 | H112: 4.49 | I112: 4.42 | J112: 5.28 | K112: 4.69 | L112: 5.07 | M112: 5.63 | N112: 5.6 | O112: 4.27
A113: =VLOOKUP(B113,'PORTFOLIO RAW'!C:C,1,FALSE) -> 997198 | B113: 997198 | C113: FIFTH THIRD BANCORP - MRKT VALUE TO BOOK | D113: 997198(MTBV) | E113: 2.07 | F113: 1.39 | G113: 0.84 | H113: 0.96 | I113: 0.75 | J113: 1.08 | K113: 1.23 | L113: 1.22 | M113: 1.05 | N113: 1.06 | O113: 1.34
A114: =VLOOKUP(B114,'PORTFOLIO RAW'!C:C,1,FALSE) -> 951503 | B114: 951503 | C114: M&T BANK - MRKT VALUE TO BOOK | D114: 951503(MTBV) | E114: 1.79 | F114: 1.67 | G114: 1.12 | H114: 1.43 | I114: 1.07 | J114: 1.28 | K114: 1.39 | L114: 1.52 | M114: 1.06 | N114: 1.19 | O114: 1.56
A115: =VLOOKUP(B115,'PORTFOLIO RAW'!C:C,1,FALSE) -> 741123 | B115: 741123 | C115: FISERV - MRKT VALUE TO BOOK | D115: 741123(MTBV) | E115: 3.3 | F115: 3.26 | G115: 2.52 | H115: 2.52 | I115: 2.33 | J115: 2.92 | K115: 3.7 | L115: 4.97 | M115: 7.63 | N115: 8.59 | O115: 9.64
A116: =VLOOKUP(B116,'PORTFOLIO RAW'!C:C,1,FALSE) -> 546814 | B116: 546814 | C116: MACY'S - MRKT VALUE TO BOOK | D116: 546814(MTBV) | E116: 1.49 | F116: 1.81 | G116: 1.61 | H116: 1.69 | I116: 1.97 | J116: 2.57 | K116: 2.69 | L116: 3.95 | M116: 4.21 | N116: 2.49 | O116: 1.15
A117: =VLOOKUP(B117,'PORTFOLIO RAW'!C:C,1,FALSE) -> 938076 | B117: 938076 | C117: FRANKLIN RESOURCES - MRKT VALUE TO BOOK | D117: 938076(MTBV) | E117: 4.34 | F117: 3.58 | G117: 3.12 | H117: 3.15 | I117: 2.98 | J117: 2.9 | K117: 3.27 | L117: 3.01 | M117: 2 | N117: 1.69 | O117: 1.9
A118: =VLOOKUP(B118,'PORTFOLIO RAW'!C:C,1,FALSE) -> 152594 | B118: 152594 | C118: FREEPORT-MCMORAN - MRKT VALUE TO BOOK | D118: 152594(MTBV) | E118: 2.88 | F118: 13.66 | G118: 4.63 | H118: 3.14 | I118: 2.34 | J118: 2.21 | K118: 1.68 | L118: 1.94 | M118: 1.58 | N118: 2.18 | O118: 2.57
A119: =VLOOKUP(B119,'PORTFOLIO RAW'!C:C,1,FALSE) -> 951018 | B119: 951018 | C119: GAP - MRKT VALUE TO BOOK | D119: 951018(MTBV) | E119: 3.4 | F119: 3.09 | G119: 3.14 | H119: 2.91 | I119: 3.1 | J119: 6.01 | K119: 6.34 | L119: 6.4 | M119: 5.05 | N119: 3.1 | O119: 3.49
A120: =VLOOKUP(B120,'PORTFOLIO RAW'!C:C,1,FALSE) -> 907652 | B120: 907652 | C120: GENERAL DYNAMICS - MRKT VALUE TO BOOK | D120: 907652(MTBV) | E120: 2.87 | F120: 3.26 | G120: 2 | H120: 1.82 | I120: 1.63 | J120: 2.05 | K120: 2.13 | L120: 3.66 | M120: 4.18 | N120: 4.22 | O120: 5.35
A121: =VLOOKUP(B121,'PORTFOLIO RAW'!C:C,1,FALSE) -> 905801 | B121: 905801 | C121: GENERAL MILLS - MRKT VALUE TO BOOK | D121: 905801(MTBV) | E121: 3.07 | F121: 4.52 | G121: 3.65 | H121: 3.64 | I121: 3.76 | J121: 3.91 | K121: 4.72 | L121: 6.2 | M121: 6.86 | N121: 8.84 | O121: 4.83
A122: =VLOOKUP(B122,'PORTFOLIO RAW'!C:C,1,FALSE) -> 906511 | B122: 906511 | C122: GENUINE PARTS - MRKT VALUE TO BOOK | D122: 906511(MTBV) | E122: 3.18 | F122: 2.94 | G122: 2.29 | H122: 2.5 | I122: 2.94 | J122: 3.24 | K122: 3.76 | L122: 4.14 | M122: 4.01 | N122: 4.6 | O122: 3.73
... A235: =VLOOKUP(B235,'PORTFOLIO RAW'!C:C,1,FALSE) -> 933974 | B235: 933974 | C235: TRAVELERS COS. - MRKT VALUE TO BOOK | D235: 933974(MTBV) | E235: 1.3 | F235: 1.18 | G235: 1.06 | H235: 1.07 | I235: 0.98 | J235: 1.18 | K235: 1.37 | L235: 1.4 | M235: 1.39 | N235: 1.47 | O235: 1.48
A236: =VLOOKUP(B236,'PORTFOLIO RAW'!C:C,1,FALSE) -> 14015T | B236: 14015T | C236: FIDELITY NAT.INFO.SVS. - MRKT VALUE TO BOOK | D236: 14015T(MTBV) | E236: 2.35 | F236: 1.09 | G236: 0.58 | H236: 1.29 | I236: 1.22 | J236: 1.44 | K236: 2.08 | L236: 2.49 | M236: 2.06 | N236: 2.58 | O236: 2.85
A237: =VLOOKUP(B237,'PORTFOLIO RAW'!C:C,1,FALSE) -> 905019 | B237: 905019 | C237: MERCK & COMPANY - MRKT VALUE TO BOOK | D237: 905019(MTBV) | E237: 6.13 | F237: 3.64 | G237: 1.14 | H237: 2.07 | I237: 1.84 | J237: 2.58 | K237: 2.82 | L237: 3.59 | M237: 3.29 | N237: 4.27 | O237: 5.23
A238: =VLOOKUP(B238,'PORTFOLIO RAW'!C:C,1,FALSE) -> 912090 | B238: 912090 | C238: SCHLUMBERGER - MRKT VALUE TO BOOK | D238: 912090(MTBV) | E238: 8.6 | F238: 6.45 | G238: 3.87 | H238: 2.58 | I238: 2.99 | J238: 2.87 | K238: 2.93 | L238: 3.54 | M238: 2.58 | N238: 2.55 | O238: 2.54
A239: =VLOOKUP(B239,'PORTFOLIO RAW'!C:C,1,FALSE) -> 755741 | B239: 755741 | C239: CHARLES SCHWAB - MRKT VALUE TO BOOK | D239: 755741(MTBV) | E239: 7.07 | F239: 7.16 | G239: 4.03 | H239: 2.68 | I239: 1.86 | J239: 1.97 | K239: 2.88 | L239: 3.63 | M239: 3.14 | N239: 2.99 | O239: 3.55
A240: =VLOOKUP(B240,'PORTFOLIO RAW'!C:C,1,FALSE) -> 14361V | B240: 14361V | C240: ZIMMER BIOMET HDG. - MRKT VALUE TO BOOK | D240: 14361V(MTBV) | E240: 3.61 | F240: 2.71 | G240: 1.94 | H240: 1.8 | I240: 1.98 | J240: 1.99 | K240: 2.24 | L240: 2.69 | M240: 2.04 | N240: 2.58 | O240: 2
A241: =VLOOKUP(B241,'PORTFOLIO RAW'!C:C,1,FALSE) -> 154680 | B241: 154680 | C241: AMERISOURCEBERGEN - MRKT VALUE TO BOOK | D241: 154680(MTBV) | E241: 2.65 | F241: 2.31 | G241: 2.38 | H241: 2.89 | I241: 3.73 | J241: 3.93 | K241: 6.14 | L241: 8.87 | M241: 36.21 | N241: 9.17 | O241: 8.44
A242: =VLOOKUP(B242,'PORTFOLIO RAW'!C:C,1,FALSE) -> 14698C | B242: 14698C | C242: PRINCIPAL FINL.GP. - MRKT VALUE TO BOOK | D242: 14698C(MTBV) | E242: 2.32 | F242: 2.11 | G242: 1.09 | H242: 0.93 | I242: 0.88 | J242: 1.01 | K242: 1.35 | L242: 1.57 | M242: 1.52 | N242: 1.38 | O242: 1.61
A243: =VLOOKUP(B243,'PORTFOLIO RAW'!C:C,1,FALSE) -> 905361 | B243: 905361 | C243: SHERWIN-WILLIAMS - MRKT VALUE TO BOOK | D243: 905361(MTBV) | E243: 4.93 | F243: 4.64 | G243: 4.84 | H243: 5.05 | I243: 5.2 | J243: 8.99 | K243: 10.66 | L243: 21.64 | M243: 26.49 | N243: 13.51 | O243: 8.78
A244: =VLOOKUP(B244,'PORTFOLIO RAW'!C:C,1,FALSE) -> 357834 | B244: 357834 | C244: SIMON PROPERTY GROUP - MRKT VALUE TO BOOK | D244: 357834(MTBV) | E244: 7.85 | F244: 8.69 | G244: 4.71 | H244: 5.95 | I244: 7.63 | J244: 8.06 | K244: 8.07 | L244: 10.2 | M244: 12.86 | N244: 15.37 | O244: 13.64
A245: =VLOOKUP(B245,'PORTFOLIO RAW'!C:C,1,FALSE) -> 906400 | B245: 906400 | C245: SNAP-ON - MRKT VALUE TO BOOK | D245: 906400(MTBV) | E245: 2.22 | F245: 2.83 | G245: 1.65 | H245: 1.96 | I245: 1.9 | J245: 2.33 | K245: 2.78 | L245: 3.26 | M245: 3.75 | N245: 3.32 | O245: 2.91
...

Sheet MCAP
A1: Market Capitalization
B2: 1 | C2: 2 | D2: 3 | E2: 4 | F2: 5 | G2: 6 | H2: 7 | I2: 8 | J2: 9 | K2: 10 | L2: 11 | M2: 12 | N2: 13 | O2: 14
B3: Code | C3: Name | D3: Code | E3: 2007 | F3: 2008 | G3: 2009 | H3: 2010 | I3: 2011 | J3: 2012 | K3: 2013 | L3: 2014 | M3: 2015 | N3: 2016 | O3: 2017
A4: =VLOOKUP(B4,'PORTFOLIO RAW'!B:B,1,FALSE) -> #N/A | B4: 891399 | C4: AMAZON.COM INC - MARKET CAPITALIZATION | D4: 891399(WC08001) | E4: 38538240 | F4: 21947840 | G4: 59726880 | H4: 81180000 | I4: 78760500 | J4: 113894980 | K4: 183044610 | L4: 144312750 | M4: 318344190 | N4: 357687990 | O4: 566023480
A5: =VLOOKUP(B5,'[1]PORTFOLIO RAW'!B:B,1,FALSE) -> 916328 | B5: 916328 | C5: ABBOTT LABORATORIES - MARKET CAPITALIZATION | D5: 916328(WC08001) | E5: 87027454 | F5: 82853346 | G5: 83747538 | H5: 74116001 | I5: 88302401 | J5: 103271721 | K5: 59338607 | L5: 67891755 | M5: 66137387 | N5: 56572906 | O5: 99507393
A6: =VLOOKUP(B6,'[1]PORTFOLIO RAW'!B:B,1,FALSE) -> 545101 | B6: 545101 | C6: AES CORP - MARKET CAPITALIZATION | D6: 545101(WC08001) | E6: 14338569 | F6: 5461363 | G6: 8886820 | H6: 9593056 | I6: 9059806 | J6: 7963623 | K6: 10483596 | L6: 9692032 | M6: 6381360 | N6: 7659698 | O6: 7152003
A7: =VLOOKUP(B7,'[1]PORTFOLIO RAW'!B:B,1,FALSE) -> 906187 | B7: 906187 | C7: INT'L BUSINESS MACHS - MARKET CAPITALIZATION | D7: 906187(WC08001) | E7: 149743810 | F7: 112698313 | G7: 170868669 | H7: 180220333 | I7: 213886010 | J7: 214031778 | K7: 197772108 | L7: 158919632 | M7: 132903587 | N7: 157004530 | O7: 141480737
A8: =VLOOKUP(B8,'[1]PORTFOLIO RAW'!B:B,1,FALSE) -> 936365 | B8: 936365 | C8: ADVANCED MICRO - MARKET CAPITALIZATION | D8: 936365(WC08001) | E8: 4545000 | F8: 1315440 | G8: 6495280 | H8: 5586940 | I8: 3763800 | J8: 1711200 | K8: 2805750 | L8: 2071920 | M8: 2273040 | N8: 10602900 | O8: 9940760
A9: =VLOOKUP(B9,'[1]PORTFOLIO RAW'!B:B,1,FALSE) -> 749382 | B9: 749382 | C9: ADOBE INC - MARKET CAPITALIZATION | D9: 749382(WC08001) | E9: 24416307 | F9: 11200903 | G9: 19223324 | H9: 15448390 | I9: 13895836 | J9: 18618894 | K9: 29715612 | L9: 36167087 | M9: 46764177 | N9: 50883449 | O9: 86088753
A10: =VLOOKUP(B10,'[1]PORTFOLIO RAW'!B:B,1,FALSE) -> 905271 | B10: 905271 | C10: AIR PRODUCTS & CHEMS - MARKET CAPITALIZATION | D10: 905271(WC08001) | E10: 21240531 | F10: 10523252 | G10: 17124757 | H10: 19445371 | I10: 17905682 | J10: 17852223 | K10: 23605617 | L10: 30798607 | M10: 28020374 | N10: 31259396 | O10: 35826224
A11: =VLOOKUP(B11,'[1]PORTFOLIO RAW'!B:B,1,FALSE) -> 894371 | B11: 894371 | C11: BOSTON PROPERTIES - MARKET CAPITALIZATION | D11: 894371(WC08001) | E11: 10971523 | F11: 6664936 | G11: 9314682 | H11: 12071143 | I11: 14751518 | J11: 16040924 | K11: 15354914 | L11: 19704234 | M11: 19587589 | N11: 19343728 | O11: 20066917
A12: =VLOOKUP(B12,'[1]PORTFOLIO RAW'!B:B,1,FALSE) -> 322677 | B12: 322677 | C12: ALLSTATE CORP - MARKET CAPITALIZATION | D12: 322677(WC08001) | E12: 29405490 | F12: 17559360 | G12: 16131480 | H12: 16992040 | I12: 13732410 | J12: 19241430 | K12: 24488460 | L12: 29364500 | M12: 23656290 | N12: 27127920 | O12: 37172050
A13: =VLOOKUP(B13,'[1]PORTFOLIO RAW'!B:B,1,FALSE) -> 906191 | B13: 906191 | C13: HONEYWELL INTERNATNL - MARKET CAPITALIZATION | D13: 906191(WC08001) | E13: 45965321 | F13: 24116466 | G13: 29957004 | H13: 41624280 | I13: 42104945 | J13: 49684316 | K13: 71615806 | L13: 78157424 | M13: 79790328 | N13: 88138680 | O13: 115158024
A14: =VLOOKUP(B14,'[1]PORTFOLIO RAW'!B:B,1,FALSE) -> 938692 | B14: 938692 | C14: AMGEN INC - MARKET CAPITALIZATION | D14: 938692(WC08001) | E14: 50480280 | F14: 60464250 | G14: 56287150 | H14: 51166800 | I14: 51085476 | J14: 65193060 | K14: 86084768 | L14: 121124116 | M14: 122396820 | N14: 107932222 | O14: 125590580
A15: =VLOOKUP(B15,'[1]PORTFOLIO RAW'!B:B,1,FALSE) -> 905802 | B15: 905802 | C15: HESS CORPORATION - MARKET CAPITALIZATION | D15: 905802(WC08001) | E15: 32335674 | F15: 17493760 | G15: 19797384 | H15: 25846087 | I15: 19310615 | J15: 18087303 | K15: 27001077 | L15: 21100337 | M15: 13867490 | N15: 19716230 | O15: 14955595
A16: =VLOOKUP(B16,'[1]PORTFOLIO RAW'!B:B,1,FALSE) -> 906156 | B16: 906156 | C16: AMERICAN EXPRESS CO - MARKET CAPITALIZATION | D16: 906156(WC08001) | E16: 60239160 | F16: 21518000 | G16: 48299840 | H16: 51375240 | I16: 54905880 | J16: 63515400 | K16: 96536720 | L16: 95179920 | M16: 67393950 | N16: 66968320 | O16: 85307290
... A110: =VLOOKUP(B110,'[1]PORTFOLIO RAW'!B:B,1,FALSE) -> 905016 | B110: 905016 | C110: NEXTERA ENERGY - MARKET CAPITALIZATION | D110: 905016(WC08001) | E110: 27609842 | F110: 20580707 | G110: 21847537 | H110: 21880591 | I110: 25326080 | J110: 29336560 | K110: 37244700 | L110: 47086470 | M110: 47893290 | N110: 55907280 | O110: 73565490
A111: =VLOOKUP(B111,'[1]PORTFOLIO RAW'!B:B,1,FALSE) -> 28341F | B111: 28341F | C111: ASSURANT INC - MARKET CAPITALIZATION | D111: 28341F(WC08001) | E111: 7881356 | F111: 3521056 | G111: 3438804 | H111: 3929054 | I111: 3634811 | J111: 2729642 | K111: 4767238 | L111: 4742169 | M111: 5303590 | N111: 5194726 | O111: 5285812
A112: =VLOOKUP(B112,'[1]PORTFOLIO RAW'!B:B,1,FALSE) -> 755980 | B112: 755980 | C112: FASTENAL COMPANY - MARKET CAPITALIZATION | D112: 755980(WC08001) | E112: 6027459 | F112: 5176295 | G112: 6139015 | H112: 8832574 | I112: 12876231 | J112: 13834728 | K112: 14098761 | L112: 14071475 | M112: 11820724 | N112: 13584827 | O112: 15728381
A113: =VLOOKUP(B113,'[1]PORTFOLIO RAW'!B:B,1,FALSE) -> 905994 | B113: 905994 | C113: FEDERAL REALTY INVST - MARKET CAPITALIZATION | D113: 905994(WC08001) | E113: 4817741 | F113: 3661831 | G113: 4147312 | H113: 4794754 | I113: 5766632 | J113: 6742103 | K113: 6764191 | L113: 9156128 | M113: 10152985 | N113: 10231337 | O113: 9707199
A114: =VLOOKUP(B114,'[1]PORTFOLIO RAW'!B:B,1,FALSE) -> 997198 | B114: 997198 | C114: FIFTH THIRD BANCORP - MARKET CAPITALIZATION | D114: 997198(WC08001) | E114: 13385532 | F114: 4769217 | G114: 7751913 | H114: 11689281 | I114: 11699912 | J114: 13408711 | K114: 17987080 | L114: 16789957 | M114: 15780114 | N114: 20240427 | O114: 21050040
A115: =VLOOKUP(B115,'[1]PORTFOLIO RAW'!B:B,1,FALSE) -> 951503 | B115: 951503 | C115: M&T BANK CORPORATION - MARKET CAPITALIZATION | D115: 951503(WC08001) | E115: 8960656 | F115: 6336072 | G115: 7907916 | H115: 10420115 | I115: 9594671 | J115: 12621581 | K115: 15194715 | L115: 16621150 | M115: 19335906 | N115: 24431384 | O115: 25662932
A116: =VLOOKUP(B116,'[1]PORTFOLIO RAW'!B:B,1,FALSE) -> 741123 | B116: 741123 | C116: FISERV INC - MARKET CAPITALIZATION | D116: 741123(WC08001) | E116: 9161399 | F116: 5670083 | G116: 7427136 | H116: 8602464 | I116: 8229474 | J116: 10542602 | K116: 15158135 | L116: 17054091 | M116: 20605938 | N116: 22903340 | O116: 27222588
A117: =VLOOKUP(B117,'[1]PORTFOLIO RAW'!B:B,1,FALSE) -> 546814 | B117: 546814 | C117: MACY'S INC - MARKET CAPITALIZATION | D117: 546814(WC08001) | E117: 10857639 | F117: 4348035 | G117: 7052608 | H117: 10709490 | I117: 13328956 | J117: 15128054 | K117: 19487529 | L117: 22392721 | M117: 10852758 | N117: 10888489 | O117: 7677030
A118: =VLOOKUP(B118,'[1]PORTFOLIO RAW'!B:B,1,FALSE) -> 938076 | B118: 938076 | C118: FRANKLIN RESOURCES - MARKET CAPITALIZATION | D118: 938076(WC08001) | E118: 28089120 | F118: 14846580 | G118: 24159320 | H118: 24911893 | I118: 20911631 | J118: 26674666 | K118: 36422869 | L118: 34489590 | M118: 22221503 | N118: 22574261 | O118: 24042315
A119: =VLOOKUP(B119,'[1]PORTFOLIO RAW'!B:B,1,FALSE) -> 152594 | B119: 152594 | C119: FREEPORT-MCMORAN INC - MARKET CAPITALIZATION | D119: 152594(WC08001) | E119: 39234520 | F119: 9384960 | G119: 34524700 | H119: 56742525 | I119: 34876920 | J119: 32455800 | K119: 39174120 | L119: 24271040 | M119: 8435420 | N119: 19059550 | O119: 27454080
A120: =VLOOKUP(B120,'[1]PORTFOLIO RAW'!B:B,1,FALSE) -> 951018 | B120: 951018 | C120: GAP INC - MARKET CAPITALIZATION | D120: 951018(WC08001) | E120: 15619520 | F120: 9292660 | G120: 14162200 | H120: 13018320 | I120: 8996750 | J120: 14371520 | K120: 17429680 | L120: 17728310 | M120: 9805900 | N120: 8953560 | O120: 13249340
A121: =VLOOKUP(B121,'[1]PORTFOLIO RAW'!B:B,1,FALSE) -> 907652 | B121: 907652 | C121: GENERAL DYNAMICS - MARKET CAPITALIZATION | D121: 907652(WC08001) | E121: 42882558 | F121: 27751506 | G121: 26293489 | H121: 26400832 | I121: 23671040 | J121: 24499015 | K121: 33767637 | L121: 45712423 | M121: 42991932 | N121: 52215583 | O121: 60403411
A122: =VLOOKUP(B122,'[1]PORTFOLIO RAW'!B:B,1,FALSE) -> 905801 | B122: 905801 | C122: GENERAL MILLS, INC. - MARKET CAPITALIZATION | D122: 905801(WC08001) | E122: 19380000 | F122: 20503125 | G122: 23225680 | H122: 23364835 | I122: 26056368 | J122: 26212370 | K122: 31982328 | L122: 32653959 | M122: 34521042 | N122: 36864336 | O122: 34204401
A123: =VLOOKUP(B123,'[1]PORTFOLIO RAW'!B:B,1,FALSE) -> 906511 | B123: 906511 | C123: GENUINE PARTS CO - MARKET CAPITALIZATION | D123: 906511(WC08001) | E123: 7688821 | F123: 6036244 | G123: 6032521 | H123: 8093046 | I123: 9525848 | J123: 9844819 | K123: 12792384 | L123: 16317257 | M123: 12890498 | N123: 14179132 | O123: 13933465
... A182: =VLOOKUP(B182,'[1]PORTFOLIO RAW'!B:B,1,FALSE) -> 771830 | B182: 771830 | C182: MAXIM INTEGRATED PRD - MARKET CAPITALIZATION | D182: 771830(WC08001) | E182: 8488256 | F182: 3660715 | G182: 6218306 | H182: 7106030 | I182: 7702111 | J182: 8606321 | K182: 8024598 | L182: 9065135 | M182: 10823274 | N182: 10950370 | O182: 14790639
A183: =VLOOKUP(B183,'[1]PORTFOLIO RAW'!B:B,1,FALSE) -> 312367 | B183: 312367 | C183: ACTIVISION BLIZZARD - MARKET CAPITALIZATION | D183: 312367(WC08001) | E183: NA | F183: 11225706 | G183: 13892290 | H183: 14720499 | I183: 13963382 | J183: 11805257 | K183: 12547131 | L183: 14546879 | M183: 28432598 | N183: 26919521 | O183: 47965229
A184: =VLOOKUP(B184,'[1]PORTFOLIO RAW'!B:B,1,FALSE) -> 912635 | B184: 912635 | C184: CVS HEALTH CORP - MARKET CAPITALIZATION | D184: 912635(WC08001) | E184: 57099166 | F184: 41350106 | G184: 44804110 | H184: 47391510 | I184: 52932440 | J184: 59518850 | K184: 84452600 | L184: 109793400 | M184: 107644770 | N184: 83723510 | O184: 73515000
A185: =VLOOKUP(B185,'[1]PORTFOLIO RAW'!B:B,1,FALSE) -> 152533 | B185: 152533 | C185: LAB CORP OF AMERICA - MARKET CAPITALIZATION | D185: 152533(WC08001) | E185: 8383830 | F185: 6969162 | G185: 7880652 | H185: 9003008 | I185: 8407866 | J185: 8098970 | K185: 7830409 | L185: 9128340 | M185: 12524732 | N185: 13184626 | O185: 16254069
A186: =VLOOKUP(B186,'[1]PORTFOLIO RAW'!B:B,1,FALSE) -> 719643 | B186: 719643 | C186: MICROSOFT CORP - MARKET CAPITALIZATION | D186: 719643(WC08001) | E186: 333928000 | F186: 177895440 | G186: 271515840 | H186: 241923880 | I186: 217440960 | J186: 223853996 | K186: 311550480 | L186: 382701550 | M186: 445337960 | N186: 485189120 | O186: 659342320
A187: =VLOOKUP(B187,'[1]PORTFOLIO RAW'!B:B,1,FALSE) -> 999506 | B187: 999506 | C187: MICRON TECHNOLOGY - MARKET CAPITALIZATION | D187: 999506(WC08001) | E187: 5494775 | F187: 2009304 | G187: 8962272 | H187: 7975890 | I187: 6191247 | J187: 6452218 | K187: 22715700 | L187: 37565730 | M187: 14712240 | N187: 22796800 | O187: 45725440
A188: =VLOOKUP(B188,'[1]PORTFOLIO RAW'!B:B,1,FALSE) -> 328228 | B188: 328228 | C188: MICROCHIP TECHNOLOGY - MARKET CAPITALIZATION | D188: 328228(WC08001) | E188: 6831964 | F188: 3600136 | G188: 5309443 | H188: 6340110 | I188: 6942913 | J188: 6294776 | K188: 8792160 | L188: 9022123 | M188: 9404817 | N188: 13091843 | O188: 20132751
A189: =VLOOKUP(B189,'[1]PORTFOLIO RAW'!B:B,1,FALSE) -> 902172 | B189: 902172 | C189: 3M COMPANY - MARKET CAPITALIZATION | D189: 902172(WC08001) | E189: 59796037 | F189: 39906481 | G189: 58745229 | H189: 61443668 | I189: 56799901 | J189: 63796460 | K189: 93027298 | L189: 104365316 | M189: 91789490 | N189: 106557411 | O189: 140017903
A190: =VLOOKUP(B190,'[1]PORTFOLIO RAW'!B:B,1,FALSE) -> 325475 | B190: 325475 | C190: MOHAWK INDUSTRIES - MARKET CAPITALIZATION | D190: 325475(WC08001) | E190: 5085835 | F190: 2940050 | G190: 3259838 | H190: 3895382 | I190: 4116543 | J190: 6256272 | K190: 10822945 | L190: 11327764 | M190: 14001413 | N190: 14809866 | O190: 20532754
A191: =VLOOKUP(B191,'[1]PORTFOLIO RAW'!B:B,1,FALSE) -> 905010 | B191: 905010 | C191: XCEL ENERGY INC - MARKET CAPITALIZATION | D191: 905010(WC08001) | E191: 9677626 | F191: 8417837 | G191: 9708347 | H191: 11358960 | I191: 13446692 | J191: 13033399 | K191: 13913324 | L191: 18165939 | M191: 18225601 | N191: 20643968 | O191: 24428472
...

Sheet NI
A1: NET INCOME
B2: 1 | C2: 2 | D2: 3 | E2: 4 | F2: 5 | G2: 6 | H2: 7 | I2: 8 | J2: 9 | K2: 10 | L2: 11 | M2: 12 | N2: 13 | O2: 14
B3: Code | C3: Name | D3: Code | E3: 2007 | F3: 2008 | G3: 2009 | H3: 2010 | I3: 2011 | J3: 2012 | K3: 2013 | L3: 2014 | M3: 2015 | N3: 2016 | O3: 2017
A4: 902172 | B4: 902172 | C4: 3M COMPANY - NET INCOME - BASIC | D4: 902172(WC01706) | E4: 4096000 | F4: 3460000 | G4: 3193000 | H4: 4085000 | I4: 4283000 | J4: 4444000 | K4: 4659000 | L4: 4956000 | M4: 4833000 | N4: 5050000 | O4: 5620000
A5: 916328 | B5: 916328 | C5: ABBOTT LABORATORIES - NET INCOME - BASIC | D5: 916328(WC01706) | E5: 3606314 | F5: 4734216 | G5: 5745838 | H5: 4626172 | I5: 4728449 | J5: 5962920 | K5: 2576000 | L5: 2284000 | M5: 2671000 | N5: 1384000 | O5: 1937000
A6: 14352P | B6: 14352P | C6: ACCENTURE PLC - NET INCOME - BASIC | D6: 14352P(WC01706) | E6: 1243148 | F6: 1691751 | G6: 1589963 | H6: 1780656 | I6: 2277677 | J6: 2553510 | K6: 3281878 | L6: 2941498 | M6: 3053581 | N6: 4111892 | O6: 3445149
A7: 312367 | B7: 312367 | C7: ACTIVISION BLIZZARD - NET INCOME - BASIC | D7: 312367(WC01706) | E7: 227000 | F7: -107000 | G7: 113000 | H7: 414000 | I7: 1069000 | J7: 1125000 | K7: 998000 | L7: 847000 | M7: 881000 | N7: 962000 | O7: 909000
A8: 749382 | B8: 749382 | C8: ADOBE INC - NET INCOME - BASIC | D8: 749382(WC01706) | E8: 723807 | F8: 871814 | G8: 386508 | H8: 774680 | I8: 832847 | J8: 832775 | K8: 289985 | L8: 268395 | M8: 629551 | N8: 1168782 | O8: 1693954
A9: 14806F | B9: 14806F | C9: ADVANCE AUTO PARTS - NET INCOME - BASIC | D9: 14806F(WC01706) | E9: 238317 | F9: 238038 | G9: 270373 | H9: 344501 | I9: 393627 | J9: 386800 | K9: 390863 | L9: 492270 | M9: 471745 | N9: 457677 | O9: 331705
A10: 936365 | B10: 936365 | C10: ADVANCED MICRO - NET INCOME - BASIC | D10: 936365(WC01706) | E10: -3379000 | F10: -3098000 | G10: 304000 | H10: 471000 | I10: 491000 | J10: -1183000 | K10: -83000 | L10: -403000 | M10: -660000 | N10: -497000 | O10: -1087000
A11: 545101 | B11: 545101 | C11: AES CORP - NET INCOME - BASIC | D11: 545101(WC01706) | E11: 495000 | F11: 1228000 | G11: 808000 | H11: -55000 | I11: -28000 | J11: -928000 | K11: 266000 | L11: 825000 | M11: 306000 | N11: -11000 | O11: -511000
A12: 933185 | B12: 933185 | C12: AFLAC INCORPORATED - NET INCOME - BASIC | D12: 933185(WC01706) | E12: 1634000 | F12: 1254000 | G12: 1497000 | H12: 2344000 | I12: 1964000 | J12: 2866000 | K12: 3158000 | L12: 2951000 | M12: 2533000 | N12: 2659000 | O12: 2671000
A13: 277642 | B13: 277642 | C13: AGILENT TECHNOLOGIES - NET INCOME - BASIC | D13: 277642(WC01706) | E13: 638000 | F13: 693000 | G13: -31000 | H13: 684000 | I13: 1012000 | J13: 1153000 | K13: 724000 | L13: 504000 | M13: 401000 | N13: 462000 | O13: 684000
A14: 905271 | B14: 905271 | C14: AIR PRODUCTS & CHEMS - NET INCOME - BASIC | D14: 905271(WC01706) | E14: 1042700 | F14: 1090500 | G14: 631400 | H14: 1029100 | I14: 1224200 | J14: 1046500 | K14: 994200 | L14: 991700 | M14: 1277900 | N14: 631100 | O14: 1219900
A15: 277355 | B15: 277355 | C15: AKAMAI TECHNOLOGIES - NET INCOME - BASIC | D15: 277355(WC01706) | E15: 100967 | F15: 145138 | G15: 145913 | H15: 171220 | I15: 200904 | J15: 203989 | K15: 293487 | L15: 333948 | M15: 321406 | N15: 316132 | O15: 244321
A16: 130298 | B16: 130298 | C16: ALBEMARLE CORP - NET INCOME - BASIC | D16: 130298(WC01706) | E16: 229690 | F16: 194202 | G16: 178368 | H16: 323720 | I16: 436280 | J16: 311536 | K16: 413171 | L16: 133316 | M16: 334906 | N16: 643675 | O16: 474350
A17: 325596 | B17: 325596 | C17: ALLERGAN PLC - NET INCOME - BASIC | D17: 325596(WC01706) | E17: 141030 | F17: 238379 | G17: 222000 | H17: 184400 | I17: 260900 | J17: 97300 | K17: -750400 | L17: -1630500 | M17: 3683200 | N17: 14695000 | O17: -7203900
A18: 906979 | B18: 906979 | C18: ALLIANT ENERGY CORP - NET INCOME - BASIC | D18: 906979(WC01706) | E18: 424700 | F18: 288000 | G18: 111000 | H18: 287600 | I18: 303600 | J18: 319800 | K18: 358300 | L18: 383100 | M18: 378200 | N18: 371500 | O18: 439200
A19: 322677 | B19: 322677 | C19: ALLSTATE CORP - NET INCOME - BASIC | D19: 322677(WC01706) | E19: 4636000 | F19: -1679000 | G19: 854000 | H19: 928000 | I19: 788000 | J19: 2306000 | K19: 2263000 | L19: 2746000 | M19: 2055000 | N19: 1761000 | O19: 2567000
A20: 29026M | B20: 29026M | C20: ALPHABET INC - NET INCOME - BASIC | D20: 29026M(WC01706) | E20: 4203720 | F20: 4226858 | G20: 6520448 | H20: 8505000 | I20: 9737000 | J20: 10737000 | K20: 12920000 | L20: 14444000 | M20: 15826000 | N20: 19478000 | O20: 22486000
A21: 904853 | B21: 904853 | C21: ALTRIA GROUP INC - NET INCOME - BASIC | D21: 904853(WC01706) | E21: 9786000 | F21: 3090000 | G21: 3206000 | H21: 3890000 | I21: 3377000 | J21: 4167000 | K21: 4523000 | L21: 5058000 | M21: 5231000 | N21: 14215000 | O21: 6841000
A22: 891399 | B22: 891399 | C22: AMAZON.COM INC - NET INCOME - BASIC | D22: 891399(WC01706) | E22: 476000 | F22: 645000 | G22: 902000 | H22: 1152000 | I22: 631000 | J22: -39000 | K22: 274000 | L22: -241000 | M22: 596000 | N22: 2371000 | O22: 2244000
A23: 670942 | B23: 670942 | C23: AMEREN CORPORATION - NET INCOME - BASIC | D23: 670942(WC01706) | E23: 618000 | F23: 607000 | G23: 612000 | H23: 139000 | I23: 519000 | J23: -974000 | K23: 289000 | L23: 586000 | M23: 630000 | N23: 653000 | O23: 677000
A24: 905425 | B24: 905425 | C24: AMERICAN ELECTRIC - NET INCOME - BASIC | D24: 905425(WC01706) | E24: 1144000 | F24: 1380000 | G24: 1362000 | H24: 1211000 | I24: 1568000 | J24: 1259000 | K24: 1480000 | L24: 1634000 | M24: 2047100 | N24: 610900 | O24: 1885900
A25: 906156 | B25: 906156 | C25: AMERICAN EXPRESS CO - NET INCOME - BASIC | D25: 906156(WC01706) | E25: 4012000 | F25: 2688000 | G25: 1802000 | H25: 4006000 | I25: 4877000 | J25: 4433000 | K25: 5312000 | L25: 5839000 | M25: 5063000 | N25: 5285000 | O25: 5234000
A26: 916305 | B26: 916305 | C26: AMERICAN INT'L GROUP - NET INCOME - BASIC | D26: 916305(WC01706) | E26: 6200000 | F26: -99689000 | G26: -12244000 | H26: 1583000 | I26: 16986000 | J26: 3438000 | K26: 9085000 | L26: 7529000 | M26: 2196000 | N26: -849000 | O26: 616000
A27: 680902 | B27: 680902 | C27: AMERICAN TOWER CORP - NET INCOME - BASIC | D27: 680902(WC01706) | E27: 56316 | F27: 347246 | G27: 246595 | H27: 372936 | I27: 396462 | J27: 637283 | K27: 551333 | L27: 801022 | M27: 594911 | N27: 849300 | O27: 1151500
A28: 31604H | B28: 31604H | C28: AMERIPRISE FIN - NET INCOME - BASIC | D28: 31604H(WC01706) | E28: 814000 | F28: -38000 | G28: 722000 | H28: 1097000 | I28: 1050000 | J28: 1036000 | K28: 1334000 | L28: 1619000 | M28: 1562000 | N28: 1314000 | O28: 1766000
A29: 154680 | B29: 154680 | C29: AMERISOURCEBERGEN - NET INCOME - BASIC | D29: 154680(WC01706) | E29: 493768 | F29: 469064 | G29: 511852 | H29: 636748 | I29: 706624 | J29: 718986 | K29: 433707 | L29: 276484 | M29: -134887 | N29: 1427929 | O29: 364484
A30: 938692 | B30: 938692 | C30: AMGEN INC - NET INCOME - BASIC | D30: 938692(WC01706) | E30: 3166000 | F30: 4196000 | G30: 4605000 | H30: 4627000 | I30: 3683000 | J30: 4345000 | K30: 5081000 | L30: 5158000 | M30: 6939000 | N30: 7722000 | O30: 8079000
A31: 546075 | B31: 546075 | C31: AMPHENOL CORP - NET INCOME - BASIC | D31: 546075(WC01706) | E31: 353194 | F31: 419151 | G31: 317834 | H31: 496405 | I31: 524191 | J31: 555317 | K31: 635672 | L31: 709100 | M31: 763500 | N31: 822900 | O31: 1049000
A32: 905276 | B32: 905276 | C32: ANALOG DEVICES, INC. - NET INCOME - BASIC | D32: 905276(WC01706) | E32: 496907 | F32: 525177 | G32: 247772 | H32: 711225 | I32: 860894 | J32: 651236 | K32: 673487 | L32: 629320 | M32: 696878 | N32: 861664 | O32: 725016
A33: 14737P | B33: 14737P | C33: ANTHEM INC - NET INCOME - BASIC | D33: 14737P(WC01706) | E33: 3345400 | F33: 2490700 | G33: 4745900 | H33: 2887100 | I33: 2646700 | J33: 2655500 | K33: 2489700 | L33: 2569700 | M33: 2560000 | N33: 2469800 | O33: 2734500
A34: 922817 | B34: 922817 | C34: AON PLC - NET INCOME - BASIC | D34: 922817(WC01706) | E34: 864000 | F34: 651000 | G34: 639000 | H34: 733000 | I34: 975000 | J34: 993000 | K34: 1113000 | L34: 1397000 | M34: 1385000 | N34: 1396000 | O34: 1576000
A35: 921983 | B35: 921983 | C35: APACHE CORPORATION - NET INCOME - BASIC | D35: 921983(WC01706) | E35: 2806678 | F35: 706274 | G35: -291692 | H35: 3000000 | I35: 4508000 | J35: 1925000 | K35: 2188000 | L35: -5403000 | M35: -23119000 | N35: -1405000 | O35: 1417000
A36: 992816 | B36: 992816 | C36: APPLE INC - NET INCOME - BASIC | D36: 992816(WC01706) | E36: 3496000 | F36: 4834000 | G36: 8235000 | H36: 14013000 | I36: 25922000 | J36: 41733000 | K36: 37037000 | L36: 39510000 | M36: 53394000 | N36: 45687000 | O36: 48351000
A37: 905296 | B37: 905296 | C37: APPLIED MATERIALS - NET INCOME - BASIC | D37: 905296(WC01706) | E37: 1710196 | F37: 960746 | G37: -305327 | H37: 937866 | I37: 1926000 | J37: 109000 | K37: 256000 | L37: 1072000 | M37: 1377000 | N37: 1721000 | O37: 3434000
A38: 132808 | B38: 132808 | C38: APT INVESTMENT & MGT - NET INCOME - BASIC | D38: 132808(WC01706) | E38: -114070 | F38: 361755 | G38: -114840 | H38: -125318 | I38: -103161 | J38: 82146 | K38: 203673 | L38: 11584 | M38: 55373 | N38: 23991 | O38: -8592
A39: 921093 | B39: 921093 | C39: ARCHER DANIELS MIDL. - NET INCOME - BASIC | D39: 921093(WC01706) | E39: 2162000 | F39: 1802000 | G39: 1707000 | H39: 1930000 | I39: 2036000 | J39: 1146000 | K39: 1342000 | L39: 2248000 | M39: 1849000 | N39: 1279000 | O39: 1216000
A40: 905113 | B40: 905113 | C40: ARCONIC INC - NET INCOME - BASIC | D40: 905113(WC01706) | E40: 2569000 | F40: -76000 | G40: -1153000 | H40: 253000 | I40: 608000 | J40: 189000 | K40: -2287000 | L40: 247000 | M40: -391000 | N40: -1010000 | O40: 145000
...

Sheet EBITDA
A1: EBITDA
B2: 1 | C2: 2 | D2: 3 | E2: 4 | F2: 5 | G2: 6 | H2: 7 | I2: 8 | J2: 9 | K2: 10 | L2: 11 | M2: 12 | N2: 13 | O2: 14
B3: Code | C3: Name | D3: Code | E3: 2007 | F3: 2008 | G3: 2009 | H3: 2010 | I3: 2011 | J3: 2012 | K3: 2013 | L3: 2014 | M3: 2015 | N3: 2016 | O3: 2017
A4: =VLOOKUP(B4,'PORTFOLIO RAW'!C:C,1,FALSE) -> 891399 | B4: 891399 | C4: AMAZON.COM INC - EBIT & DEPRECIATION | D4: 891399(WC18198) | E4: 1008000 | F4: 1312000 | G4: 1627000 | H4: 2193000 | I4: 2148000 | J4: 2795000 | K4: 3900000 | L4: 4845000 | M4: 8308000 | N4: 12492000 | O4: 16132000
A5: =VLOOKUP(B5,'PORTFOLIO RAW'!C:C,1,FALSE) -> 916328 | B5: 916328 | C5: ABBOTT LABORATORIES - EBIT & DEPRECIATION | D5: 916328(WC18198) | E5: 6419660 | F5: 8104592 | G5: 9493940 | H5: 9138274 | I5: 9260677 | J5: 9638224 | K5: 4299000 | L5: 4216000 | M5: 4818000 | N5: 3197000 | O5: 6156000
A6: =VLOOKUP(B6,'PORTFOLIO RAW'!C:C,1,FALSE) -> 545101 | B6: 545101 | C6: AES CORP - EBIT & DEPRECIATION | D6: 545101(WC18198) | E6: 4268000 | F6: 5596000 | G6: 4790000 | H6: 3622000 | I6: 5044000 | J6: 3280000 | K6: 3783000 | L6: 4294000 | M6: 3705000 | N6: 2744000 | O6: 3110000
A7: =VLOOKUP(B7,'PORTFOLIO RAW'!C:C,1,FALSE) -> 906187 | B7: 906187 | C7: INT'L BUSINESS MACHS - EBIT & DEPRECIATION | D7: 906187(WC18198) | E7: 20301000 | F7: 22838000 | G7: 23630000 | H7: 25025000 | I7: 26328000 | J7: 27048000 | K7: 24533000 | L7: 25168000 | M7: 20375000 | N7: 17449000 | O7: 16590000
A8: =VLOOKUP(B8,'PORTFOLIO RAW'!C:C,1,FALSE) -> 936365 | B8: 936365 | C8: ADVANCED MICRO - EBIT & DEPRECIATION | D8: 936365(WC18198) | E8: -1494000 | F8: -671000 | G8: 1974000 | H8: 1553000 | I8: 496000 | J8: -782000 | K8: 339000 | L8: -18000 | M8: -319000 | N8: -159000 | O8: 339000
A9: =VLOOKUP(B9,'PORTFOLIO RAW'!C:C,1,FALSE) -> 749382 | B9: 749382 | C9: ADOBE INC - EBIT & DEPRECIATION | D9: 749382(WC18198) | E9: 1262907 | F9: 1358796 | G9: 987350 | H9: 1264303 | I9: 1372387 | J9: 1486047 | K9: 744876 | L9: 734698 | M9: 1277438 | N9: 1837115 | O9: 2538040
A10: =VLOOKUP(B10,'PORTFOLIO RAW'!C:C,1,FALSE) -> 905271 | B10: 905271 | C10: AIR PRODUCTS & CHEMS - EBIT & DEPRECIATION | D10: 905271(WC18198) | E10: 2247700 | F10: 2364800 | G10: 1686600 | H10: 2252400 | I10: 2504300 | J10: 2129000 | K10: 2231400 | L10: 2280100 | M10: 2610900 | N10: 3016200 | O10: 2307700
A11: =VLOOKUP(B11,'PORTFOLIO RAW'!C:C,1,FALSE) -> 894371 | B11: 894371 | C11: BOSTON PROPERTIES - EBIT & DEPRECIATION | D11: 894371(WC18198) | E11: 1717571 | F11: 907372 | G11: 906955 | H11: 870003 | I11: 1061245 | J11: 1111776 | K11: 1640851 | L11: 1597604 | M11: 1848886 | N11: 1669155 | O11: 1543277
A12: =VLOOKUP(B12,'PORTFOLIO RAW'!C:C,1,FALSE) -> 322677 | B12: 322677 | C12: ALLSTATE CORP - EBIT & DEPRECIATION | D12: 322677(WC18198) | E12: 6917000 | F12: -2496000 | G12: 1879000 | H12: 1692000 | I12: 1491000 | J12: 3719000 | K12: 4131000 | L12: 4924000 | M12: 3945000 | N12: 3431000 | O12: 4809000
A13: =VLOOKUP(B13,'PORTFOLIO RAW'!C:C,1,FALSE) -> 906191 | B13: 906191 | C13: HONEYWELL INTERNATNL - EBIT & DEPRECIATION | D13: 906191(WC18198) | E13: 4604000 | F13: 5097000 | G13: 4368000 | H13: 4211000 | I13: 3676000 | J13: 5119000 | K13: 6711000 | L13: 7045000 | M13: 7779000 | N13: 7806000 | O13: 8294000
A14: =VLOOKUP(B14,'PORTFOLIO RAW'!C:C,1,FALSE) -> 938692 | B14: 938692 | C14: AMGEN INC - EBIT & DEPRECIATION | D14: 938692(WC18198) | E14: 5437000 | F14: 6567000 | G14: 6830000 | H14: 6937000 | I14: 5819000 | J14: 7150000 | K14: 8595000 | L14: 9809000 | M14: 11184000 | N14: 12542000 | O14: 12856000
A15: =VLOOKUP(B15,'PORTFOLIO RAW'!C:C,1,FALSE) -> 905802 | B15: 905802 | C15: HESS CORPORATION - EBIT & DEPRECIATION | D15: 905802(WC18198) | E15: 5360000 | F15: 6952000 | G15: 4313000 | H15: 6511000 | I15: 6323000 | J15: 7106000 | K15: 7669000 | L15: 5983000 | M15: 38000 | N15: -272000 | O15: -2570000
... A29: =VLOOKUP(B29,'PORTFOLIO RAW'!C:C,1,FALSE) -> 670942 | B29: 670942 | C29: AMEREN CORPORATION - EBIT & DEPRECIATION | D29: 670942(WC18198) | E29: 2176000 | F29: 2125000 | G29: 2229000 | H29: 1758000 | I29: 2061000 | J29: -424000 | K29: 1933000 | L29: 2056000 | M29: 2099000 | N29: 2268000 | O29: 2392000
A30: =VLOOKUP(B30,'PORTFOLIO RAW'!C:C,1,FALSE) -> 702259 | B30: 702259 | C30: AUTODESK INC - EBIT & DEPRECIATION | D30: 702259(WC18198) | E30: 534700 | F30: 344300 | G30: 196200 | H30: 377400 | I30: 478400 | J30: NA | K30: 418600 | L30: 242100 | M30: 159400 | N30: -337400 | O30: -395100
A31: =VLOOKUP(B31,'PORTFOLIO RAW'!C:C,1,FALSE) -> 912669 | B31: 912669 | C31: AUTOMATIC DATA PROC - EBIT & DEPRECIATION | D31: 912669(WC18198) | E31: 2007200 | F31: 2211600 | G31: 2246100 | H31: 2181000 | I31: 2259500 | J31: 2453100 | K31: 2410400 | L31: 2616900 | M31: 2355100 | N31: 2579500 | O31: 2927200
A32: =VLOOKUP(B32,'PORTFOLIO RAW'!C:C,1,FALSE) -> 544616 | B32: 544616 | C32: AUTOZONE INC - EBIT & DEPRECIATION | D32: 544616(WC18198) | E32: 1217496 | F32: 1297428 | G32: 1360382 | H32: 1514124 | I32: 1693070 | J32: 1842119 | K32: 2001955 | L32: 2083340 | M32: 2224575 | N32: 2360163 | O32: 2406622
A33: =VLOOKUP(B33,'PORTFOLIO RAW'!C:C,1,FALSE) -> 921161 | B33: 921161 | C33: AVERY DENNISON CORP - EBIT & DEPRECIATION | D33: 921161(WC18198) | E33: 715100 | F33: 664900 | G33: -445200 | H33: 670700 | I33: 546200 | J33: 548900 | K33: 626800 | L33: 629400 | M33: 657800 | N33: 713500 | O33: 826300
A34: =VLOOKUP(B34,'PORTFOLIO RAW'!C:C,1,FALSE) -> 932060 | B34: 932060 | C34: BALL CORPORATION - EBIT & DEPRECIATION | D34: 932060(WC18198) | E34: 794900 | F34: 887900 | G34: 931700 | H34: 1016400 | I34: 1138000 | J34: 1073400 | K34: 1067300 | L34: 1086400 | M34: 774200 | N34: 807000 | O34: 1528000
A35: =VLOOKUP(B35,'PORTFOLIO RAW'!C:C,1,FALSE) -> 874227 | B35: 874227 | C35: BERKSHIRE HATHAWAY - EBIT & DEPRECIATION | D35: 874227(WC18198) | E35: 24478000 | F35: 12347000 | G35: 16671000 | H35: 25888000 | I35: 22661000 | J35: 30126000 | K35: 38105000 | L35: 38728000 | M35: 46240000 | N35: 45142000 | O35: 35482000
A36: =VLOOKUP(B36,'PORTFOLIO RAW'!C:C,1,FALSE) -> 916365 | B36: 916365 | C36: BAXTER INTERNATIONAL - EBIT & DEPRECIATION | D36: 916365(WC18198) | E36: 2846000 | F36: 3255000 | G36: 3418000 | H36: 2779000 | I36: 3637000 | J36: 3698000 | K36: 3503000 | L36: 3611000 | M36: 1333000 | N36: 5843000 | O36: 2063000
A37: =VLOOKUP(B37,'PORTFOLIO RAW'!C:C,1,FALSE) -> 905876 | B37: 905876 | C37: BECTON, DICKINSON - EBIT & DEPRECIATION | D37: 905876(WC18198) | E37: 1691706 | F37: 2067372 | G37: 2143456 | H37: 2207692 | I37: 2299698 | J37: 2105920 | K37: 1850000 | L37: 2219000 | M37: 2001000 | N37: 2576000 | O37: 2588000
A38: =VLOOKUP(B38,'PORTFOLIO RAW'!C:C,1,FALSE) -> 945384 | B38: 945384 | C38: VERIZON COMMUNICATNS - EBIT & DEPRECIATION | D38: 945384(WC18198) | E38: 30166000 | F38: 31731000 | G38: 30649000 | H38: 31002000 | I38: 29362000 | J38: 28604000 | K38: 48408000 | L38: 34938000 | M38: 49263000 | N38: 41388000 | O38: 42134000
A39: =VLOOKUP(B39,'PORTFOLIO RAW'!C:C,1,FALSE) -> 929302 | B39: 929302 | C39: BEST BUY CO INC - EBIT & DEPRECIATION | D39: 929302(WC18198) | E39: 2670000 | F39: 2870000 | G39: 2587000 | H39: 3215000 | I39: 3143000 | J39: 940820 | K39: 1903000 | L39: 2133000 | M39: 2047000 | N39: 2542000 | O39: 2575000
A40: =VLOOKUP(B40,'PORTFOLIO RAW'!C:C,1,FALSE) -> 895784 | B40: 895784 | C40: SL GREEN REALTY CORP - EBIT & DEPRECIATION | D40: 895784(WC18198) | E40: 598725 | F40: 547709 | G40: 500310 | H40: 724810 | I40: 1218024 | J40: 783663 | K40: 816231 | L40: 933469 | M40: 1216001 | N40: 1417949 | O40: 758011
A41: =VLOOKUP(B41,'PORTFOLIO RAW'!C:C,1,FALSE) -> 878574 | B41: 878574 | C41: YUM! BRANDS INC - EBIT & DEPRECIATION | D41: 878574(WC18198) | E41: 1881000 | F41: 2119000 | G41: 2084000 | H41: 2369000 | I41: 2448000 | J41: 2932000 | K41: 2516000 | L41: 2288000 | M41: 2648000 | N41: 1960000 | O41: 3000000
A42: =VLOOKUP(B42,'PORTFOLIO RAW'!C:C,1,FALSE) -> 905159 | B42: 905159 | C42: FIRSTENERGY CORP - EBIT & DEPRECIATION | D42: 905159(WC18198) | E42: 3573000 | F42: 3498000 | G42: 2819000 | H42: 2657000 | I42: 3502000 | J42: 3377000 | K42: 2813000 | L42: 2426000 | M42: 3884000 | N42: -6751000 | O42: 1423000
... A44: =VLOOKUP(B44,'PORTFOLIO RAW'!C:C,1,FALSE) -> 904818 | B44: 904818 | C44: BOEING CO - EBIT & DEPRECIATION | D44: 904818(WC18198) | E44: 7908000 | F44: 5670000 | G44: 3662000 | H44: 6643000 | I44: 7401000 | J44: 8004000 | K44: 8462000 | L44: 9376000 | M44: 9263000 | N44: 7784000 | O44: 12476000
A45: =VLOOKUP(B45,'PORTFOLIO RAW'!C:C,1,FALSE) -> 923649 | B45: 923649 | C45: ROBERT HALF INTL INC - EBIT & DEPRECIATION | D45: 923649(WC18198) | E45: 565945 | F45: 497786 | G45: 132529 | H45: 171726 | I45: 301631 | J45: 392969 | K45: NA | L45: NA | M45: NA | N45: NA | O45: NA
A46: =VLOOKUP(B46,'PORTFOLIO RAW'!C:C,1,FALSE) -> 325824 | B46: 325824 | C46: BOSTON SCIENTIFIC - EBIT & DEPRECIATION | D46: 325824(WC18198) | E46: 940000 | F46: -699000 | G46: -61000 | H46: 146000 | I46: 1641000 | J46: -3161000 | K46: 790000 | L46: 432000 | M46: 403000 | N46: 1225000 | O46: 2006000
A47: =VLOOKUP(B47,'PORTFOLIO RAW'!C:C,1,FALSE) -> 879628 | B47: 879628 | C47: C.H. ROBINSON - EBIT & DEPRECIATION | D47: 879628(WC18198) | E47: 550880 | F47: 609551 | G47: 617575 | H47: 653471 | I47: 727202 | J47: NA | K47: 741343 | L47: 805427 | M47: 931919 | N47: 912200 | O47: 868096
A48: =VLOOKUP(B48,'PORTFOLIO RAW'!C:C,1,FALSE) -> 905080 | B48: 905080 | C48: BRISTOL-MYERS SQUIBB - EBIT & DEPRECIATION | D48: 905080(WC18198) | E48: 4324000 | F48: 5980000 | G48: 6086000 | H48: 6808000 | I48: 7646000 | J48: 3328000 | K48: 4235000 | L48: 3306000 | M48: 2861000 | N48: 6675000 | O48: 6109000
A49: =VLOOKUP(B49,'PORTFOLIO RAW'!C:C,1,FALSE) -> 130502 | B49: 130502 | C49: AVALONBAY COMMUNITIE - EBIT & DEPRECIATION | D49: 130502(WC18198) | E49: 467178 | F49: 418099 | G49: 435041 | H49: 505086 | I49: 575663 | J49: 636788 | K49: 801598 | L49: 1143050 | M49: 1327114 | N49: 1687995 | O49: 1589868
A50: =VLOOKUP(B50,'PORTFOLIO RAW'!C:C,1,FALSE) -> 902103 | B50: 902103 | C50: SEMPRA ENERGY - EBIT & DEPRECIATION | D50: 902103(WC18198) | E50: 2517000 | F50: 2018000 | G50: 2618000 | H50: 2381000 | I50: 3155000 | J50: 2845000 | K50: 3063000 | L50: 3161000 | M50: 3421000 | N50: 3072000 | O50: 3699000
A51: =VLOOKUP(B51,'PORTFOLIO RAW'!C:C,1,FALSE) -> 951849 | B51: 951849 | C51: FEDEX CORP - EBIT & DEPRECIATION | D51: 951849(WC18198) | E51: 5093000 | F51: 4060000 | G51: 2737000 | H51: 3931000 | I51: 4324000 | J51: 5306000 | K51: 4923000 | L51: 6072000 | M51: 4473000 | N51: 5707000 | O51: 8086000
A52: =VLOOKUP(B52,'PORTFOLIO RAW'!C:C,1,FALSE) -> 674693 | B52: 674693 | C52: VERISIGN, INC. - EBIT & DEPRECIATION | D52: 674693(WC18198) | E52: 121127 | F52: 292344 | G52: 414907 | H52: 320676 | I52: 396625 | J52: 517710 | K52: 609988 | L52: 632995 | M52: 670902 | N52: 754904 | O52: 786119
A53: =VLOOKUP(B53,'PORTFOLIO RAW'!C:C,1,FALSE) -> 546075 | B53: 546075 | C53: AMPHENOL CORP - EBIT & DEPRECIATION | D53: 546075(WC18198) | E53: 630726 | F53: 723509 | G53: 581637 | H53: 807275 | I53: 879220 | J53: 960233 | K53: 1046680 | L53: 1221000 | M53: 1292700 | N53: 1430700 | O53: 1671500
A54: =VLOOKUP(B54,'PORTFOLIO RAW'!C:C,1,FALSE) -> 912216 | B54: 912216 | C54: BROWN FORMAN CORP - EBIT & DEPRECIATION | D54: 912216(WC18198) | E54: 664000 | F54: 745000 | G54: 722000 | H54: 772000 | I54: 917000 | J54: 843000 | K54: 952000 | L54: 1023000 | M54: 1080000 | N54: 1591000 | O54: 1050000
...

Sheet EQIT
A1: EQUITY
B2: 1 | C2: 2 | D2: 3 | E2: 4 | F2: 5 | G2: 6 | H2: 7 | I2: 8 | J2: 9 | K2: 10 | L2: 11 | M2: 12 | N2: 13 | O2: 14
B3: Code | C3: Name | D3: Code | E3: 2007 | F3: 2008 | G3: 2009 | H3: 2010 | I3: 2011 | J3: 2012 | K3: 2013 | L3: 2014 | M3: 2015 | N3: 2016 | O3: 2017
A4: =VLOOKUP(B4,'[1]PORTFOLIO RAW'!B:B,1,FALSE) -> 891399 | B4: 891399 | C4: AMAZON.COM INC - COMMON SHAREHOLDERS' EQUITY | D4: 891399(WC03501) | E4: 1197000 | F4: 2672000 | G4: 5257000 | H4: 6864000 | I4: 7757000 | J4: 8192000 | K4: 9746000 | L4: 10741000 | M4: 13384000 | N4: 19285000 | O4: 27709000
