Workbook

Sheet PORTFOLIO RAW
A2: NAME | B2: Code
A3: MMM | B3: 902172
A4: ABT | B4: 916328
A5: ACN | B5: 14352P
A6: ATVI.O | B6: 312367
A7: ADBE.O | B7: 749382
A8: AAP | B8: 14806F
A9: AMD.O | B9: 936365
A10: AES | B10: 545101
A11: AFL | B11: 933185
A12: A | B12: 277642
A13: APD | B13: 905271
A14: AKAM.O | B14: 277355
A15: ALB | B15: 130298
A16: AGN | B16: 325596
A17: LNT.O | B17: 906979
A18: ALL | B18: 322677
A19: GOOG.O | B19: 29026M
A20: MO | B20: 904853
A21: AMZN.O | B21: 891399
A22: AEE | B22: 670942
A23: AEP | B23: 905425
A24: AXP | B24: 906156
A25: AIG | B25: 916305
A26: AMT | B26: 680902
A27: AMP | B27: 31604H
A28: ABC | B28: 154680
A29: AMGN.O | B29: 938692
A30: APH | B30: 546075
A31: ADI.O | B31: 905276
A32: ANTM.K | B32: 14737P
A33: AON | B33: 922817
A34: APA | B34: 921983
A35: AIV | B35: 132808
A36: AAPL.O | B36: 992816
A37: AMAT.O | B37: 905296
A38: ADM | B38: 921093
A39: ARNC.K | B39: 905113
A40: AIZ | B40: 28341F
A41: T | B41: 945388
...

Sheet MB
A1: Market to Book Ratio
A2: Code | B2: Code | C2: Name | D2: Code | E2: 2007 | F2: 2008 | G2: 2009 | H2: 2010 | I2: 2011 | J2: 2012 | K2: 2013 | L2: 2014 | M2: 2015 | N2: 2016 | O2: 2017
A3: =VLOOKUP(B3,'[1]PORTFOLIO RAW'!B:B,1,FALSE) -> 891399 | B3: 891399 | C3: AMAZON.COM - MRKT VALUE TO BOOK | D3: 891399(MTBV) | E3: 30.96 | F3: 12.91 | G3: 7.42 | H3: 9.87 | I3: 13.65 | J3: 14.39 | K3: 14.83 | L3: 14.25 | M3: 18.88 | N3: 19.18 | O3: 16.87
A4: =VLOOKUP(B4,'[1]PORTFOLIO RAW'!B:B,1,FALSE) -> 916328 | B4: 916328 | C4: ABBOTT LABORATORIES - MRKT VALUE TO BOOK | D4: 916328(MTBV) | E4: 4.67 | F4: 5.18 | G4: 3.11 | H4: 3.6 | I4: 3.36 | J4: 4.1 | K4: 2.18 | L4: 3.04 | M4: 3.04 | N4: 2.98 | O4: 2.92
A5: =VLOOKUP(B5,'[1]PORTFOLIO RAW'!B:B,1,FALSE) -> 545101 | B5: 545101 | C5: AES - MRKT VALUE TO BOOK | D5: 545101(MTBV) | E5: 4.08 | F5: 2.42 | G5: 2.05 | H5: 1.4 | I5: 1.41 | J5: 1.83 | K5: 2.29 | L5: 2.49 | M5: 2.37 | N5: 3.01 | O5: 3.02
A6: =VLOOKUP(B6,'[1]PORTFOLIO RAW'!B:B,1,FALSE) -> 906187 | B6: 906187 | C6: INTERNATIONAL BUS.MCHS. - MRKT VALUE TO BOOK | D6: 906187(MTBV) | E6: 5.58 | F6: 11.96 | G6: 7.07 | H6: 7.21 | I6: 10.36 | J6: 12.49 | K6: 9.13 | L6: 16.31 | M6: 9.93 | N6: 8.09 | O6: 7.73
A7: =VLOOKUP(B7,'[1]PORTFOLIO RAW'!B:B,1,FALSE) -> 936365 | B7: 936365 | C7: ADVANCED MICRO DEVICES - MRKT VALUE TO BOOK | D7: 936365(MTBV) | E7: 2.47 | F7: -40.13 | G7: 5.87 | H7: 4.06 | I7: 2.93 | J7: 4.72 | K7: 5.07 | L7: 15.65 | M7: -3.54 | N7: 13.27 | O7: 21.29
A8: =VLOOKUP(B8,'[1]PORTFOLIO RAW'!B:B,1,FALSE) -> 749382 | B8: 749382 | C8: ADOBE (NAS) - MRKT VALUE TO BOOK | D8: 749382(MTBV) | E8: 5.42 | F8: 4.92 | G8: 3.54 | H8: 3.35 | I8: 2.1 | J8: 2.55 | K8: 3.91 | L8: 4.93 | M8: 5.79 | N8: 6.75 | O8: 8.75
A9: =VLOOKUP(B9,'[1]PORTFOLIO RAW'!B:B,1,FALSE) -> 905271 | B9: 905271 | C9: AIR PRDS.& CHEMS. - MRKT VALUE TO BOOK | D9: 905271(MTBV) | E9: 3.65 | F9: 3.51 | G9: 3.52 | H9: 3.18 | I9: 3.02 | J9: 2.78 | K9: 3.23 | L9: 3.89 | M9: 3.99 | N9: 4.5 | O9: 3.26
A10: =VLOOKUP(B10,'[1]PORTFOLIO RAW'!B:B,1,FALSE) -> 894371 | B10: 894371 | C10: BOSTON PROPERTIES - MRKT VALUE TO BOOK | D10: 894371(MTBV) | E10: 3.36 | F10: 3.23 | G10: 2.2 | H10: 2.83 | I10: 3.01 | J10: 3.33 | K10: 3.01 | L10: 3.15 | M10: 3.19 | N10: 3.72 | O10: 3.32
A11: =VLOOKUP(B11,'[1]PORTFOLIO RAW'!B:B,1,FALSE) -> 322677 | B11: 322677 | C11: ALLSTATE ORD SHS - MRKT VALUE TO BOOK | D11: 322677(MTBV) | E11: 1.56 | F11: 1.57 | G11: 0.94 | H11: 0.94 | I11: 0.73 | J11: 1.09 | K11: 1.26 | L11: 1.45 | M11: 1.31 | N11: 1.42 | O11: 1.73
A12: =VLOOKUP(B12,'[1]PORTFOLIO RAW'!B:B,1,FALSE) -> 906191 | B12: 906191 | C12: HONEYWELL INTL. - MRKT VALUE TO BOOK | D12: 906191(MTBV) | E12: 4.72 | F12: 4.69 | G12: 3.42 | H12: 3.21 | I12: 3.39 | J12: 3.64 | K12: 3.84 | L12: 4.28 | M12: 4.19 | N12: 4.51 | O12: 6.11
A13: =VLOOKUP(B13,'[1]PORTFOLIO RAW'!B:B,1,FALSE) -> 938692 | B13: 938692 | C13: AMGEN - MRKT VALUE TO BOOK | D13: 938692(MTBV) | E13: 3.36 | F13: 3.11 | G13: 2.72 | H13: 2.24 | I13: 2.79 | J13: 3.33 | K13: 3.98 | L13: 4.24 | M13: 4.07 | N13: 4.34 | O13: 5.44
A14: =VLOOKUP(B14,'[1]PORTFOLIO RAW'!B:B,1,FALSE) -> 905802 | B14: 905802 | C14: HESS - MRKT VALUE TO BOOK | D14: 905802(MTBV) | E14: 2.16 | F14: 2.51 | G14: 1.36 | H14: 1.12 | I14: 1.1 | J14: 0.9 | K14: 1.09 | L14: 1.35 | M14: 0.78 | N14: 1 | O14: 1.25
... A108: =VLOOKUP(B108,'[1]PORTFOLIO RAW'!B:B,1,FALSE) -> 905016 | B108: 905016 | C108: NEXTERA ENERGY - MRKT VALUE TO BOOK | D108: 905016(MTBV) | E108: 2.37 | F108: 1.96 | G108: 1.75 | H108: 1.57 | I108: 1.57 | J108: 1.77 | K108: 1.9 | L108: 2.08 | M108: 1.98 | N108: 2.37 | O108: 2.44
A109: =VLOOKUP(B109,'[1]PORTFOLIO RAW'!B:B,1,FALSE) -> 28341F | B109: 28341F | C109: ASSURANT - MRKT VALUE TO BOOK | D109: 28341F(MTBV) | E109: 1.51 | F109: 1.54 | G109: 0.81 | H109: 0.99 | I109: 0.77 | J109: 0.59 | K109: 0.94 | L109: 1.09 | M109: 1.26 | N109: 1.49 | O109: 1.37
A110: =VLOOKUP(B110,'[1]PORTFOLIO RAW'!B:B,1,FALSE) -> 755980 | B110: 755980 | C110: FASTENAL - MRKT VALUE TO BOOK | D110: 755980(MTBV) | E110: 6.65 | F110: 6.97 | G110: 4.86 | H110: 6 | I110: 7.41 | J110: 8.33 | K110: 8.4 | L110: 7.16 | M110: 5.99 | N110: 5.97 | O110: 6.12
A111: =VLOOKUP(B111,'[1]PORTFOLIO RAW'!B:B,1,FALSE) -> 905994 | B111: 905994 | C111: FEDERAL REALTY INV.TST. - MRKT VALUE TO BOOK | D111: 905994(MTBV) | E111: 4.41 | F111: 4.71 | G111: 3.32 | H111: 4.49 | I111: 4.42 | J111: 5.28 | K111: 4.69 | L111: 5.07 | M111: 5.63 | N111: 5.6 | O111: 4.27
A112: =VLOOKUP(B112,'[1]PORTFOLIO RAW'!B:B,1,FALSE) -> 997198 | B112: 997198 | C112: FIFTH THIRD BANCORP - MRKT VALUE TO BOOK | D112: 997198(MTBV) | E112: 2.07 | F112: 1.39 | G112: 0.84 | H112: 0.96 | I112: 0.75 | J112: 1.08 | K112: 1.23 | L112: 1.22 | M112: 1.05 | N112: 1.06 | O112: 1.34
A113: =VLOOKUP(B113,'[1]PORTFOLIO RAW'!B:B,1,FALSE) -> 951503 | B113: 951503 | C113: M&T BANK - MRKT VALUE TO BOOK | D113: 951503(MTBV) | E113: 1.79 | F113: 1.67 | G113: 1.12 | H113: 1.43 | I113: 1.07 | J113: 1.28 | K113: 1.39 | L113: 1.52 | M113: 1.06 | N113: 1.19 | O113: 1.56
A114: =VLOOKUP(B114,'[1]PORTFOLIO RAW'!B:B,1,FALSE) -> 741123 | B114: 741123 | C114: FISERV - MRKT VALUE TO BOOK | D114: 741123(MTBV) | E114: 3.3 | F114: 3.26 | G114: 2.52 | H114: 2.52 | I114: 2.33 | J114: 2.92 | K114: 3.7 | L114: 4.97 | M114: 7.63 | N114: 8.59 | O114: 9.64
A115: =VLOOKUP(B115,'[1]PORTFOLIO RAW'!B:B,1,FALSE) -> 546814 | B115: 546814 | C115: MACY'S - MRKT VALUE TO BOOK | D115: 546814(MTBV) | E115: 1.49 | F115: 1.81 | G115: 1.61 | H115: 1.69 | I115: 1.97 | J115: 2.57 | K115: 2.69 | L115: 3.95 | M115: 4.21 | N115: 2.49 | O115: 1.15
A116: =VLOOKUP(B116,'[1]PORTFOLIO RAW'!B:B,1,FALSE) -> 938076 | B116: 938076 | C116: FRANKLIN RESOURCES - MRKT VALUE TO BOOK | D116: 938076(MTBV) | E116: 4.34 | F116: 3.58 | G116: 3.12 | H116: 3.15 | I116: 2.98 | J116: 2.9 | K116: 3.27 | L116: 3.01 | M116: 2 | N116: 1.69 | O116: 1.9
A117: =VLOOKUP(B117,'[1]PORTFOLIO RAW'!B:B,1,FALSE) -> 152594 | B117: 152594 | C117: FREEPORT-MCMORAN - MRKT VALUE TO BOOK | D117: 152594(MTBV) | E117: 2.88 | F117: 13.66 | G117: 4.63 | H117: 3.14 | I117: 2.34 | J117: 2.21 | K117: 1.68 | L117: 1.94 | M117: 1.58 | N117: 2.18 | O117: 2.57
A118: =VLOOKUP(B118,'[1]PORTFOLIO RAW'!B:B,1,FALSE) -> 951018 | B118: 951018 | C118: GAP - MRKT VALUE TO BOOK | D118: 951018(MTBV) | E118: 3.4 | F118: 3.09 | G118: 3.14 | H118: 2.91 | I118: 3.1 | J118: 6.01 | K118: 6.34 | L118: 6.4 | M118: 5.05 | N118: 3.1 | O118: 3.49
A119: =VLOOKUP(B119,'[1]PORTFOLIO RAW'!B:B,1,FALSE) -> 907652 | B119: 907652 | C119: GENERAL DYNAMICS - MRKT VALUE TO BOOK | D119: 907652(MTBV) | E119: 2.87 | F119: 3.26 | G119: 2 | H119: 1.82 | I119: 1.63 | J119: 2.05 | K119: 2.13 | L119: 3.66 | M119: 4.18 | N119: 4.22 | O119: 5.35
A120: =VLOOKUP(B120,'[1]PORTFOLIO RAW'!B:B,1,FALSE) -> 905801 | B120: 905801 | C120: GENERAL MILLS - MRKT VALUE TO BOOK | D120: 905801(MTBV) | E120: 3.07 | F120: 4.52 | G120: 3.65 | H120: 3.64 | I120: 3.76 | J120: 3.91 | K120: 4.72 | L120: 6.2 | M120: 6.86 | N120: 8.84 | O120: 4.83
A121: =VLOOKUP(B121,'[1]PORTFOLIO RAW'!B:B,1,FALSE) -> 906511 | B121: 906511 | C121: GENUINE PARTS - MRKT VALUE TO BOOK | D121: 906511(MTBV) | E121: 3.18 | F121: 2.94 | G121: 2.29 | H121: 2.5 | I121: 2.94 | J121: 3.24 | K121: 3.76 | L121: 4.14 | M121: 4.01 | N121: 4.6 | O121: 3.73
... A234: =VLOOKUP(B234,'[1]PORTFOLIO RAW'!B:B,1,FALSE) -> 933974 | B234: 933974 | C234: TRAVELERS COS. - MRKT VALUE TO BOOK | D234: 933974(MTBV) | E234: 1.3 | F234: 1.18 | G234: 1.06 | H234: 1.07 | I234: 0.98 | J234: 1.18 | K234: 1.37 | L234: 1.4 | M234: 1.39 | N234: 1.47 | O234: 1.48
A235: =VLOOKUP(B235,'[1]PORTFOLIO RAW'!B:B,1,FALSE) -> 14015T | B235: 14015T | C235: FIDELITY NAT.INFO.SVS. - MRKT VALUE TO BOOK | D235: 14015T(MTBV) | E235: 2.35 | F235: 1.09 | G235: 0.58 | H235: 1.29 | I235: 1.22 | J235: 1.44 | K235: 2.08 | L235: 2.49 | M235: 2.06 | N235: 2.58 | O235: 2.85
A236: =VLOOKUP(B236,'[1]PORTFOLIO RAW'!B:B,1,FALSE) -> 905019 | B236: 905019 | C236: MERCK & COMPANY - MRKT VALUE TO BOOK | D236: 905019(MTBV) | E236: 6.13 | F236: 3.64 | G236: 1.14 | H236: 2.07 | I236: 1.84 | J236: 2.58 | K236: 2.82 | L236: 3.59 | M236: 3.29 | N236: 4.27 | O236: 5.23
A237: =VLOOKUP(B237,'[1]PORTFOLIO RAW'!B:B,1,FALSE) -> 912090 | B237: 912090 | C237: SCHLUMBERGER - MRKT VALUE TO BOOK | D237: 912090(MTBV) | E237: 8.6 | F237: 6.45 | G237: 3.87 | H237: 2.58 | I237: 2.99 | J237: 2.87 | K237: 2.93 | L237: 3.54 | M237: 2.58 | N237: 2.55 | O237: 2.54
A238: =VLOOKUP(B238,'[1]PORTFOLIO RAW'!B:B,1,FALSE) -> 755741 | B238: 755741 | C238: CHARLES SCHWAB - MRKT VALUE TO BOOK | D238: 755741(MTBV) | E238: 7.07 | F238: 7.16 | G238: 4.03 | H238: 2.68 | I238: 1.86 | J238: 1.97 | K238: 2.88 | L238: 3.63 | M238: 3.14 | N238: 2.99 | O238: 3.55
A239: =VLOOKUP(B239,'[1]PORTFOLIO RAW'!B:B,1,FALSE) -> 14361V | B239: 14361V | C239: ZIMMER BIOMET HDG. - MRKT VALUE TO BOOK | D239: 14361V(MTBV) | E239: 3.61 | F239: 2.71 | G239: 1.94 | H239: 1.8 | I239: 1.98 | J239: 1.99 | K239: 2.24 | L239: 2.69 | M239: 2.04 | N239: 2.58 | O239: 2
A240: =VLOOKUP(B240,'[1]PORTFOLIO RAW'!B:B,1,FALSE) -> 154680 | B240: 154680 | C240: AMERISOURCEBERGEN - MRKT VALUE TO BOOK | D240: 154680(MTBV) | E240: 2.65 | F240: 2.31 | G240: 2.38 | H240: 2.89 | I240: 3.73 | J240: 3.93 | K240: 6.14 | L240: 8.87 | M240: 36.21 | N240: 9.17 | O240: 8.44
A241: =VLOOKUP(B241,'[1]PORTFOLIO RAW'!B:B,1,FALSE) -> 14698C | B241: 14698C | C241: PRINCIPAL FINL.GP. - MRKT VALUE TO BOOK | D241: 14698C(MTBV) | E241: 2.32 | F241: 2.11 | G241: 1.09 | H241: 0.93 | I241: 0.88 | J241: 1.01 | K241: 1.35 | L241: 1.57 | M241: 1.52 | N241: 1.38 | O241: 1.61
A242: =VLOOKUP(B242,'[1]PORTFOLIO RAW'!B:B,1,FALSE) -> 905361 | B242: 905361 | C242: SHERWIN-WILLIAMS - MRKT VALUE TO BOOK | D242: 905361(MTBV) | E242: 4.93 | F242: 4.64 | G242: 4.84 | H242: 5.05 | I242: 5.2 | J242: 8.99 | K242: 10.66 | L242: 21.64 | M242: 26.49 | N242: 13.51 | O242: 8.78
A243: =VLOOKUP(B243,'[1]PORTFOLIO RAW'!B:B,1,FALSE) -> 357834 | B243: 357834 | C243: SIMON PROPERTY GROUP - MRKT VALUE TO BOOK | D243: 357834(MTBV) | E243: 7.85 | F243: 8.69 | G243: 4.71 | H243: 5.95 | I243: 7.63 | J243: 8.06 | K243: 8.07 | L243: 10.2 | M243: 12.86 | N243: 15.37 | O243: 13.64
A244: =VLOOKUP(B244,'[1]PORTFOLIO RAW'!B:B,1,FALSE) -> 906400 | B244: 906400 | C244: SNAP-ON - MRKT VALUE TO BOOK | D244: 906400(MTBV) | E244: 2.22 | F244: 2.83 | G244: 1.65 | H244: 1.96 | I244: 1.9 | J244: 2.33 | K244: 2.78 | L244: 3.26 | M244: 3.75 | N244: 3.32 | O244: 2.91
A245: =VLOOKUP(B245,'[1]PORTFOLIO RAW'!B:B,1,FALSE) -> 14861V | B245: 14861V | C245: PRUDENTIAL FINL. - MRKT VALUE TO BOOK | D245: 14861V(MTBV) | E245: 1.86 | F245: 1.83 | G245: 0.99 | H245: 0.9 | I245: 0.75 | J245: 0.98 | K245: 1.45 | L245: 1.89 | M245: 1.31 | N245: 1.26 | O245: 1.33
...

Sheet MCAP
A1: Market Capitalization
E2: 4 | F2: 5 | G2: 6 | H2: 7 | I2: 8 | J2: 9 | K2: 10 | L2: 11 | M2: 12 | N2: 13 | O2: 14 | P2: 15
B3: Code | C3: Name | D3: Code | E3: 2007 | F3: 2008 | G3: 2009 | H3: 2010 | I3: 2011 | J3: 2012 | K3: 2013 | L3: 2014 | M3: 2015 | N3: 2016 | O3: 2017 | P3: 2018
A4: =VLOOKUP(B4,'[1]PORTFOLIO RAW'!B:B,1,FALSE) -> 891399 | B4: 891399 | C4: AMAZON.COM INC - MARKET CAPITALIZATION | D4: 891399(WC08001) | E4: 38538240 | F4: 21947840 | G4: 59726880 | H4: 81180000 | I4: 78760500 | J4: 113894980 | K4: 183044610 | L4: 144312750 | M4: 318344190 | N4: 357687990 | O4: 566023480 | P4: 737467270
A5: =VLOOKUP(B5,'[1]PORTFOLIO RAW'!B:B,1,FALSE) -> 916328 | B5: 916328 | C5: ABBOTT LABORATORIES - MARKET CAPITALIZATION | D5: 916328(WC08001) | E5: 87027454 | F5: 82853346 | G5: 83747538 | H5: 74116001 | I5: 88302401 | J5: 103271721 | K5: 59338607 | L5: 67891755 | M5: 66137387 | N5: 56572906 | O5: 99507393 | P5: 126983953
A6: =VLOOKUP(B6,'[1]PORTFOLIO RAW'!B:B,1,FALSE) -> 545101 | B6: 545101 | C6: AES CORP - MARKET CAPITALIZATION | D6: 545101(WC08001) | E6: 14338569 | F6: 5461363 | G6: 8886820 | H6: 9593056 | I6: 9059806 | J6: 7963623 | K6: 10483596 | L6: 9692032 | M6: 6381360 | N6: 7659698 | O6: 7152003 | P6: 9576830
A7: =VLOOKUP(B7,'[1]PORTFOLIO RAW'!B:B,1,FALSE) -> 906187 | B7: 906187 | C7: INT'L BUSINESS MACHS - MARKET CAPITALIZATION | D7: 906187(WC08001) | E7: 149743810 | F7: 112698313 | G7: 170868669 | H7: 180220333 | I7: 213886010 | J7: 214031778 | K7: 197772108 | L7: 158919632 | M7: 132903587 | N7: 157004530 | O7: 141480737 | P7: 101448135
A8: =VLOOKUP(B8,'[1]PORTFOLIO RAW'!B:B,1,FALSE) -> 936365 | B8: 936365 | C8: ADVANCED MICRO - MARKET CAPITALIZATION | D8: 936365(WC08001) | E8: 4545000 | F8: 1315440 | G8: 6495280 | H8: 5586940 | I8: 3763800 | J8: 1711200 | K8: 2805750 | L8: 2071920 | M8: 2273040 | N8: 10602900 | O8: 9940760 | P8: 18552300
A9: =VLOOKUP(B9,'[1]PORTFOLIO RAW'!B:B,1,FALSE) -> 749382 | B9: 749382 | C9: ADOBE INC - MARKET CAPITALIZATION | D9: 749382(WC08001) | E9: 24416307 | F9: 11200903 | G9: 19223324 | H9: 15448390 | I9: 13895836 | J9: 18618894 | K9: 29715612 | L9: 36167087 | M9: 46764177 | N9: 50883449 | O9: 86088753 | P9: 110328877
A10: =VLOOKUP(B10,'[1]PORTFOLIO RAW'!B:B,1,FALSE) -> 905271 | B10: 905271 | C10: AIR PRODUCTS & CHEMS - MARKET CAPITALIZATION | D10: 905271(WC08001) | E10: 21240531 | F10: 10523252 | G10: 17124757 | H10: 19445371 | I10: 17905682 | J10: 17852223 | K10: 23605617 | L10: 30798607 | M10: 28020374 | N10: 31259396 | O10: 35826224 | P10: 35133415
A11: =VLOOKUP(B11,'[1]PORTFOLIO RAW'!B:B,1,FALSE) -> 894371 | B11: 894371 | C11: BOSTON PROPERTIES - MARKET CAPITALIZATION | D11: 894371(WC08001) | E11: 10971523 | F11: 6664936 | G11: 9314682 | H11: 12071143 | I11: 14751518 | J11: 16040924 | K11: 15354914 | L11: 19704234 | M11: 19587589 | N11: 19343728 | O11: 20066917 | P11: 17384302
A12: =VLOOKUP(B12,'[1]PORTFOLIO RAW'!B:B,1,FALSE) -> 322677 | B12: 322677 | C12: ALLSTATE CORP - MARKET CAPITALIZATION | D12: 322677(WC08001) | E12: 29405490 | F12: 17559360 | G12: 16131480 | H12: 16992040 | I12: 13732410 | J12: 19241430 | K12: 24488460 | L12: 29364500 | M12: 23656290 | N12: 27127920 | O12: 37172050 | P12: 27433160
A13: =VLOOKUP(B13,'[1]PORTFOLIO RAW'!B:B,1,FALSE) -> 906191 | B13: 906191 | C13: HONEYWELL INTERNATNL - MARKET CAPITALIZATION | D13: 906191(WC08001) | E13: 45965321 | F13: 24116466 | G13: 29957004 | H13: 41624280 | I13: 42104945 | J13: 49684316 | K13: 71615806 | L13: 78157424 | M13: 79790328 | N13: 88138680 | O13: 115158024 | P13: 96394752
A14: =VLOOKUP(B14,'[1]PORTFOLIO RAW'!B:B,1,FALSE) -> 938692 | B14: 938692 | C14: AMGEN INC - MARKET CAPITALIZATION | D14: 938692(WC08001) | E14: 50480280 | F14: 60464250 | G14: 56287150 | H14: 51166800 | I14: 51085476 | J14: 65193060 | K14: 86084768 | L14: 121124116 | M14: 122396820 | N14: 107932222 | O14: 125590580 | P14: 122564232
A15: =VLOOKUP(B15,'[1]PORTFOLIO RAW'!B:B,1,FALSE) -> 905802 | B15: 905802 | C15: HESS CORPORATION - MARKET CAPITALIZATION | D15: 905802(WC08001) | E15: 32335674 | F15: 17493760 | G15: 19797384 | H15: 25846087 | I15: 19310615 | J15: 18087303 | K15: 27001077 | L15: 21100337 | M15: 13867490 | N15: 19716230 | O15: 14955595 | P15: 11803099
... A109: =VLOOKUP(B109,'[1]PORTFOLIO RAW'!B:B,1,FALSE) -> 905016 | B109: 905016 | C109: NEXTERA ENERGY - MARKET CAPITALIZATION | D109: 905016(WC08001) | E109: 27609842 | F109: 20580707 | G109: 21847537 | H109: 21880591 | I109: 25326080 | J109: 29336560 | K109: 37244700 | L109: 47086470 | M109: 47893290 | N109: 55907280 | O109: 73565490 | P109: 83085960
A110: =VLOOKUP(B110,'[1]PORTFOLIO RAW'!B:B,1,FALSE) -> 28341F | B110: 28341F | C110: ASSURANT INC - MARKET CAPITALIZATION | D110: 28341F(WC08001) | E110: 7881356 | F110: 3521056 | G110: 3438804 | H110: 3929054 | I110: 3634811 | J110: 2729642 | K110: 4767238 | L110: 4742169 | M110: 5303590 | N110: 5194726 | O110: 5285812 | P110: 5537139
A111: =VLOOKUP(B111,'[1]PORTFOLIO RAW'!B:B,1,FALSE) -> 755980 | B111: 755980 | C111: FASTENAL COMPANY - MARKET CAPITALIZATION | D111: 755980(WC08001) | E111: 6027459 | F111: 5176295 | G111: 6139015 | H111: 8832574 | I111: 12876231 | J111: 13834728 | K111: 14098761 | L111: 14071475 | M111: 11820724 | N111: 13584827 | O111: 15728381 | P111: 14949811
A112: =VLOOKUP(B112,'[1]PORTFOLIO RAW'!B:B,1,FALSE) -> 905994 | B112: 905994 | C112: FEDERAL REALTY INVST - MARKET CAPITALIZATION | D112: 905994(WC08001) | E112: 4817741 | F112: 3661831 | G112: 4147312 | H112: 4794754 | I112: 5766632 | J112: 6742103 | K112: 6764191 | L112: 9156128 | M112: 10152985 | N112: 10231337 | O112: 9707199 | P112: 8764427
A113: =VLOOKUP(B113,'[1]PORTFOLIO RAW'!B:B,1,FALSE) -> 997198 | B113: 997198 | C113: FIFTH THIRD BANCORP - MARKET CAPITALIZATION | D113: 997198(WC08001) | E113: 13385532 | F113: 4769217 | G113: 7751913 | H113: 11689281 | I113: 11699912 | J113: 13408711 | K113: 17987080 | L113: 16789957 | M113: 15780114 | N113: 20240427 | O113: 21050040 | P113: 15215224
A114: =VLOOKUP(B114,'[1]PORTFOLIO RAW'!B:B,1,FALSE) -> 951503 | B114: 951503 | C114: M&T BANK CORPORATION - MARKET CAPITALIZATION | D114: 951503(WC08001) | E114: 8960656 | F114: 6336072 | G114: 7907916 | H114: 10420115 | I114: 9594671 | J114: 12621581 | K114: 15194715 | L114: 16621150 | M114: 19335906 | N114: 24431384 | O114: 25662932 | P114: 19824903
A115: =VLOOKUP(B115,'[1]PORTFOLIO RAW'!B:B,1,FALSE) -> 741123 | B115: 741123 | C115: FISERV INC - MARKET CAPITALIZATION | D115: 741123(WC08001) | E115: 9161399 | F115: 5670083 | G115: 7427136 | H115: 8602464 | I115: 8229474 | J115: 10542602 | K115: 15158135 | L115: 17054091 | M115: 20605938 | N115: 22903340 | O115: 27222588 | P115: 28844825
A116: =VLOOKUP(B116,'[1]PORTFOLIO RAW'!B:B,1,FALSE) -> 546814 | B116: 546814 | C116: MACY'S INC - MARKET CAPITALIZATION | D116: 546814(WC08001) | E116: 10857639 | F116: 4348035 | G116: 7052608 | H116: 10709490 | I116: 13328956 | J116: 15128054 | K116: 19487529 | L116: 22392721 | M116: 10852758 | N116: 10888489 | O116: 7677030 | P116: 9157350
A117: =VLOOKUP(B117,'[1]PORTFOLIO RAW'!B:B,1,FALSE) -> 938076 | B117: 938076 | C117: FRANKLIN RESOURCES - MARKET CAPITALIZATION | D117: 938076(WC08001) | E117: 28089120 | F117: 14846580 | G117: 24159320 | H117: 24911893 | I117: 20911631 | J117: 26674666 | K117: 36422869 | L117: 34489590 | M117: 22221503 | N117: 22574261 | O117: 24042315 | P117: 15397176
A118: =VLOOKUP(B118,'[1]PORTFOLIO RAW'!B:B,1,FALSE) -> 152594 | B118: 152594 | C118: FREEPORT-MCMORAN INC - MARKET CAPITALIZATION | D118: 152594(WC08001) | E118: 39234520 | F118: 9384960 | G118: 34524700 | H118: 56742525 | I118: 34876920 | J118: 32455800 | K118: 39174120 | L118: 24271040 | M118: 8435420 | N118: 19059550 | O118: 27454080 | P118: 14939190
A119: =VLOOKUP(B119,'[1]PORTFOLIO RAW'!B:B,1,FALSE) -> 951018 | B119: 951018 | C119: GAP INC - MARKET CAPITALIZATION | D119: 951018(WC08001) | E119: 15619520 | F119: 9292660 | G119: 14162200 | H119: 13018320 | I119: 8996750 | J119: 14371520 | K119: 17429680 | L119: 17728310 | M119: 9805900 | N119: 8953560 | O119: 13249340 | P119: 9737280
A120: =VLOOKUP(B120,'[1]PORTFOLIO RAW'!B:B,1,FALSE) -> 907652 | B120: 907652 | C120: GENERAL DYNAMICS - MARKET CAPITALIZATION | D120: 907652(WC08001) | E120: 42882558 | F120: 27751506 | G120: 26293489 | H120: 26400832 | I120: 23671040 | J120: 24499015 | K120: 33767637 | L120: 45712423 | M120: 42991932 | N120: 52215583 | O120: 60403411 | P120: 45386236
A121: =VLOOKUP(B121,'[1]PORTFOLIO RAW'!B:B,1,FALSE) -> 905801 | B121: 905801 | C121: GENERAL MILLS, INC. - MARKET CAPITALIZATION | D121: 905801(WC08001) | E121: 19380000 | F121: 20503125 | G121: 23225680 | H121: 23364835 | I121: 26056368 | J121: 26212370 | K121: 31982328 | L121: 32653959 | M121: 34521042 | N121: 36864336 | O121: 34204401 | P121: 23095314
A122: =VLOOKUP(B122,'[1]PORTFOLIO RAW'!B:B,1,FALSE) -> 906511 | B122: 906511 | C122: GENUINE PARTS CO - MARKET CAPITALIZATION | D122: 906511(WC08001) | E122: 7688821 | F122: 6036244 | G122: 6032521 | H122: 8093046 | I122: 9525848 | J122: 9844819 | K122: 12792384 | L122: 16317257 | M122: 12890498 | N122: 14179132 | O122: 13933465 | P122: 14012834
... A181: =VLOOKUP(B181,'[1]PORTFOLIO RAW'!B:B,1,FALSE) -> 771830 | B181: 771830 | C181: MAXIM INTEGRATED PRD - MARKET CAPITALIZATION | D181: 771830(WC08001) | E181: 8488256 | F181: 3660715 | G181: 6218306 | H181: 7106030 | I181: 7702111 | J181: 8606321 | K181: 8024598 | L181: 9065135 | M181: 10823274 | N181: 10950370 | O181: 14790639 | P181: 14170064
A182: =VLOOKUP(B182,'[1]PORTFOLIO RAW'!B:B,1,FALSE) -> 312367 | B182: 312367 | C182: ACTIVISION BLIZZARD - MARKET CAPITALIZATION | D182: 312367(WC08001) | E182: NA | F182: 11225706 | G182: 13892290 | H182: 14720499 | I182: 13963382 | J182: 11805257 | K182: 12547131 | L182: 14546879 | M182: 28432598 | N182: 26919521 | O182: 47965229 | P182: 35552354
A183: =VLOOKUP(B183,'[1]PORTFOLIO RAW'!B:B,1,FALSE) -> 912635 | B183: 912635 | C183: CVS HEALTH CORP - MARKET CAPITALIZATION | D183: 912635(WC08001) | E183: 57099166 | F183: 41350106 | G183: 44804110 | H183: 47391510 | I183: 52932440 | J183: 59518850 | K183: 84452600 | L183: 109793400 | M183: 107644770 | N183: 83723510 | O183: 73515000 | P183: 84848400
A184: =VLOOKUP(B184,'[1]PORTFOLIO RAW'!B:B,1,FALSE) -> 152533 | B184: 152533 | C184: LAB CORP OF AMERICA - MARKET CAPITALIZATION | D184: 152533(WC08001) | E184: 8383830 | F184: 6969162 | G184: 7880652 | H184: 9003008 | I184: 8407866 | J184: 8098970 | K184: 7830409 | L184: 9128340 | M184: 12524732 | N184: 13184626 | O184: 16254069 | P184: 12497004
A185: =VLOOKUP(B185,'[1]PORTFOLIO RAW'!B:B,1,FALSE) -> 719643 | B185: 719643 | C185: MICROSOFT CORP - MARKET CAPITALIZATION | D185: 719643(WC08001) | E185: 333928000 | F185: 177895440 | G185: 271515840 | H185: 241923880 | I185: 217440960 | J185: 223853996 | K185: 311550480 | L185: 382701550 | M185: 445337960 | N185: 485189120 | O185: 659342320 | P185: 779752890
A186: =VLOOKUP(B186,'[1]PORTFOLIO RAW'!B:B,1,FALSE) -> 999506 | B186: 999506 | C186: MICRON TECHNOLOGY - MARKET CAPITALIZATION | D186: 999506(WC08001) | E186: 5494775 | F186: 2009304 | G186: 8962272 | H186: 7975890 | I186: 6191247 | J186: 6452218 | K186: 22715700 | L186: 37565730 | M186: 14712240 | N186: 22796800 | O186: 45725440 | P186: 36838530
A187: =VLOOKUP(B187,'[1]PORTFOLIO RAW'!B:B,1,FALSE) -> 328228 | B187: 328228 | C187: MICROCHIP TECHNOLOGY - MARKET CAPITALIZATION | D187: 328228(WC08001) | E187: 6831964 | F187: 3600136 | G187: 5309443 | H187: 6340110 | I187: 6942913 | J187: 6294776 | K187: 8792160 | L187: 9022123 | M187: 9404817 | N187: 13091843 | O187: 20132751 | P187: 16903197
A188: =VLOOKUP(B188,'[1]PORTFOLIO RAW'!B:B,1,FALSE) -> 902172 | B188: 902172 | C188: 3M COMPANY - MARKET CAPITALIZATION | D188: 902172(WC08001) | E188: 59796037 | F188: 39906481 | G188: 58745229 | H188: 61443668 | I188: 56799901 | J188: 63796460 | K188: 93027298 | L188: 104365316 | M188: 91789490 | N188: 106557411 | O188: 140017903 | P188: 109860633
A189: =VLOOKUP(B189,'[1]PORTFOLIO RAW'!B:B,1,FALSE) -> 325475 | B189: 325475 | C189: MOHAWK INDUSTRIES - MARKET CAPITALIZATION | D189: 325475(WC08001) | E189: 5085835 | F189: 2940050 | G189: 3259838 | H189: 3895382 | I189: 4116543 | J189: 6256272 | K189: 10822945 | L189: 11327764 | M189: 14001413 | N189: 14809866 | O189: 20532754 | P189: 8457027
A190: =VLOOKUP(B190,'[1]PORTFOLIO RAW'!B:B,1,FALSE) -> 905010 | B190: 905010 | C190: XCEL ENERGY INC - MARKET CAPITALIZATION | D190: 905010(WC08001) | E190: 9677626 | F190: 8417837 | G190: 9708347 | H190: 11358960 | I190: 13446692 | J190: 13033399 | K190: 13913324 | L190: 18165939 | M190: 18225601 | N190: 20643968 | O190: 24428472 | P190: 25326592
A191: =VLOOKUP(B191,'[1]PORTFOLIO RAW'!B:B,1,FALSE) -> 902230 | B191: 902230 | C191: FORD MOTOR COMPANY - MARKET CAPITALIZATION | D191: 902230(WC08001) | E191: 14772350 | F191: 5523480 | G191: 33370000 | H191: 63511717 | I191: 40896036 | J191: 50793107 | K191: 61473120 | L191: 62139500 | M191: 56796790 | N191: 49090110 | O191: 50684420 | P191: 31143150
...

Sheet NI
A1: Net Income
B2: Name | C2: Code | D2: Name | E2: Code | F2: 2007 | G2: 2008 | H2: 2009 | I2: 2010 | J2: 2011 | K2: 2012 | L2: 2013 | M2: 2014 | N2: 2015 | O2: 2016 | P2: 2017
A3: 902172 | B3: 3M COMPANY | C3: 902172 | D3: 3M COMPANY - NET INCOME - BASIC | E3: 902172(WC01706) | F3: 4096000 | G3: 3460000 | H3: 3193000 | I3: 4085000 | J3: 4283000 | K3: 4444000 | L3: 4659000 | M3: 4956000 | N3: 4833000 | O3: 5050000 | P3: 5620000
A4: 916328 | B4: ABBOTT LABORATORIES | C4: 916328 | D4: ABBOTT LABORATORIES - NET INCOME - BASIC | E4: 916328(WC01706) | F4: 3606314 | G4: 4734216 | H4: 5745838 | I4: 4626172 | J4: 4728449 | K4: 5962920 | L4: 2576000 | M4: 2284000 | N4: 2671000 | O4: 1384000 | P4: 1937000
A5: 14352P | B5: ACCENTURE PLC | C5: 14352P | D5: ACCENTURE PLC - NET INCOME - BASIC | E5: 14352P(WC01706) | F5: 1243148 | G5: 1691751 | H5: 1589963 | I5: 1780656 | J5: 2277677 | K5: 2553510 | L5: 3281878 | M5: 2941498 | N5: 3053581 | O5: 4111892 | P5: 3445149
A6: 312367 | B6: ACTIVISION BLIZZARD | C6: 312367 | D6: ACTIVISION BLIZZARD - NET INCOME - BASIC | E6: 312367(WC01706) | F6: 227000 | G6: -107000 | H6: 113000 | I6: 414000 | J6: 1069000 | K6: 1125000 | L6: 998000 | M6: 847000 | N6: 881000 | O6: 962000 | P6: 909000
A7: 749382 | B7: ADOBE INC | C7: 749382 | D7: ADOBE INC - NET INCOME - BASIC | E7: 749382(WC01706) | F7: 723807 | G7: 871814 | H7: 386508 | I7: 774680 | J7: 832847 | K7: 832775 | L7: 289985 | M7: 268395 | N7: 629551 | O7: 1168782 | P7: 1693954
A8: 14806F | B8: ADVANCE AUTO PARTS | C8: 14806F | D8: ADVANCE AUTO PARTS - NET INCOME - BASIC | E8: 14806F(WC01706) | F8: 238317 | G8: 238038 | H8: 270373 | I8: 344501 | J8: 393627 | K8: 386800 | L8: 390863 | M8: 492270 | N8: 471745 | O8: 457677 | P8: 331705
A9: 936365 | B9: ADVANCED MICRO | C9: 936365 | D9: ADVANCED MICRO - NET INCOME - BASIC | E9: 936365(WC01706) | F9: -3379000 | G9: -3098000 | H9: 304000 | I9: 471000 | J9: 491000 | K9: -1183000 | L9: -83000 | M9: -403000 | N9: -660000 | O9: -497000 | P9: -1087000
A10: 545101 | B10: AES CORP | C10: 545101 | D10: AES CORP - NET INCOME - BASIC | E10: 545101(WC01706) | F10: 495000 | G10: 1228000 | H10: 808000 | I10: -55000 | J10: -28000 | K10: -928000 | L10: 266000 | M10: 825000 | N10: 306000 | O10: -11000 | P10: -511000
A11: 933185 | B11: AFLAC INCORPORATED | C11: 933185 | D11: AFLAC INCORPORATED - NET INCOME - BASIC | E11: 933185(WC01706) | F11: 1634000 | G11: 1254000 | H11: 1497000 | I11: 2344000 | J11: 1964000 | K11: 2866000 | L11: 3158000 | M11: 2951000 | N11: 2533000 | O11: 2659000 | P11: 2671000
A12: 277642 | B12: AGILENT TECHNOLOGIES | C12: 277642 | D12: AGILENT TECHNOLOGIES - NET INCOME - BASIC | E12: 277642(WC01706) | F12: 638000 | G12: 693000 | H12: -31000 | I12: 684000 | J12: 1012000 | K12: 1153000 | L12: 724000 | M12: 504000 | N12: 401000 | O12: 462000 | P12: 684000
A13: 905271 | B13: AIR PRODUCTS & CHEMS | C13: 905271 | D13: AIR PRODUCTS & CHEMS - NET INCOME - BASIC | E13: 905271(WC01706) | F13: 1042700 | G13: 1090500 | H13: 631400 | I13: 1029100 | J13: 1224200 | K13: 1046500 | L13: 994200 | M13: 991700 | N13: 1277900 | O13: 631100 | P13: 1219900
A14: 277355 | B14: AKAMAI TECHNOLOGIES | C14: 277355 | D14: AKAMAI TECHNOLOGIES - NET INCOME - BASIC | E14: 277355(WC01706) | F14: 100967 | G14: 145138 | H14: 145913 | I14: 171220 | J14: 200904 | K14: 203989 | L14: 293487 | M14: 333948 | N14: 321406 | O14: 316132 | P14: 244321
A15: 130298 | B15: ALBEMARLE CORP | C15: 130298 | D15: ALBEMARLE CORP - NET INCOME - BASIC | E15: 130298(WC01706) | F15: 229690 | G15: 194202 | H15: 178368 | I15: 323720 | J15: 436280 | K15: 311536 | L15: 413171 | M15: 133316 | N15: 334906 | O15: 643675 | P15: 474350
A16: 325596 | B16: ALLERGAN PLC | C16: 325596 | D16: ALLERGAN PLC - NET INCOME - BASIC | E16: 325596(WC01706) | F16: 141030 | G16: 238379 | H16: 222000 | I16: 184400 | J16: 260900 | K16: 97300 | L16: -750400 | M16: -1630500 | N16: 3683200 | O16: 14695000 | P16: -7203900
A17: 906979 | B17: ALLIANT ENERGY CORP | C17: 906979 | D17: ALLIANT ENERGY CORP - NET INCOME - BASIC | E17: 906979(WC01706) | F17: 424700 | G17: 288000 | H17: 111000 | I17: 287600 | J17: 303600 | K17: 319800 | L17: 358300 | M17: 383100 | N17: 378200 | O17: 371500 | P17: 439200
A18: 322677 | B18: ALLSTATE CORP | C18: 322677 | D18: ALLSTATE CORP - NET INCOME - BASIC | E18: 322677(WC01706) | F18: 4636000 | G18: -1679000 | H18: 854000 | I18: 928000 | J18: 788000 | K18: 2306000 | L18: 2263000 | M18: 2746000 | N18: 2055000 | O18: 1761000 | P18: 2567000
A19: 29026M | B19: ALPHABET INC | C19: 29026M | D19: ALPHABET INC - NET INCOME - BASIC | E19: 29026M(WC01706) | F19: 4203720 | G19: 4226858 | H19: 6520448 | I19: 8505000 | J19: 9737000 | K19: 10737000 | L19: 12920000 | M19: 14444000 | N19: 15826000 | O19: 19478000 | P19: 22486000
A20: 904853 | B20: ALTRIA GROUP INC | C20: 904853 | D20: ALTRIA GROUP INC - NET INCOME - BASIC | E20: 904853(WC01706) | F20: 9786000 | G20: 3090000 | H20: 3206000 | I20: 3890000 | J20: 3377000 | K20: 4167000 | L20: 4523000 | M20: 5058000 | N20: 5231000 | O20: 14215000 | P20: 6841000
A21: 891399 | B21: AMAZON.COM INC | C21: 891399 | D21: AMAZON.COM INC - NET INCOME - BASIC | E21: 891399(WC01706) | F21: 476000 | G21: 645000 | H21: 902000 | I21: 1152000 | J21: 631000 | K21: -39000 | L21: 274000 | M21: -241000 | N21: 596000 | O21: 2371000 | P21: 2244000
A22: 670942 | B22: AMEREN CORPORATION | C22: 670942 | D22: AMEREN CORPORATION - NET INCOME - BASIC | E22: 670942(WC01706) | F22: 618000 | G22: 607000 | H22: 612000 | I22: 139000 | J22: 519000 | K22: -974000 | L22: 289000 | M22: 586000 | N22: 630000 | O22: 653000 | P22: 677000
A23: 905425 | B23: AMERICAN ELECTRIC | C23: 905425 | D23: AMERICAN ELECTRIC - NET INCOME - BASIC | E23: 905425(WC01706) | F23: 1144000 | G23: 1380000 | H23: 1362000 | I23: 1211000 | J23: 1568000 | K23: 1259000 | L23: 1480000 | M23: 1634000 | N23: 2047100 | O23: 610900 | P23: 1885900
A24: 906156 | B24: AMERICAN EXPRESS CO | C24: 906156 | D24: AMERICAN EXPRESS CO - NET INCOME - BASIC | E24: 906156(WC01706) | F24: 4012000 | G24: 2688000 | H24: 1802000 | I24: 4006000 | J24: 4877000 | K24: 4433000 | L24: 5312000 | M24: 5839000 | N24: 5063000 | O24: 5285000 | P24: 5234000
A25: 916305 | B25: AMERICAN INT'L GROUP | C25: 916305 | D25: AMERICAN INT'L GROUP - NET INCOME - BASIC | E25: 916305(WC01706) | F25: 6200000 | G25: -99689000 | H25: -12244000 | I25: 1583000 | J25: 16986000 | K25: 3438000 | L25: 9085000 | M25: 7529000 | N25: 2196000 | O25: -849000 | P25: 616000
A26: 680902 | B26: AMERICAN TOWER CORP | C26: 680902 | D26: AMERICAN TOWER CORP - NET INCOME - BASIC | E26: 680902(WC01706) | F26: 56316 | G26: 347246 | H26: 246595 | I26: 372936 | J26: 396462 | K26: 637283 | L26: 551333 | M26: 801022 | N26: 594911 | O26: 849300 | P26: 1151500
A27: 31604H | B27: AMERIPRISE FIN | C27: 31604H | D27: AMERIPRISE FIN - NET INCOME - BASIC | E27: 31604H(WC01706) | F27: 814000 | G27: -38000 | H27: 722000 | I27: 1097000 | J27: 1050000 | K27: 1036000 | L27: 1334000 | M27: 1619000 | N27: 1562000 | O27: 1314000 | P27: 1766000
A28: 154680 | B28: AMERISOURCEBERGEN | C28: 154680 | D28: AMERISOURCEBERGEN - NET INCOME - BASIC | E28: 154680(WC01706) | F28: 493768 | G28: 469064 | H28: 511852 | I28: 636748 | J28: 706624 | K28: 718986 | L28: 433707 | M28: 276484 | N28: -134887 | O28: 1427929 | P28: 364484
A29: 938692 | B29: AMGEN INC | C29: 938692 | D29: AMGEN INC - NET INCOME - BASIC | E29: 938692(WC01706) | F29: 3166000 | G29: 4196000 | H29: 4605000 | I29: 4627000 | J29: 3683000 | K29: 4345000 | L29: 5081000 | M29: 5158000 | N29: 6939000 | O29: 7722000 | P29: 8079000
A30: 546075 | B30: AMPHENOL CORP | C30: 546075 | D30: AMPHENOL CORP - NET INCOME - BASIC | E30: 546075(WC01706) | F30: 353194 | G30: 419151 | H30: 317834 | I30: 496405 | J30: 524191 | K30: 555317 | L30: 635672 | M30: 709100 | N30: 763500 | O30: 822900 | P30: 1049000
A31: 905276 | B31: ANALOG DEVICES, INC. | C31: 905276 | D31: ANALOG DEVICES, INC. - NET INCOME - BASIC | E31: 905276(WC01706) | F31: 496907 | G31: 525177 | H31: 247772 | I31: 711225 | J31: 860894 | K31: 651236 | L31: 673487 | M31: 629320 | N31: 696878 | O31: 861664 | P31: 725016
A32: 14737P | B32: ANTHEM INC | C32: 14737P | D32: ANTHEM INC - NET INCOME - BASIC | E32: 14737P(WC01706) | F32: 3345400 | G32: 2490700 | H32: 4745900 | I32: 2887100 | J32: 2646700 | K32: 2655500 | L32: 2489700 | M32: 2569700 | N32: 2560000 | O32: 2469800 | P32: 2734500
A33: 922817 | B33: AON PLC | C33: 922817 | D33: AON PLC - NET INCOME - BASIC | E33: 922817(WC01706) | F33: 864000 | G33: 651000 | H33: 639000 | I33: 733000 | J33: 975000 | K33: 993000 | L33: 1113000 | M33: 1397000 | N33: 1385000 | O33: 1396000 | P33: 1576000
A34: 921983 | B34: APACHE CORPORATION | C34: 921983 | D34: APACHE CORPORATION - NET INCOME - BASIC | E34: 921983(WC01706) | F34: 2806678 | G34: 706274 | H34: -291692 | I34: 3000000 | J34: 4508000 | K34: 1925000 | L34: 2188000 | M34: -5403000 | N34: -23119000 | O34: -1405000 | P34: 1417000
A35: 992816 | B35: APPLE INC | C35: 992816 | D35: APPLE INC - NET INCOME - BASIC | E35: 992816(WC01706) | F35: 3496000 | G35: 4834000 | H35: 8235000 | I35: 14013000 | J35: 25922000 | K35: 41733000 | L35: 37037000 | M35: 39510000 | N35: 53394000 | O35: 45687000 | P35: 48351000
A36: 905296 | B36: APPLIED MATERIALS | C36: 905296 | D36: APPLIED MATERIALS - NET INCOME - BASIC | E36: 905296(WC01706) | F36: 1710196 | G36: 960746 | H36: -305327 | I36: 937866 | J36: 1926000 | K36: 109000 | L36: 256000 | M36: 1072000 | N36: 1377000 | O36: 1721000 | P36: 3434000
A37: 132808 | B37: APT INVESTMENT & MGT | C37: 132808 | D37: APT INVESTMENT & MGT - NET INCOME - BASIC | E37: 132808(WC01706) | F37: -114070 | G37: 361755 | H37: -114840 | I37: -125318 | J37: -103161 | K37: 82146 | L37: 203673 | M37: 11584 | N37: 55373 | O37: 23991 | P37: -8592
A38: 921093 | B38: ARCHER DANIELS MIDL. | C38: 921093 | D38: ARCHER DANIELS MIDL. - NET INCOME - BASIC | E38: 921093(WC01706) | F38: 2162000 | G38: 1802000 | H38: 1707000 | I38: 1930000 | J38: 2036000 | K38: 1146000 | L38: 1342000 | M38: 2248000 | N38: 1849000 | O38: 1279000 | P38: 1216000
A39: 905113 | B39: ARCONIC INC | C39: 905113 | D39: ARCONIC INC - NET INCOME - BASIC | E39: 905113(WC01706) | F39: 2569000 | G39: -76000 | H39: -1153000 | I39: 253000 | J39: 608000 | K39: 189000 | L39: -2287000 | M39: 247000 | N39: -391000 | O39: -1010000 | P39: 145000
A40: 28341F | B40: ASSURANT INC | C40: 28341F | D40: ASSURANT INC - NET INCOME - BASIC | E40: 28341F(WC01706) | F40: 653746 | G40: 447796 | H40: 430574 | I40: 279177 | J40: 545839 | K40: 483705 | L40: 488907 | M40: 470907 | N40: 141555 | O40: 565350 | P40: 342600
...

Sheet EBITDA
A1: EBITDA
E2: 4 | F2: 5 | G2: 6 | H2: 7 | I2: 8 | J2: 9 | K2: 10 | L2: 11 | M2: 12 | N2: 13 | O2: 14
B3: Code | C3: Name | D3: Code | E3: 2007 | F3: 2008 | G3: 2009 | H3: 2010 | I3: 2011 | J3: 2012 | K3: 2013 | L3: 2014 | M3: 2015 | N3: 2016 | O3: 2017
A4: =VLOOKUP(B4,'[1]PORTFOLIO RAW'!B:B,1,FALSE) -> 891399 | B4: 891399 | C4: AMAZON.COM INC - EBIT & DEPRECIATION | D4: 891399(WC18198) | E4: 1008000 | F4: 1312000 | G4: 1627000 | H4: 2193000 | I4: 2148000 | J4: 2795000 | K4: 3900000 | L4: 4845000 | M4: 8308000 | N4: 12492000 | O4: 16132000
A5: =VLOOKUP(B5,'[1]PORTFOLIO RAW'!B:B,1,FALSE) -> 916328 | B5: 916328 | C5: ABBOTT LABORATORIES - EBIT & DEPRECIATION | D5: 916328(WC18198) | E5: 6419660 | F5: 8104592 | G5: 9493940 | H5: 9138274 | I5: 9260677 | J5: 9638224 | K5: 4299000 | L5: 4216000 | M5: 4818000 | N5: 3197000 | O5: 6156000
A6: =VLOOKUP(B6,'[1]PORTFOLIO RAW'!B:B,1,FALSE) -> 545101 | B6: 545101 | C6: AES CORP - EBIT & DEPRECIATION | D6: 545101(WC18198) | E6: 4268000 | F6: 5596000 | G6: 4790000 | H6: 3622000 | I6: 5044000 | J6: 3280000 | K6: 3783000 | L6: 4294000 | M6: 3705000 | N6: 2744000 | O6: 3110000
A7: =VLOOKUP(B7,'[1]PORTFOLIO RAW'!B:B,1,FALSE) -> 906187 | B7: 906187 | C7: INT'L BUSINESS MACHS - EBIT & DEPRECIATION | D7: 906187(WC18198) | E7: 20301000 | F7: 22838000 | G7: 23630000 | H7: 25025000 | I7: 26328000 | J7: 27048000 | K7: 24533000 | L7: 25168000 | M7: 20375000 | N7: 17449000 | O7: 16590000
A8: =VLOOKUP(B8,'[1]PORTFOLIO RAW'!B:B,1,FALSE) -> 936365 | B8: 936365 | C8: ADVANCED MICRO - EBIT & DEPRECIATION | D8: 936365(WC18198) | E8: -1494000 | F8: -671000 | G8: 1974000 | H8: 1553000 | I8: 496000 | J8: -782000 | K8: 339000 | L8: -18000 | M8: -319000 | N8: -159000 | O8: 339000
A9: =VLOOKUP(B9,'[1]PORTFOLIO RAW'!B:B,1,FALSE) -> 749382 | B9: 749382 | C9: ADOBE INC - EBIT & DEPRECIATION | D9: 749382(WC18198) | E9: 1262907 | F9: 1358796 | G9: 987350 | H9: 1264303 | I9: 1372387 | J9: 1486047 | K9: 744876 | L9: 734698 | M9: 1277438 | N9: 1837115 | O9: 2538040
A10: =VLOOKUP(B10,'[1]PORTFOLIO RAW'!B:B,1,FALSE) -> 905271 | B10: 905271 | C10: AIR PRODUCTS & CHEMS - EBIT & DEPRECIATION | D10: 905271(WC18198) | E10: 2247700 | F10: 2364800 | G10: 1686600 | H10: 2252400 | I10: 2504300 | J10: 2129000 | K10: 2231400 | L10: 2280100 | M10: 2610900 | N10: 3016200 | O10: 2307700
A11: =VLOOKUP(B11,'[1]PORTFOLIO RAW'!B:B,1,FALSE) -> 894371 | B11: 894371 | C11: BOSTON PROPERTIES - EBIT & DEPRECIATION | D11: 894371(WC18198) | E11: 1717571 | F11: 907372 | G11: 906955 | H11: 870003 | I11: 1061245 | J11: 1111776 | K11: 1640851 | L11: 1597604 | M11: 1848886 | N11: 1669155 | O11: 1543277
A12: =VLOOKUP(B12,'[1]PORTFOLIO RAW'!B:B,1,FALSE) -> 322677 | B12: 322677 | C12: ALLSTATE CORP - EBIT & DEPRECIATION | D12: 322677(WC18198) | E12: 6917000 | F12: -2496000 | G12: 1879000 | H12: 1692000 | I12: 1491000 | J12: 3719000 | K12: 4131000 | L12: 4924000 | M12: 3945000 | N12: 3431000 | O12: 4809000
A13: =VLOOKUP(B13,'[1]PORTFOLIO RAW'!B:B,1,FALSE) -> 906191 | B13: 906191 | C13: HONEYWELL INTERNATNL - EBIT & DEPRECIATION | D13: 906191(WC18198) | E13: 4604000 | F13: 5097000 | G13: 4368000 | H13: 4211000 | I13: 3676000 | J13: 5119000 | K13: 6711000 | L13: 7045000 | M13: 7779000 | N13: 7806000 | O13: 8294000
A14: =VLOOKUP(B14,'[1]PORTFOLIO RAW'!B:B,1,FALSE) -> 938692 | B14: 938692 | C14: AMGEN INC - EBIT & DEPRECIATION | D14: 938692(WC18198) | E14: 5437000 | F14: 6567000 | G14: 6830000 | H14: 6937000 | I14: 5819000 | J14: 7150000 | K14: 8595000 | L14: 9809000 | M14: 11184000 | N14: 12542000 | O14: 12856000
A15: =VLOOKUP(B15,'[1]PORTFOLIO RAW'!B:B,1,FALSE) -> 905802 | B15: 905802 | C15: HESS CORPORATION - EBIT & DEPRECIATION | D15: 905802(WC18198) | E15: 5360000 | F15: 6952000 | G15: 4313000 | H15: 6511000 | I15: 6323000 | J15: 7106000 | K15: 7669000 | L15: 5983000 | M15: 38000 | N15: -272000 | O15: -2570000
... A29: =VLOOKUP(B29,'[1]PORTFOLIO RAW'!B:B,1,FALSE) -> 670942 | B29: 670942 | C29: AMEREN CORPORATION - EBIT & DEPRECIATION | D29: 670942(WC18198) | E29: 2176000 | F29: 2125000 | G29: 2229000 | H29: 1758000 | I29: 2061000 | J29: -424000 | K29: 1933000 | L29: 2056000 | M29: 2099000 | N29: 2268000 | O29: 2392000
A30: =VLOOKUP(B30,'[1]PORTFOLIO RAW'!B:B,1,FALSE) -> 702259 | B30: 702259 | C30: AUTODESK INC - EBIT & DEPRECIATION | D30: 702259(WC18198) | E30: 534700 | F30: 344300 | G30: 196200 | H30: 377400 | I30: 478400 | J30: NA | K30: 418600 | L30: 242100 | M30: 159400 | N30: -337400 | O30: -395100
A31: =VLOOKUP(B31,'[1]PORTFOLIO RAW'!B:B,1,FALSE) -> 912669 | B31: 912669 | C31: AUTOMATIC DATA PROC - EBIT & DEPRECIATION | D31: 912669(WC18198) | E31: 2007200 | F31: 2211600 | G31: 2246100 | H31: 2181000 | I31: 2259500 | J31: 2453100 | K31: 2410400 | L31: 2616900 | M31: 2355100 | N31: 2579500 | O31: 2927200
A32: =VLOOKUP(B32,'[1]PORTFOLIO RAW'!B:B,1,FALSE) -> 544616 | B32: 544616 | C32: AUTOZONE INC - EBIT & DEPRECIATION | D32: 544616(WC18198) | E32: 1217496 | F32: 1297428 | G32: 1360382 | H32: 1514124 | I32: 1693070 | J32: 1842119 | K32: 2001955 | L32: 2083340 | M32: 2224575 | N32: 2360163 | O32: 2406622
A33: =VLOOKUP(B33,'[1]PORTFOLIO RAW'!B:B,1,FALSE) -> 921161 | B33: 921161 | C33: AVERY DENNISON CORP - EBIT & DEPRECIATION | D33: 921161(WC18198) | E33: 715100 | F33: 664900 | G33: -445200 | H33: 670700 | I33: 546200 | J33: 548900 | K33: 626800 | L33: 629400 | M33: 657800 | N33: 713500 | O33: 826300
A34: =VLOOKUP(B34,'[1]PORTFOLIO RAW'!B:B,1,FALSE) -> 932060 | B34: 932060 | C34: BALL CORPORATION - EBIT & DEPRECIATION | D34: 932060(WC18198) | E34: 794900 | F34: 887900 | G34: 931700 | H34: 1016400 | I34: 1138000 | J34: 1073400 | K34: 1067300 | L34: 1086400 | M34: 774200 | N34: 807000 | O34: 1528000
A35: =VLOOKUP(B35,'[1]PORTFOLIO RAW'!B:B,1,FALSE) -> 874227 | B35: 874227 | C35: BERKSHIRE HATHAWAY - EBIT & DEPRECIATION | D35: 874227(WC18198) | E35: 24478000 | F35: 12347000 | G35: 16671000 | H35: 25888000 | I35: 22661000 | J35: 30126000 | K35: 38105000 | L35: 38728000 | M35: 46240000 | N35: 45142000 | O35: 35482000
A36: =VLOOKUP(B36,'[1]PORTFOLIO RAW'!B:B,1,FALSE) -> 916365 | B36: 916365 | C36: BAXTER INTERNATIONAL - EBIT & DEPRECIATION | D36: 916365(WC18198) | E36: 2846000 | F36: 3255000 | G36: 3418000 | H36: 2779000 | I36: 3637000 | J36: 3698000 | K36: 3503000 | L36: 3611000 | M36: 1333000 | N36: 5843000 | O36: 2063000
A37: =VLOOKUP(B37,'[1]PORTFOLIO RAW'!B:B,1,FALSE) -> 905876 | B37: 905876 | C37: BECTON, DICKINSON - EBIT & DEPRECIATION | D37: 905876(WC18198) | E37: 1691706 | F37: 2067372 | G37: 2143456 | H37: 2207692 | I37: 2299698 | J37: 2105920 | K37: 1850000 | L37: 2219000 | M37: 2001000 | N37: 2576000 | O37: 2588000
A38: =VLOOKUP(B38,'[1]PORTFOLIO RAW'!B:B,1,FALSE) -> 945384 | B38: 945384 | C38: VERIZON COMMUNICATNS - EBIT & DEPRECIATION | D38: 945384(WC18198) | E38: 30166000 | F38: 31731000 | G38: 30649000 | H38: 31002000 | I38: 29362000 | J38: 28604000 | K38: 48408000 | L38: 34938000 | M38: 49263000 | N38: 41388000 | O38: 42134000
A39: =VLOOKUP(B39,'[1]PORTFOLIO RAW'!B:B,1,FALSE) -> 929302 | B39: 929302 | C39: BEST BUY CO INC - EBIT & DEPRECIATION | D39: 929302(WC18198) | E39: 2670000 | F39: 2870000 | G39: 2587000 | H39: 3215000 | I39: 3143000 | J39: 940820 | K39: 1903000 | L39: 2133000 | M39: 2047000 | N39: 2542000 | O39: 2575000
A40: =VLOOKUP(B40,'[1]PORTFOLIO RAW'!B:B,1,FALSE) -> 895784 | B40: 895784 | C40: SL GREEN REALTY CORP - EBIT & DEPRECIATION | D40: 895784(WC18198) | E40: 598725 | F40: 547709 | G40: 500310 | H40: 724810 | I40: 1218024 | J40: 783663 | K40: 816231 | L40: 933469 | M40: 1216001 | N40: 1417949 | O40: 758011
A41: =VLOOKUP(B41,'[1]PORTFOLIO RAW'!B:B,1,FALSE) -> 878574 | B41: 878574 | C41: YUM! BRANDS INC - EBIT & DEPRECIATION | D41: 878574(WC18198) | E41: 1881000 | F41: 2119000 | G41: 2084000 | H41: 2369000 | I41: 2448000 | J41: 2932000 | K41: 2516000 | L41: 2288000 | M41: 2648000 | N41: 1960000 | O41: 3000000
A42: =VLOOKUP(B42,'[1]PORTFOLIO RAW'!B:B,1,FALSE) -> 905159 | B42: 905159 | C42: FIRSTENERGY CORP - EBIT & DEPRECIATION | D42: 905159(WC18198) | E42: 3573000 | F42: 3498000 | G42: 2819000 | H42: 2657000 | I42: 3502000 | J42: 3377000 | K42: 2813000 | L42: 2426000 | M42: 3884000 | N42: -6751000 | O42: 1423000
... A44: =VLOOKUP(B44,'[1]PORTFOLIO RAW'!B:B,1,FALSE) -> 904818 | B44: 904818 | C44: BOEING CO - EBIT & DEPRECIATION | D44: 904818(WC18198) | E44: 7908000 | F44: 5670000 | G44: 3662000 | H44: 6643000 | I44: 7401000 | J44: 8004000 | K44: 8462000 | L44: 9376000 | M44: 9263000 | N44: 7784000 | O44: 12476000
A45: =VLOOKUP(B45,'[1]PORTFOLIO RAW'!B:B,1,FALSE) -> 923649 | B45: 923649 | C45: ROBERT HALF INTL INC - EBIT & DEPRECIATION | D45: 923649(WC18198) | E45: 565945 | F45: 497786 | G45: 132529 | H45: 171726 | I45: 301631 | J45: 392969 | K45: NA | L45: NA | M45: NA | N45: NA | O45: NA
A46: =VLOOKUP(B46,'[1]PORTFOLIO RAW'!B:B,1,FALSE) -> 325824 | B46: 325824 | C46: BOSTON SCIENTIFIC - EBIT & DEPRECIATION | D46: 325824(WC18198) | E46: 940000 | F46: -699000 | G46: -61000 | H46: 146000 | I46: 1641000 | J46: -3161000 | K46: 790000 | L46: 432000 | M46: 403000 | N46: 1225000 | O46: 2006000
A47: =VLOOKUP(B47,'[1]PORTFOLIO RAW'!B:B,1,FALSE) -> 879628 | B47: 879628 | C47: C.H. ROBINSON - EBIT & DEPRECIATION | D47: 879628(WC18198) | E47: 550880 | F47: 609551 | G47: 617575 | H47: 653471 | I47: 727202 | J47: NA | K47: 741343 | L47: 805427 | M47: 931919 | N47: 912200 | O47: 868096
A48: =VLOOKUP(B48,'[1]PORTFOLIO RAW'!B:B,1,FALSE) -> 905080 | B48: 905080 | C48: BRISTOL-MYERS SQUIBB - EBIT & DEPRECIATION | D48: 905080(WC18198) | E48: 4324000 | F48: 5980000 | G48: 6086000 | H48: 6808000 | I48: 7646000 | J48: 3328000 | K48: 4235000 | L48: 3306000 | M48: 2861000 | N48: 6675000 | O48: 6109000
A49: =VLOOKUP(B49,'[1]PORTFOLIO RAW'!B:B,1,FALSE) -> 130502 | B49: 130502 | C49: AVALONBAY COMMUNITIE - EBIT & DEPRECIATION | D49: 130502(WC18198) | E49: 467178 | F49: 418099 | G49: 435041 | H49: 505086 | I49: 575663 | J49: 636788 | K49: 801598 | L49: 1143050 | M49: 1327114 | N49: 1687995 | O49: 1589868
A50: =VLOOKUP(B50,'[1]PORTFOLIO RAW'!B:B,1,FALSE) -> 902103 | B50: 902103 | C50: SEMPRA ENERGY - EBIT & DEPRECIATION | D50: 902103(WC18198) | E50: 2517000 | F50: 2018000 | G50: 2618000 | H50: 2381000 | I50: 3155000 | J50: 2845000 | K50: 3063000 | L50: 3161000 | M50: 3421000 | N50: 3072000 | O50: 3699000
A51: =VLOOKUP(B51,'[1]PORTFOLIO RAW'!B:B,1,FALSE) -> 951849 | B51: 951849 | C51: FEDEX CORP - EBIT & DEPRECIATION | D51: 951849(WC18198) | E51: 5093000 | F51: 4060000 | G51: 2737000 | H51: 3931000 | I51: 4324000 | J51: 5306000 | K51: 4923000 | L51: 6072000 | M51: 4473000 | N51: 5707000 | O51: 8086000
A52: =VLOOKUP(B52,'[1]PORTFOLIO RAW'!B:B,1,FALSE) -> 674693 | B52: 674693 | C52: VERISIGN, INC. - EBIT & DEPRECIATION | D52: 674693(WC18198) | E52: 121127 | F52: 292344 | G52: 414907 | H52: 320676 | I52: 396625 | J52: 517710 | K52: 609988 | L52: 632995 | M52: 670902 | N52: 754904 | O52: 786119
A53: =VLOOKUP(B53,'[1]PORTFOLIO RAW'!B:B,1,FALSE) -> 546075 | B53: 546075 | C53: AMPHENOL CORP - EBIT & DEPRECIATION | D53: 546075(WC18198) | E53: 630726 | F53: 723509 | G53: 581637 | H53: 807275 | I53: 879220 | J53: 960233 | K53: 1046680 | L53: 1221000 | M53: 1292700 | N53: 1430700 | O53: 1671500
A54: =VLOOKUP(B54,'[1]PORTFOLIO RAW'!B:B,1,FALSE) -> 912216 | B54: 912216 | C54: BROWN FORMAN CORP - EBIT & DEPRECIATION | D54: 912216(WC18198) | E54: 664000 | F54: 745000 | G54: 722000 | H54: 772000 | I54: 917000 | J54: 843000 | K54: 952000 | L54: 1023000 | M54: 1080000 | N54: 1591000 | O54: 1050000
...

Sheet EQIT
A1: EQUITY
B2: Code | C2: Name | D2: Code | E2: 2007 | F2: 2008 | G2: 2009 | H2: 2010 | I2: 2011 | J2: 2012 | K2: 2013 | L2: 2014 | M2: 2015 | N2: 2016 | O2: 2017
A3: =VLOOKUP(B3,'[1]PORTFOLIO RAW'!B:B,1,FALSE) -> 891399 | B3: 891399 | C3: AMAZON.COM INC - COMMON SHAREHOLDERS' EQUITY | D3: 891399(WC03501) | E3: 1197000 | F3: 2672000 | G3: 5257000 | H3: 6864000 | I3: 7757000 | J3: 8192000 | K3: 9746000 | L3: 10741000 | M3: 13384000 | N3: 19285000 | O3: 27709000
A4: =VLOOKUP(B4,'[1]PORTFOLIO RAW'!B:B,1,FALSE) -> 916328 | B4: 916328 | C4: ABBOTT LABORATORIES - COMMON SHAREHOLDERS' EQUITY | D4: 916328(WC03501) | E4: 17778540 | F4: 17479551 | G4: 22855627 | H4: 22388135 | I4: 24439833 | J4: 26720961 | K4: 25171000 | L4: 21526000 | M4: 21211000 | N4: 20538000 | O4: 30897000
A5: =VLOOKUP(B5,'[1]PORTFOLIO RAW'!B:B,1,FALSE) -> 545101 | B5: 545101 | C5: AES CORP - COMMON SHAREHOLDERS' EQUITY | D5: 545101(WC03501) | E5: 3164000 | F5: 3669000 | G5: 4675000 | H5: 6473000 | I5: 5946000 | J5: 4569000 | K5: 4330000 | L5: 4272000 | M5: 3149000 | N5: 2794000 | O5: 2465000
A6: =VLOOKUP(B6,'[1]PORTFOLIO RAW'!B:B,1,FALSE) -> 906187 | B6: 906187 | C6: INT'L BUSINESS MACHS - COMMON SHAREHOLDERS' EQUITY | D6: 906187(WC03501) | E6: 28469000 | F6: 13465000 | G6: 22637000 | H6: 23046000 | I6: 20139000 | J6: 18860000 | K6: 22792000 | L6: 11869000 | M6: 14262000 | N6: 18246000 | O6: 17594000
A7: =VLOOKUP(B7,'[1]PORTFOLIO RAW'!B:B,1,FALSE) -> 936365 | B7: 936365 | C7: ADVANCED MICRO - COMMON SHAREHOLDERS' EQUITY | D7: 936365(WC03501) | E7: 2990000 | F7: -82000 | G7: 648000 | H7: 1013000 | I7: 1590000 | J7: 538000 | K7: 544000 | L7: 187000 | M7: -412000 | N7: 416000 | O7: 611000
A8: =VLOOKUP(B8,'[1]PORTFOLIO RAW'!B:B,1,FALSE) -> 749382 | B8: 749382 | C8: ADOBE INC - COMMON SHAREHOLDERS' EQUITY | D8: 749382(WC03501) | E8: 4649982 | F8: 4410354 | G8: 4890568 | H8: 5192387 | I8: 5783113 | J8: 6665182 | K8: 6724634 | L8: 6775905 | M8: 7001580 | N8: 7424835 | O8: 8459869
A9: =VLOOKUP(B9,'[1]PORTFOLIO RAW'!B:B,1,FALSE) -> 905271 | B9: 905271 | C9: AIR PRODUCTS & CHEMS - COMMON SHAREHOLDERS' EQUITY | D9: 905271(WC03501) | E9: 5495600 | F9: 5030700 | G9: 4791900 | H9: 5546900 | I9: 5795800 | J9: 6477200 | K9: 7042100 | L9: 7365800 | M9: 7249000 | N9: 7079600 | O9: 10086200
A10: =VLOOKUP(B10,'[1]PORTFOLIO RAW'!B:B,1,FALSE) -> 894371 | B10: 894371 | C10: BOSTON PROPERTIES - COMMON SHAREHOLDERS' EQUITY | D10: 894371(WC03501) | E10: 3668825 | F10: 3531267 | G10: 4446002 | H10: 4372643 | I10: 4865998 | J10: 5097065 | K10: 5541153 | L10: 5697298 | M10: 5709435 | N10: 5586295 | O10: 5613957
A11: =VLOOKUP(B11,'[1]PORTFOLIO RAW'!B:B,1,FALSE) -> 322677 | B11: 322677 | C11: ALLSTATE CORP - COMMON SHAREHOLDERS' EQUITY | D11: 322677(WC03501) | E11: 20963000 | F11: 16379000 | G11: 17562000 | H11: 18081000 | I11: 17311000 | J11: 17746000 | K11: 19054000 | L11: 18632000 | M11: 17600000 | N11: 17715000 | O11: 19084000
A12: =VLOOKUP(B12,'[1]PORTFOLIO RAW'!B:B,1,FALSE) -> 906191 | B12: 906191 | C12: HONEYWELL INTERNATNL - COMMON SHAREHOLDERS' EQUITY | D12: 906191(WC03501) | E12: 9222000 | F12: 7187000 | G12: 8844000 | H12: 10666000 | I12: 10806000 | J12: 12975000 | K12: 17467000 | L12: 17657000 | M12: 18283000 | N12: 19369000 | O12: 17276000
A13: =VLOOKUP(B13,'[1]PORTFOLIO RAW'!B:B,1,FALSE) -> 938692 | B13: 938692 | C13: AMGEN INC - COMMON SHAREHOLDERS' EQUITY | D13: 938692(WC03501) | E13: 17869000 | F13: 20386000 | G13: 22667000 | H13: 23944000 | I13: 19029000 | J13: 19060000 | K13: 22096000 | L13: 25778000 | M13: 28083000 | N13: 29875000 | O13: 25241000
A14: =VLOOKUP(B14,'[1]PORTFOLIO RAW'!B:B,1,FALSE) -> 905802 | B14: 905802 | C14: HESS CORPORATION - COMMON SHAREHOLDERS' EQUITY | D14: 905802(WC03501) | E14: 9760000 | F14: 12307000 | G14: 13384000 | H14: 16689000 | I14: 18516000 | J14: 21090000 | K14: 24720000 | L14: 22205000 | M14: 19386000 | N14: 14533000 | O14: 11050000
... A108: =VLOOKUP(B108,'[1]PORTFOLIO RAW'!B:B,1,FALSE) -> 905016 | B108: 905016 | C108: NEXTERA ENERGY - COMMON SHAREHOLDERS' EQUITY | D108: 905016(WC03501) | E108: 10735000 | F108: 11681000 | G108: 12967000 | H108: 14461000 | I108: 14943000 | J108: 16068000 | K108: 18040000 | L108: 19916000 | M108: 22574000 | N108: 24341000 | O108: 28208000
A109: =VLOOKUP(B109,'[1]PORTFOLIO RAW'!B:B,1,FALSE) -> 28341F | B109: 28341F | C109: ASSURANT INC - COMMON SHAREHOLDERS' EQUITY | D109: 28341F(WC03501) | E109: 4065519 | F109: 4187905 | G109: 4658699 | H109: 4367282 | I109: 4313163 | J109: 5185366 | K109: 4280981 | L109: 4361631 | M109: 4006090 | N109: 3618201 | O109: 3671500
A110: =VLOOKUP(B110,'[1]PORTFOLIO RAW'!B:B,1,FALSE) -> 755980 | B110: 755980 | C110: FASTENAL COMPANY - COMMON SHAREHOLDERS' EQUITY | D110: 755980(WC03501) | E110: 1010161 | F110: 1142259 | G110: 1190843 | H110: 1282512 | I110: 1458976 | J110: 1560360 | K110: 1772697 | L110: 1915217 | M110: 1801289 | N110: 1933094 | O110: 2096900
A111: =VLOOKUP(B111,'[1]PORTFOLIO RAW'!B:B,1,FALSE) -> 905994 | B111: 905994 | C111: FEDERAL REALTY INVST - COMMON SHAREHOLDERS' EQUITY | D111: 905994(WC03501) | E111: 1105438 | F111: 1104605 | G111: 1167340 | H111: 1139836 | I111: 1206095 | J111: 1276815 | K111: 1438163 | L111: 1594404 | M111: 1653752 | N111: 1966736 | O111: 2106709
A112: =VLOOKUP(B112,'[1]PORTFOLIO RAW'!B:B,1,FALSE) -> 997198 | B112: 997198 | C112: FIFTH THIRD BANCORP - COMMON SHAREHOLDERS' EQUITY | D112: 997198(WC03501) | E112: 9152000 | F112: 7836000 | G112: 9678000 | H112: 10232000 | I112: 12790000 | J112: 13305000 | K112: 13555000 | L112: 14295000 | M112: 14508000 | N112: 14874000 | O112: 15034000
A113: =VLOOKUP(B113,'[1]PORTFOLIO RAW'!B:B,1,FALSE) -> 951503 | B113: 951503 | C113: M&T BANK CORPORATION - COMMON SHAREHOLDERS' EQUITY | D113: 951503(WC03501) | E113: 6485256 | F113: 6184731 | G113: 6974907 | H113: 7579695 | I113: 8406624 | J113: 9321093 | K113: 10424032 | L113: 11104396 | M113: 14941789 | N113: 15255122 | O113: 15019319
A114: =VLOOKUP(B114,'[1]PORTFOLIO RAW'!B:B,1,FALSE) -> 741123 | B114: 741123 | C114: FISERV INC - COMMON SHAREHOLDERS' EQUITY | D114: 741123(WC03501) | E114: 2467000 | F114: 2594000 | G114: 3026000 | H114: 3229000 | I114: 3258000 | J114: 3417000 | K114: 3585000 | L114: 3295000 | M114: 2660000 | N114: 2541000 | O114: 2731000
A115: =VLOOKUP(B115,'[1]PORTFOLIO RAW'!B:B,1,FALSE) -> 546814 | B115: 546814 | C115: MACY'S INC - COMMON SHAREHOLDERS' EQUITY | D115: 546814(WC03501) | E115: 9907000 | F115: 4646000 | G115: 4701000 | H115: 5530000 | I115: 5933000 | J115: 6051000 | K115: 6249000 | L115: 5378000 | M115: 4250000 | N115: 4323000 | O115: 5673000
A116: =VLOOKUP(B116,'[1]PORTFOLIO RAW'!B:B,1,FALSE) -> 938076 | B116: 938076 | C116: FRANKLIN RESOURCES - COMMON SHAREHOLDERS' EQUITY | D116: 938076(WC03501) | E116: 7332275 | F116: 7074364 | G116: 7632173 | H116: 7726994 | I116: 8524731 | J116: 9201300 | K116: 10073100 | L116: 11584100 | M116: 11841000 | N116: 11935800 | O116: 12620000
A117: =VLOOKUP(B117,'[1]PORTFOLIO RAW'!B:B,1,FALSE) -> 152594 | B117: 152594 | C117: FREEPORT-MCMORAN INC - COMMON SHAREHOLDERS' EQUITY | D117: 152594(WC03501) | E117: 14259000 | F117: 2066000 | G117: 6244000 | H117: 12504000 | I117: 15642000 | J117: 17543000 | K117: 20934000 | L117: 18287000 | M117: 7828000 | N117: 6051000 | O117: 7977000
A118: =VLOOKUP(B118,'[1]PORTFOLIO RAW'!B:B,1,FALSE) -> 951018 | B118: 951018 | C118: GAP INC - COMMON SHAREHOLDERS' EQUITY | D118: 951018(WC03501) | E118: 4274000 | F118: 4387000 | G118: 4891000 | H118: 4080000 | I118: 2755000 | J118: 2894000 | K118: 3062000 | L118: 2983000 | M118: 2545000 | N118: 2904000 | O118: 3144000
A119: =VLOOKUP(B119,'[1]PORTFOLIO RAW'!B:B,1,FALSE) -> 907652 | B119: 907652 | C119: GENERAL DYNAMICS - COMMON SHAREHOLDERS' EQUITY | D119: 907652(WC03501) | E119: 11768000 | F119: 10053000 | G119: 12423000 | H119: 13316000 | I119: 13232000 | J119: 11390000 | K119: 14501000 | L119: 11829000 | M119: 10738000 | N119: 10976000 | O119: 11435000
A120: =VLOOKUP(B120,'[1]PORTFOLIO RAW'!B:B,1,FALSE) -> 905801 | B120: 905801 | C120: GENERAL MILLS, INC. - COMMON SHAREHOLDERS' EQUITY | D120: 905801(WC03501) | E120: 5319000 | F120: 6215800 | G120: 5174700 | H120: 5402900 | I120: 6365500 | J120: 6421700 | K120: 6672200 | L120: 6534800 | M120: 4996700 | N120: 4930200 | O120: 4327900
A121: =VLOOKUP(B121,'[1]PORTFOLIO RAW'!B:B,1,FALSE) -> 906511 | B121: 906511 | C121: GENUINE PARTS CO - COMMON SHAREHOLDERS' EQUITY | D121: 906511(WC03501) | E121: 2716716 | F121: 2324332 | G121: 2621330 | H121: 2793819 | I121: 2783235 | J121: 2997887 | K121: 3349074 | L121: 3301248 | M121: 3146567 | N121: 3193728 | O121: 3412152
... A235: =VLOOKUP(B235,'[1]PORTFOLIO RAW'!B:B,1,FALSE) -> 933974 | B235: 933974 | C235: TRAVELERS COS - COMMON SHAREHOLDERS' EQUITY | D235: 933974(WC03501) | E235: 25885000 | F235: 25374000 | G235: 25475000 | H235: 23549000 | I235: 21606000 | J235: 22302000 | K235: 23474000 | L235: 22870000 | M235: 22309000 | N235: 22491000 | O235: 22777000
A236: =VLOOKUP(B236,'[1]PORTFOLIO RAW'!B:B,1,FALSE) -> 14015T | B236: 14015T | C236: FIDELITY NATNL INF - COMMON SHAREHOLDERS' EQUITY | D236: 14015T(WC03501) | E236: 3781179 | F236: 3532800 | G236: 8308900 | H236: 6403200 | I236: 6503000 | J236: 6640900 | K236: 6580500 | L236: 6556700 | M236: 9321000 | N236: 9741000 | O236: 10835000
A237: =VLOOKUP(B237,'[1]PORTFOLIO RAW'!B:B,1,FALSE) -> 905019 | B237: 905019 | C237: MERCK & CO INC - COMMON SHAREHOLDERS' EQUITY | D237: 905019(WC03501) | E237: 18184700 | F237: 18758300 | G237: 59058000 | H237: 54376000 | I237: 54517000 | J237: 53020000 | K237: 49765000 | L237: 48647000 | M237: 44676000 | N237: 40088000 | O237: 34336000
A238: =VLOOKUP(B238,'[1]PORTFOLIO RAW'!B:B,1,FALSE) -> 912090 | B238: 912090 | C238: SCHLUMBERGER LIMITED - COMMON SHAREHOLDERS' EQUITY | D238: 912090(WC03501) | E238: 14876000 | F238: 16863000 | G238: 19120000 | H238: 31226000 | I238: 31263000 | J238: 34751000 | K238: 39469000 | L238: 37850000 | M238: 35633000 | N238: 41078000 | O238: 36842000
A239: =VLOOKUP(B239,'[1]PORTFOLIO RAW'!B:B,1,FALSE) -> 755741 | B239: 755741 | C239: CHARLES SCHWAB CORP - COMMON SHAREHOLDERS' EQUITY | D239: 755741(WC03501) | E239: 3732000 | F239: 4061000 | G239: 5073000 | H239: 6226000 | I239: 7714000 | J239: 8704000 | K239: 9496000 | L239: 10918000 | M239: 11917000 | N239: 13586000 | O239: 15675000
A240: =VLOOKUP(B240,'[1]PORTFOLIO RAW'!B:B,1,FALSE) -> 14361V | B240: 14361V | C240: ZIMMER BIOMET - COMMON SHAREHOLDERS' EQUITY | D240: 14361V(WC03501) | E240: 5449600 | F240: 5650300 | G240: 5638700 | H240: 5771300 | I240: 5507200 | J240: 5860900 | K240: 6297300 | L240: 6520800 | M240: 9887900 | N240: 9668900 | O240: 11735800
A241: =VLOOKUP(B241,'[1]PORTFOLIO RAW'!B:B,1,FALSE) -> 154680 | B241: 154680 | C241: AMERISOURCEBERGEN - COMMON SHAREHOLDERS' EQUITY | D241: 154680(WC03501) | E241: 3099720 | F241: 2710045 | G241: 2716469 | H241: 2954297 | I241: 2866858 | J241: 2456712 | K241: 2319745 | L241: 1956899 | M241: 633520 | N241: 2129404 | O241: 2064461
A242: =VLOOKUP(B242,'[1]PORTFOLIO RAW'!B:B,1,FALSE) -> 14698C | B242: 14698C | C242: PRINCIPAL FINL GROUP - COMMON SHAREHOLDERS' EQUITY | D242: 14698C(WC03501) | E242: 6854600 | F242: 6393600 | G242: 8284000 | H242: 9045100 | I242: 8709200 | J242: 8267500 | K242: 9434200 | L242: 10183900 | M242: 9311600 | N242: 10227300 | O242: 11335900
A243: =VLOOKUP(B243,'[1]PORTFOLIO RAW'!B:B,1,FALSE) -> 905361 | B243: 905361 | C243: SHERWIN-WILLIAMS CO - COMMON SHAREHOLDERS' EQUITY | D243: 905361(WC03501) | E243: 1785727 | F243: 1605648 | G243: 1490950 | H243: 1609440 | I243: 1516919 | J243: 1690718 | K243: 1734129 | L243: 996470 | M243: 867910 | N243: 1878441 | O243: 3692188
A244: =VLOOKUP(B244,'[1]PORTFOLIO RAW'!B:B,1,FALSE) -> 357834 | B244: 357834 | C244: SIMON PROPERTY GROUP - COMMON SHAREHOLDERS' EQUITY | D244: 357834(WC03501) | E244: 2833974 | F244: 2614638 | G244: 4412433 | H244: 4785405 | I244: 4604619 | J244: 5865884 | K244: 5805016 | L244: 5049115 | M244: 4427731 | N244: 4267043 | O244: 3643091
A245: =VLOOKUP(B245,'[1]PORTFOLIO RAW'!B:B,1,FALSE) -> 906400 | B245: 906400 | C245: SNAP-ON INC - COMMON SHAREHOLDERS' EQUITY | D245: 906400(WC03501) | E245: 1280100 | F245: 1186500 | G245: 1290000 | H245: 1388500 | I245: 1530900 | J245: 1802100 | K245: 2113200 | L245: 2207800 | M245: 2412700 | N245: 2617200 | O245: 2953900
A246: =VLOOKUP(B246,'[1]PORTFOLIO RAW'!B:B,1,FALSE) -> 14861V | B246: 14861V | C246: PRUDENTIAL FINANCIAL - COMMON SHAREHOLDERS' EQUITY | D246: 14861V(WC03501) | E246: 23057000 | F246: 20157000 | G246: 24684000 | H246: 29270000 | I246: 31588000 | J246: 27173000 | K246: 24934000 | L246: 22519000 | M246: 26117000 | N246: 27692000 | O246: 34101000
...

Sheet DEBT
A1: DEBT
B2: Code | C2: Name | D2: Code | E2: 2007 | F2: 2008 | G2: 2009 | H2: 2010 | I2: 2011 | J2: 2012 | K2: 2013 | L2: 2014 | M2: 2015 | N2: 2016 | O2: 2017
A3: =VLOOKUP(B3,'[1]PORTFOLIO RAW'!B:B,1,FALSE) -> 891399 | B3: 891399 | C3: AMAZON.COM INC - TOTAL DEBT | D3: 891399(WC03255) | E3: 1361000 | F3: 592000 | G3: 393000 | H3: 865000 | I3: 1939000 | J3: 4964000 | K3: 6917000 | L3: 16089000 | M3: 17547000 | N3: 20410000 | O3: 44147000
