Workbook

Sheet PORTFOLIO RAW
A2: NAME | B2: Code | C2: Industry
A3: MMM | B3: 902172 | C3: Industrials
A4: ABT | B4: 916328 | C4: Healthcare
A5: ACN | B5: 14352P | C5: Technology
A6: ATVI.O | B6: 312367 | C6: Technology
A7: ADBE.O | B7: 749382 | C7: Technology
A8: AAP | B8: 14806F | C8: Consumer Cyclicals
A9: AMD.O | B9: 936365 | C9: Technology
A10: AES | B10: 545101 | C10: Utilities
A11: AFL | B11: 933185 | C11: Financials
A12: A | B12: 277642 | C12: Healthcare
A13: APD | B13: 905271 | C13: Basic Materials
A14: AKAM.O | B14: 277355 | C14: Technology
A15: ALB | B15: 130298 | C15: Basic Materials
A16: AGN | B16: 325596 | C16: Healthcare
A17: LNT.O | B17: 906979 | C17: Utilities
A18: ALL | B18: 322677 | C18: Financials
A19: GOOG.O | B19: 29026M | C19: Technology
A20: MO | B20: 904853 | C20: Consumer Non-Cyclicals
A21: AMZN.O | B21: 891399 | C21: Consumer Cyclicals
A22: AEE | B22: 670942 | C22: Utilities
A23: AEP | B23: 905425 | C23: Utilities
A24: AXP | B24: 906156 | C24: Financials
A25: AIG | B25: 916305 | C25: Financials
A26: AMT | B26: 680902 | C26: Financials
A27: AMP | B27: 31604H | C27: Financials
A28: ABC | B28: 154680 | C28: Consumer Non-Cyclicals
A29: AMGN.O | B29: 938692 | C29: Healthcare
A30: APH | B30: 546075 | C30: Technology
A31: ADI.O | B31: 905276 | C31: Technology
A32: ANTM.K | B32: 14737P | C32: Healthcare
A33: AON | B33: 922817 | C33: Financials
A34: APA | B34: 921983 | C34: Energy
A35: AIV | B35: 132808 | C35: Financials
A36: AAPL.O | B36: 992816 | C36: Technology
A37: AMAT.O | B37: 905296 | C37: Technology
A38: ADM | B38: 921093 | C38: Consumer Non-Cyclicals
A39: ARNC.K | B39: 905113 | C39: Basic Materials
A40: AIZ | B40: 28341F | C40: Financials
A41: T | B41: 945388 | C41: Telecommunications Services
...

Sheet MB
A1: Market to Book Ratio
A2: Code | B2: Code | C2: Name | D2: Code | E2: 2007 | F2: 2008 | G2: 2009 | H2: 2010 | I2: 2011 | J2: 2012 | K2: 2013 | L2: 2014 | M2: 2015 | N2: 2016 | O2: 2017
A3: =VLOOKUP(B3,'PORTFOLIO RAW'!B:B,1,FALSE) -> 891399 | B3: 891399 | C3: AMAZON.COM - MRKT VALUE TO BOOK | D3: 891399(MTBV) | E3: 30.96 | F3: 12.91 | G3: 7.42 | H3: 9.87 | I3: 13.65 | J3: 14.39 | K3: 14.83 | L3: 14.25 | M3: 18.88 | N3: 19.18 | O3: 16.87
A4: =VLOOKUP(B4,'PORTFOLIO RAW'!B:B,1,FALSE) -> 916328 | B4: 916328 | C4: ABBOTT LABORATORIES - MRKT VALUE TO BOOK | D4: 916328(MTBV) | E4: 4.67 | F4: 5.18 | G4: 3.11 | H4: 3.6 | I4: 3.36 | J4: 4.1 | K4: 2.18 | L4: 3.04 | M4: 3.04 | N4: 2.98 | O4: 2.92
A5: =VLOOKUP(B5,'PORTFOLIO RAW'!B:B,1,FALSE) -> 545101 | B5: 545101 | C5: AES - MRKT VALUE TO BOOK | D5: 545101(MTBV) | E5: 4.08 | F5: 2.42 | G5: 2.05 | H5: 1.4 | I5: 1.41 | J5: 1.83 | K5: 2.29 | L5: 2.49 | M5: 2.37 | N5: 3.01 | O5: 3.02
A6: =VLOOKUP(B6,'PORTFOLIO RAW'!B:B,1,FALSE) -> 906187 | B6: 906187 | C6: INTERNATIONAL BUS.MCHS. - MRKT VALUE TO BOOK | D6: 906187(MTBV) | E6: 5.58 | F6: 11.96 | G6: 7.07 | H6: 7.21 | I6: 10.36 | J6: 12.49 | K6: 9.13 | L6: 16.31 | M6: 9.93 | N6: 8.09 | O6: 7.73
A7: =VLOOKUP(B7,'PORTFOLIO RAW'!B:B,1,FALSE) -> 936365 | B7: 936365 | C7: ADVANCED MICRO DEVICES - MRKT VALUE TO BOOK | D7: 936365(MTBV) | E7: 2.47 | F7: -40.13 | G7: 5.87 | H7: 4.06 | I7: 2.93 | J7: 4.72 | K7: 5.07 | L7: 15.65 | M7: -3.54 | N7: 13.27 | O7: 21.29
A8: =VLOOKUP(B8,'PORTFOLIO RAW'!B:B,1,FALSE) -> 749382 | B8: 749382 | C8: ADOBE (NAS) - MRKT VALUE TO BOOK | D8: 749382(MTBV) | E8: 5.42 | F8: 4.92 | G8: 3.54 | H8: 3.35 | I8: 2.1 | J8: 2.55 | K8: 3.91 | L8: 4.93 | M8: 5.79 | N8: 6.75 | O8: 8.75
A9: =VLOOKUP(B9,'PORTFOLIO RAW'!B:B,1,FALSE) -> 905271 | B9: 905271 | C9: AIR PRDS.& CHEMS. - MRKT VALUE TO BOOK | D9: 905271(MTBV) | E9: 3.65 | F9: 3.51 | G9: 3.52 | H9: 3.18 | I9: 3.02 | J9: 2.78 | K9: 3.23 | L9: 3.89 | M9: 3.99 | N9: 4.5 | O9: 3.26
A10: =VLOOKUP(B10,'PORTFOLIO RAW'!B:B,1,FALSE) -> 894371 | B10: 894371 | C10: BOSTON PROPERTIES - MRKT VALUE TO BOOK | D10: 894371(MTBV) | E10: 3.36 | F10: 3.23 | G10: 2.2 | H10: 2.83 | I10: 3.01 | J10: 3.33 | K10: 3.01 | L10: 3.15 | M10: 3.19 | N10: 3.72 | O10: 3.32
A11: =VLOOKUP(B11,'PORTFOLIO RAW'!B:B,1,FALSE) -> 322677 | B11: 322677 | C11: ALLSTATE ORD SHS - MRKT VALUE TO BOOK | D11: 322677(MTBV) | E11: 1.56 | F11: 1.57 | G11: 0.94 | H11: 0.94 | I11: 0.73 | J11: 1.09 | K11: 1.26 | L11: 1.45 | M11: 1.31 | N11: 1.42 | O11: 1.73
A12: =VLOOKUP(B12,'PORTFOLIO RAW'!B:B,1,FALSE) -> 906191 | B12: 906191 | C12: HONEYWELL INTL. - MRKT VALUE TO BOOK | D12: 906191(MTBV) | E12: 4.72 | F12: 4.69 | G12: 3.42 | H12: 3.21 | I12: 3.39 | J12: 3.64 | K12: 3.84 | L12: 4.28 | M12: 4.19 | N12: 4.51 | O12: 6.11
A13: =VLOOKUP(B13,'PORTFOLIO RAW'!B:B,1,FALSE) -> 938692 | B13: 938692 | C13: AMGEN - MRKT VALUE TO BOOK | D13: 938692(MTBV) | E13: 3.36 | F13: 3.11 | G13: 2.72 | H13: 2.24 | I13: 2.79 | J13: 3.33 | K13: 3.98 | L13: 4.24 | M13: 4.07 | N13: 4.34 | O13: 5.44
A14: =VLOOKUP(B14,'PORTFOLIO RAW'!B:B,1,FALSE) -> 905802 | B14: 905802 | C14: HESS - MRKT VALUE TO BOOK | D14: 905802(MTBV) | E14: 2.16 | F14: 2.51 | G14: 1.36 | H14: 1.12 | I14: 1.1 | J14: 0.9 | K14: 1.09 | L14: 1.35 | M14: 0.78 | N14: 1 | O14: 1.25
... A109: =VLOOKUP(B109,'PORTFOLIO RAW'!B:B,1,FALSE) -> 905016 | B109: 905016 | C109: NEXTERA ENERGY - MRKT VALUE TO BOOK | D109: 905016(MTBV) | E109: 2.37 | F109: 1.96 | G109: 1.75 | H109: 1.57 | I109: 1.57 | J109: 1.77 | K109: 1.9 | L109: 2.08 | M109: 1.98 | N109: 2.37 | O109: 2.44
A110: =VLOOKUP(B110,'PORTFOLIO RAW'!B:B,1,FALSE) -> 28341F | B110: 28341F | C110: ASSURANT - MRKT VALUE TO BOOK | D110: 28341F(MTBV) | E110: 1.51 | F110: 1.54 | G110: 0.81 | H110: 0.99 | I110: 0.77 | J110: 0.59 | K110: 0.94 | L110: 1.09 | M110: 1.26 | N110: 1.49 | O110: 1.37
A111: =VLOOKUP(B111,'PORTFOLIO RAW'!B:B,1,FALSE) -> 755980 | B111: 755980 | C111: FASTENAL - MRKT VALUE TO BOOK | D111: 755980(MTBV) | E111: 6.65 | F111: 6.97 | G111: 4.86 | H111: 6 | I111: 7.41 | J111: 8.33 | K111: 8.4 | L111: 7.16 | M111: 5.99 | N111: 5.97 | O111: 6.12
A112: =VLOOKUP(B112,'PORTFOLIO RAW'!B:B,1,FALSE) -> 905994 | B112: 905994 | C112: FEDERAL REALTY INV.TST. - MRKT VALUE TO BOOK | D112: 905994(MTBV) | E112: 4.41 | F112: 4.71 | G112: 3.32 | H112: 4.49 | I112: 4.42 | J112: 5.28 | K112: 4.69 | L112: 5.07 | M112: 5.63 | N112: 5.6 | O112: 4.27
A113: =VLOOKUP(B113,'PORTFOLIO RAW'!B:B,1,FALSE) -> 997198 | B113: 997198 | C113: FIFTH THIRD BANCORP - MRKT VALUE TO BOOK | D113: 997198(MTBV) | E113: 2.07 | F113: 1.39 | G113: 0.84 | H113: 0.96 | I113: 0.75 | J113: 1.08 | K113: 1.23 | L113: 1.22 | M113: 1.05 | N113: 1.06 | O113: 1.34
A114: =VLOOKUP(B114,'PORTFOLIO RAW'!B:B,1,FALSE) -> 951503 | B114: 951503 | C114: M&T BANK - MRKT VALUE TO BOOK | D114: 951503(MTBV) | E114: 1.79 | F114: 1.67 | G114: 1.12 | H114: 1.43 | I114: 1.07 | J114: 1.28 | K114: 1.39 | L114: 1.52 | M114: 1.06 | N114: 1.19 | O114: 1.56
A115: =VLOOKUP(B115,'PORTFOLIO RAW'!B:B,1,FALSE) -> 741123 | B115: 741123 | C115: FISERV - MRKT VALUE TO BOOK | D115: 741123(MTBV) | E115: 3.3 | F115: 3.26 | G115: 2.52 | H115: 2.52 | I115: 2.33 | J115: 2.92 | K115: 3.7 | L115: 4.97 | M115: 7.63 | N115: 8.59 | O115: 9.64
A116: =VLOOKUP(B116,'PORTFOLIO RAW'!B:B,1,FALSE) -> 546814 | B116: 546814 | C116: MACY'S - MRKT VALUE TO BOOK | D116: 546814(MTBV) | E116: 1.49 | F116: 1.81 | G116: 1.61 | H116: 1.69 | I116: 1.97 | J116: 2.57 | K116: 2.69 | L116: 3.95 | M116: 4.21 | N116: 2.49 | O116: 1.15
A117: =VLOOKUP(B117,'PORTFOLIO RAW'!B:B,1,FALSE) -> 938076 | B117: 938076 | C117: FRANKLIN RESOURCES - MRKT VALUE TO BOOK | D117: 938076(MTBV) | E117: 4.34 | F117: 3.58 | G117: 3.12 | H117: 3.15 | I117: 2.98 | J117: 2.9 | K117: 3.27 | L117: 3.01 | M117: 2 | N117: 1.69 | O117: 1.9
A118: =VLOOKUP(B118,'PORTFOLIO RAW'!B:B,1,FALSE) -> 152594 | B118: 152594 | C118: FREEPORT-MCMORAN - MRKT VALUE TO BOOK | D118: 152594(MTBV) | E118: 2.88 | F118: 13.66 | G118: 4.63 | H118: 3.14 | I118: 2.34 | J118: 2.21 | K118: 1.68 | L118: 1.94 | M118: 1.58 | N118: 2.18 | O118: 2.57
A119: =VLOOKUP(B119,'PORTFOLIO RAW'!B:B,1,FALSE) -> 951018 | B119: 951018 | C119: GAP - MRKT VALUE TO BOOK | D119: 951018(MTBV) | E119: 3.4 | F119: 3.09 | G119: 3.14 | H119: 2.91 | I119: 3.1 | J119: 6.01 | K119: 6.34 | L119: 6.4 | M119: 5.05 | N119: 3.1 | O119: 3.49
A120: =VLOOKUP(B120,'PORTFOLIO RAW'!B:B,1,FALSE) -> 907652 | B120: 907652 | C120: GENERAL DYNAMICS - MRKT VALUE TO BOOK | D120: 907652(MTBV) | E120: 2.87 | F120: 3.26 | G120: 2 | H120: 1.82 | I120: 1.63 | J120: 2.05 | K120: 2.13 | L120: 3.66 | M120: 4.18 | N120: 4.22 | O120: 5.35
A121: =VLOOKUP(B121,'PORTFOLIO RAW'!B:B,1,FALSE) -> 905801 | B121: 905801 | C121: GENERAL MILLS - MRKT VALUE TO BOOK | D121: 905801(MTBV) | E121: 3.07 | F121: 4.52 | G121: 3.65 | H121: 3.64 | I121: 3.76 | J121: 3.91 | K121: 4.72 | L121: 6.2 | M121: 6.86 | N121: 8.84 | O121: 4.83
A122: =VLOOKUP(B122,'PORTFOLIO RAW'!B:B,1,FALSE) -> 906511 | B122: 906511 | C122: GENUINE PARTS - MRKT VALUE TO BOOK | D122: 906511(MTBV) | E122: 3.18 | F122: 2.94 | G122: 2.29 | H122: 2.5 | I122: 2.94 | J122: 3.24 | K122: 3.76 | L122: 4.14 | M122: 4.01 | N122: 4.6 | O122: 3.73
... A235: =VLOOKUP(B235,'PORTFOLIO RAW'!B:B,1,FALSE) -> 933974 | B235: 933974 | C235: TRAVELERS COS. - MRKT VALUE TO BOOK | D235: 933974(MTBV) | E235: 1.3 | F235: 1.18 | G235: 1.06 | H235: 1.07 | I235: 0.98 | J235: 1.18 | K235: 1.37 | L235: 1.4 | M235: 1.39 | N235: 1.47 | O235: 1.48
A236: =VLOOKUP(B236,'PORTFOLIO RAW'!B:B,1,FALSE) -> 14015T | B236: 14015T | C236: FIDELITY NAT.INFO.SVS. - MRKT VALUE TO BOOK | D236: 14015T(MTBV) | E236: 2.35 | F236: 1.09 | G236: 0.58 | H236: 1.29 | I236: 1.22 | J236: 1.44 | K236: 2.08 | L236: 2.49 | M236: 2.06 | N236: 2.58 | O236: 2.85
A237: =VLOOKUP(B237,'PORTFOLIO RAW'!B:B,1,FALSE) -> 905019 | B237: 905019 | C237: MERCK & COMPANY - MRKT VALUE TO BOOK | D237: 905019(MTBV) | E237: 6.13 | F237: 3.64 | G237: 1.14 | H237: 2.07 | I237: 1.84 | J237: 2.58 | K237: 2.82 | L237: 3.59 | M237: 3.29 | N237: 4.27 | O237: 5.23
A238: =VLOOKUP(B238,'PORTFOLIO RAW'!B:B,1,FALSE) -> 912090 | B238: 912090 | C238: SCHLUMBERGER - MRKT VALUE TO BOOK | D238: 912090(MTBV) | E238: 8.6 | F238: 6.45 | G238: 3.87 | H238: 2.58 | I238: 2.99 | J238: 2.87 | K238: 2.93 | L238: 3.54 | M238: 2.58 | N238: 2.55 | O238: 2.54
A239: =VLOOKUP(B239,'PORTFOLIO RAW'!B:B,1,FALSE) -> 755741 | B239: 755741 | C239: CHARLES SCHWAB - MRKT VALUE TO BOOK | D239: 755741(MTBV) | E239: 7.07 | F239: 7.16 | G239: 4.03 | H239: 2.68 | I239: 1.86 | J239: 1.97 | K239: 2.88 | L239: 3.63 | M239: 3.14 | N239: 2.99 | O239: 3.55
A240: =VLOOKUP(B240,'PORTFOLIO RAW'!B:B,1,FALSE) -> 14361V | B240: 14361V | C240: ZIMMER BIOMET HDG. - MRKT VALUE TO BOOK | D240: 14361V(MTBV) | E240: 3.61 | F240: 2.71 | G240: 1.94 | H240: 1.8 | I240: 1.98 | J240: 1.99 | K240: 2.24 | L240: 2.69 | M240: 2.04 | N240: 2.58 | O240: 2
A241: =VLOOKUP(B241,'PORTFOLIO RAW'!B:B,1,FALSE) -> 154680 | B241: 154680 | C241: AMERISOURCEBERGEN - MRKT VALUE TO BOOK | D241: 154680(MTBV) | E241: 2.65 | F241: 2.31 | G241: 2.38 | H241: 2.89 | I241: 3.73 | J241: 3.93 | K241: 6.14 | L241: 8.87 | M241: 36.21 | N241: 9.17 | O241: 8.44
A242: =VLOOKUP(B242,'PORTFOLIO RAW'!B:B,1,FALSE) -> 14698C | B242: 14698C | C242: PRINCIPAL FINL.GP. - MRKT VALUE TO BOOK | D242: 14698C(MTBV) | E242: 2.32 | F242: 2.11 | G242: 1.09 | H242: 0.93 | I242: 0.88 | J242: 1.01 | K242: 1.35 | L242: 1.57 | M242: 1.52 | N242: 1.38 | O242: 1.61
A243: =VLOOKUP(B243,'PORTFOLIO RAW'!B:B,1,FALSE) -> 905361 | B243: 905361 | C243: SHERWIN-WILLIAMS - MRKT VALUE TO BOOK | D243: 905361(MTBV) | E243: 4.93 | F243: 4.64 | G243: 4.84 | H243: 5.05 | I243: 5.2 | J243: 8.99 | K243: 10.66 | L243: 21.64 | M243: 26.49 | N243: 13.51 | O243: 8.78
A244: =VLOOKUP(B244,'PORTFOLIO RAW'!B:B,1,FALSE) -> 357834 | B244: 357834 | C244: SIMON PROPERTY GROUP - MRKT VALUE TO BOOK | D244: 357834(MTBV) | E244: 7.85 | F244: 8.69 | G244: 4.71 | H244: 5.95 | I244: 7.63 | J244: 8.06 | K244: 8.07 | L244: 10.2 | M244: 12.86 | N244: 15.37 | O244: 13.64
A245: =VLOOKUP(B245,'PORTFOLIO RAW'!B:B,1,FALSE) -> 906400 | B245: 906400 | C245: SNAP-ON - MRKT VALUE TO BOOK | D245: 906400(MTBV) | E245: 2.22 | F245: 2.83 | G245: 1.65 | H245: 1.96 | I245: 1.9 | J245: 2.33 | K245: 2.78 | L245: 3.26 | M245: 3.75 | N245: 3.32 | O245: 2.91
A246: =VLOOKUP(B246,'PORTFOLIO RAW'!B:B,1,FALSE) -> 14861V | B246: 14861V | C246: PRUDENTIAL FINL. - MRKT VALUE TO BOOK | D246: 14861V(MTBV) | E246: 1.86 | F246: 1.83 | G246: 0.99 | H246: 0.9 | I246: 0.75 | J246: 0.98 | K246: 1.45 | L246: 1.89 | M246: 1.31 | N246: 1.26 | O246: 1.33
...

Sheet MCAP
A1: Market Capitalization
A2: Code | B2: Code | C2: Name | D2: Code | E2: 2007 | F2: 2008 | G2: 2009 | H2: 2010 | I2: 2011 | J2: 2012 | K2: 2013 | L2: 2014 | M2: 2015 | N2: 2016 | O2: 2017 | P2: 2018
A3: =VLOOKUP(B3,'PORTFOLIO RAW'!B:B,1,FALSE) -> 906187 | B3: 906187 | C3: INT'L BUSINESS MACHS - MARKET CAPITALIZATION | D3: 906187(WC08001) | E3: 149743810 | F3: 112698313 | G3: 170868669 | H3: 180220333 | I3: 213886010 | J3: 214031778 | K3: 197772108 | L3: 158919632 | M3: 132903587 | N3: 157004530 | O3: 141480737 | P3: 101448135
A4: =VLOOKUP(B4,'PORTFOLIO RAW'!B:B,1,FALSE) -> 902172 | B4: 902172 | C4: 3M COMPANY - MARKET CAPITALIZATION | D4: 902172(WC08001) | E4: 59796037 | F4: 39906481 | G4: 58745229 | H4: 61443668 | I4: 56799901 | J4: 63796460 | K4: 93027298 | L4: 104365316 | M4: 91789490 | N4: 106557411 | O4: 140017903 | P4: 109860633
A5: =VLOOKUP(B5,'PORTFOLIO RAW'!B:B,1,FALSE) -> 902317 | B5: 902317 | C5: EXELON CORPORATION - MARKET CAPITALIZATION | D5: 902317(WC08001) | E5: 53978980 | F5: 36591380 | G5: 32254200 | H5: 27565680 | I5: 28770312 | J5: 25421199 | K5: 23473230 | L5: 31888800 | M5: 25548400 | N5: 32792760 | O5: 37951830 | P5: 43656800
A6: =VLOOKUP(B6,'PORTFOLIO RAW'!B:B,1,FALSE) -> 998171 | B6: 998171 | C6: HOME DEPOT, INC. - MARKET CAPITALIZATION | D6: 998171(WC08001) | E6: 45528600 | F6: 39041920 | G6: 49123140 | H6: 56902380 | I6: 64615480 | J6: 91785400 | K6: 113629200 | L6: 137195790 | M6: 165577000 | N6: 161298240 | O6: 219475740 | P6: 189861100
A7: =VLOOKUP(B7,'PORTFOLIO RAW'!B:B,1,FALSE) -> 912273 | B7: 912273 | C7: CORNING INCORPORATED - MARKET CAPITALIZATION | D7: 912273(WC08001) | E7: 37616320 | F7: 14752440 | G7: 29988430 | H7: 30158520 | I7: 19664700 | J7: 18551400 | K7: 24930180 | L7: 29212820 | M7: 20656400 | N7: 22474020 | O7: 27447420 | P7: 23805480
A8: =VLOOKUP(B8,'PORTFOLIO RAW'!B:B,1,FALSE) -> 905113 | B8: 905113 | C8: ARCONIC INC - MARKET CAPITALIZATION | D8: 905113(WC08001) | E8: 30241536 | F8: 9011574 | G8: 15706955 | H8: 15728979 | I8: 9207164 | J8: 9263400 | K8: 11384849 | L8: 19211119 | M8: 12931280 | N8: 8130157 | O8: 13118601 | P8: 8147944
A9: =VLOOKUP(B9,'PORTFOLIO RAW'!B:B,1,FALSE) -> 902354 | B9: 902354 | C9: KIMBERLY-CLARK CORP - MARKET CAPITALIZATION | D9: 902354(WC08001) | E9: 29185206 | F9: 21813264 | G9: 26567070 | H9: 25650976 | I9: 29107692 | J9: 32868599 | K9: 39778264 | L9: 42206762 | M9: 45942570 | N9: 40695192 | O9: 42363726 | P9: 39309300
A10: =VLOOKUP(B10,'PORTFOLIO RAW'!B:B,1,FALSE) -> 9373MH | B10: 9373MH | C10: LINDE PLC - MARKET CAPITALIZATION | D10: 9373MH(WC08001) | E10: 27986954 | F10: 18215291 | G10: 24613216 | H10: 29022553 | I10: 31912859 | J10: 32422317 | K10: 38246226 | L10: 37476734 | M10: 29171618 | N10: 33387522 | O10: 44358665 | P10: 85391584
A11: =VLOOKUP(B11,'PORTFOLIO RAW'!B:B,1,FALSE) -> 905296 | B11: 905296 | C11: APPLIED MATERIALS - MARKET CAPITALIZATION | D11: 905296(WC08001) | E11: 24610227 | F11: 13480609 | G11: 18692383 | H11: 18658372 | I11: 13987260 | J11: 13693680 | K11: 21286720 | L11: 30427320 | M11: 21657200 | N11: 34787060 | O11: 54187200 | P11: 31659580
A12: =VLOOKUP(B12,'PORTFOLIO RAW'!B:B,1,FALSE) -> 545615 | B12: 545615 | C12: JOHNSON CONTROLS INT - MARKET CAPITALIZATION | D12: 545615(WC08001) | E12: 19678368 | F12: 10212172 | G12: 16918162 | H12: 20239527 | I12: 21702594 | J12: 13519020 | K12: 19020411 | L12: 18723948 | M12: 13467820 | N12: 38545430 | O12: 35365126 | P12: 28196259
A13: =VLOOKUP(B13,'PORTFOLIO RAW'!B:B,1,FALSE) -> 951018 | B13: 951018 | C13: GAP INC - MARKET CAPITALIZATION | D13: 951018(WC08001) | E13: 15619520 | F13: 9292660 | G13: 14162200 | H13: 13018320 | I13: 8996750 | J13: 14371520 | K13: 17429680 | L13: 17728310 | M13: 9805900 | N13: 8953560 | O13: 13249340 | P13: 9737280
A14: =VLOOKUP(B14,'PORTFOLIO RAW'!B:B,1,FALSE) -> 902230 | B14: 902230 | C14: FORD MOTOR COMPANY - MARKET CAPITALIZATION | D14: 902230(WC08001) | E14: 14772350 | F14: 5523480 | G14: 33370000 | H14: 63511717 | I14: 40896036 | J14: 50793107 | K14: 61473120 | L14: 62139500 | M14: 56796790 | N14: 49090110 | O14: 50684420 | P14: 31143150
A15: =VLOOKUP(B15,'PORTFOLIO RAW'!B:B,1,FALSE) -> 904069 | B15: 904069 | C15: INTERNATIONAL PAPER - MARKET CAPITALIZATION | D15: 904069(WC08001) | E15: 13767976 | F15: 5043981 | G15: 11600025 | H15: 11921232 | I15: 12933750 | J15: 17524859 | K15: 21393358 | L15: 22512494 | M15: 15537075 | N15: 21819811 | O15: 23924875 | P15: 16167812
A16: =VLOOKUP(B16,'PORTFOLIO RAW'!B:B,1,FALSE) -> 902335 | B16: 902335 | C16: WEC ENERGY GROUP INC - MARKET CAPITALIZATION | D16: 902335(WC08001) | E16: 5696297 | F16: 4908259 | G16: 5825676 | H16: 6879886 | I16: 8057819 | J16: 8440104 | K16: 9341309 | L16: 11893784 | M16: 16197720 | N16: 18510816 | O16: 20963622 | P16: 21853136
A17: =VLOOKUP(B17,'PORTFOLIO RAW'!B:B,1,FALSE) -> 905082 | B17: 905082 | C17: FMC CORPORATION - MARKET CAPITALIZATION | D17: 905082(WC08001) | E17: 4098309 | F17: 3243370 | G17: 4043653 | H17: 5711004 | I17: 6008789 | J17: 8056471 | K17: 10027554 | L17: 7603107 | M17: 5229951 | N17: 7561512 | O17: 12715730 | P17: 9783548
A18: =VLOOKUP(B18,'PORTFOLIO RAW'!B:B,1,FALSE) -> 912228 | B18: 912228 | C18: PROCTER & GAMBLE - MARKET CAPITALIZATION | D18: 912228(WC08001) | E18: 229944098 | F18: 187432058 | G18: 176857710 | H18: 182922355 | I18: 184499847 | J18: 186561720 | K18: 223250643 | L18: 246927319 | M18: 215558445 | N18: 224325440 | O18: 234597204 | P18: 229616160
A19: =VLOOKUP(B19,'PORTFOLIO RAW'!B:B,1,FALSE) -> 542868 | B19: 542868 | C19: CISCO SYSTEMS, INC. - MARKET CAPITALIZATION | D19: 542868(WC08001) | E19: 165126390 | F19: 96055900 | G19: 138492900 | H19: 114400650 | I19: 98264800 | J19: 104102521 | K19: 120875270 | L19: 142051205 | M19: 138083175 | N19: 151976380 | O19: 190848900 | P19: 199924620
A20: =VLOOKUP(B20,'PORTFOLIO RAW'!B:B,1,FALSE) -> 922726 | B20: 922726 | C20: INTEL CORPORATION - MARKET CAPITALIZATION | D20: 922726(WC08001) | E20: 155107880 | F20: 81538920 | G20: 112669200 | H20: 115896330 | I20: 121250000 | J20: 101945280 | K20: 128918485 | L20: 172304920 | M20: 162776250 | N20: 171557100 | O20: 216351920 | P20: 211935880
A21: =VLOOKUP(B21,'PORTFOLIO RAW'!B:B,1,FALSE) -> 902242 | B21: 902242 | C21: JPMORGAN CHASE & CO - MARKET CAPITALIZATION | D21: 902242(WC08001) | E21: 146987010 | F21: 117544026 | G21: 164263140 | H21: 165874676 | I21: 125441966 | J21: 167256355 | K21: 219657214 | L21: 232471512 | M21: 241899221 | N21: 307295076 | O21: 366301457 | P21: 319780298
A22: =VLOOKUP(B22,'PORTFOLIO RAW'!B:B,1,FALSE) -> 905019 | B22: 905019 | C22: MERCK & CO INC - MARKET CAPITALIZATION | D22: 905019(WC08001) | E22: 126244143 | F22: 64073786 | G22: 113574452 | H22: 111079130 | I22: 114639617 | J22: 123910449 | K22: 146522712 | L22: 161177982 | M22: 146899185 | N22: 161817813 | O22: 151738335 | P22: 198097475
... A46: =VLOOKUP(B46,'PORTFOLIO RAW'!B:B,1,FALSE) -> 905016 | B46: 905016 | C46: NEXTERA ENERGY - MARKET CAPITALIZATION | D46: 905016(WC08001) | E46: 27609842 | F46: 20580707 | G46: 21847537 | H46: 21880591 | I46: 25326080 | J46: 29336560 | K46: 37244700 | L46: 47086470 | M46: 47893290 | N46: 55907280 | O46: 73565490 | P46: 83085960
A47: =VLOOKUP(B47,'PORTFOLIO RAW'!B:B,1,FALSE) -> 14352P | B47: 14352P | C47: ACCENTURE PLC - MARKET CAPITALIZATION | D47: 14352P(WC08001) | E47: 27330590 | F47: 23976484 | G47: 29584317 | H47: 33459247 | I47: 36771251 | J47: 45003917 | K47: 54787741 | L47: 58637023 | M47: 67928811 | N47: 75266594 | O47: 97378767 | P47: 90202687
A48: =VLOOKUP(B48,'PORTFOLIO RAW'!B:B,1,FALSE) -> 912633 | B48: 912633 | C48: RAYTHEON COMPANY - MARKET CAPITALIZATION | D48: 912633(WC08001) | E48: 25870097 | F48: 20416000 | G48: 19474560 | H48: 16636060 | I48: 16400820 | J48: 18879680 | K48: 28570500 | L48: 33208190 | M48: 37234470 | N48: 41606000 | O48: 54100800 | P48: 43244700
A49: =VLOOKUP(B49,'PORTFOLIO RAW'!B:B,1,FALSE) -> 904383 | B49: 904383 | C49: DUKE ENERGY CORP - MARKET CAPITALIZATION | D49: 904383(WC08001) | E49: 25454540 | F49: 19092720 | G49: 22527890 | H49: 23669488 | I49: 29392000 | J49: 44915200 | K49: 48721060 | L49: 59062780 | M49: 49116320 | N49: 54334000 | O49: 58877000 | P49: 62740100
A50: =VLOOKUP(B50,'PORTFOLIO RAW'!B:B,1,FALSE) -> 902321 | B50: 902321 | C50: PUBLIC SVC ENTRPR GR - MARKET CAPITALIZATION | D50: 902321(WC08001) | E50: 24978650 | F50: 14760542 | G50: 16823849 | H50: 16095040 | I50: 16701254 | J50: 15480310 | K50: 16207667 | L50: 20946693 | M50: 19577140 | N50: 22159400 | O50: 26007500 | P50: 26233200
A51: =VLOOKUP(B51,'PORTFOLIO RAW'!B:B,1,FALSE) -> 516007 | B51: 516007 | C51: MGM RESORTS - MARKET CAPITALIZATION | D51: 516007(WC08001) | E51: 24682463 | F51: 3804676 | G51: 4023923 | H51: 7254423 | I51: 5098547 | J51: 5694688 | K51: 11533282 | L51: 10503825 | M51: 12833140 | N51: 16551986 | O51: 18907949 | P51: 12796653
A52: =VLOOKUP(B52,'PORTFOLIO RAW'!B:B,1,FALSE) -> 944704 | B52: 944704 | C52: CARDINAL HEALTH, INC - MARKET CAPITALIZATION | D52: 944704(WC08001) | E52: 21257775 | F52: 12309237 | G52: 11606400 | H52: 13653684 | I52: 14258171 | J52: 14124740 | K52: 22648590 | L52: 27206010 | M52: 29280560 | N52: 23174340 | O52: 19361320 | P52: 13781400
A53: =VLOOKUP(B53,'PORTFOLIO RAW'!B:B,1,FALSE) -> 905271 | B53: 905271 | C53: AIR PRODUCTS & CHEMS - MARKET CAPITALIZATION | D53: 905271(WC08001) | E53: 21240531 | F53: 10523252 | G53: 17124757 | H53: 19445371 | I53: 17905682 | J53: 17852223 | K53: 23605617 | L53: 30798607 | M53: 28020374 | N53: 31259396 | O53: 35826224 | P53: 35133415
A54: =VLOOKUP(B54,'PORTFOLIO RAW'!B:B,1,FALSE) -> 902107 | B54: 902107 | C54: PPL CORP - MARKET CAPITALIZATION | D54: 902107(WC08001) | E54: 19443686 | F54: 11495754 | G54: 12186783 | H54: 12722851 | I54: 17016675 | J54: 16661057 | K54: 18966359 | L54: 24190294 | M54: 22998739 | N54: 23144841 | O54: 21460668 | P54: 20406751
A55: =VLOOKUP(B55,'PORTFOLIO RAW'!B:B,1,FALSE) -> 357834 | B55: 357834 | C55: SIMON PROPERTY GROUP - MARKET CAPITALIZATION | D55: 357834(WC08001) | E55: 19372758 | F55: 12290225 | G55: 22802712 | H55: 29545084 | I55: 37888793 | J55: 48991431 | K55: 47262199 | L55: 56597586 | M55: 60163735 | N55: 55623960 | O55: 53439796 | P55: 51911844
A56: =VLOOKUP(B56,'PORTFOLIO RAW'!B:B,1,FALSE) -> 134784 | B56: 134784 | C56: MCKESSON CORPORATION - MARKET CAPITALIZATION | D56: 134784(WC08001) | E56: 19325450 | F56: 10728210 | G56: 16937500 | H56: 19072980 | I56: 19633320 | J56: 22785600 | K56: 36637800 | L56: 47950980 | M56: 45757360 | N56: 31601250 | O56: 32905450 | P56: 22314940
A57: =VLOOKUP(B57,'PORTFOLIO RAW'!B:B,1,FALSE) -> 878574 | B57: 878574 | C57: YUM! BRANDS INC - MARKET CAPITALIZATION | D57: 878574(WC08001) | E57: 19096730 | F57: 14458500 | G57: 16400930 | H57: 23004450 | I57: 27144600 | J57: 29946400 | K57: 33495230 | L57: 31616900 | M57: 30681000 | N57: 22482150 | O57: 27094520 | P57: 28127520
A58: =VLOOKUP(B58,'PORTFOLIO RAW'!B:B,1,FALSE) -> 905861 | B58: 905861 | C58: NORTHERN TRUST CORP - MARKET CAPITALIZATION | D58: 905861(WC08001) | E58: 16894237 | F58: 11640933 | G58: 12664032 | H58: 13424120 | I58: 9558397 | J58: 11983976 | K58: 14687861 | L58: 15730534 | M58: 16529789 | N58: 20357318 | O58: 22587793 | P58: 18307217
A59: =VLOOKUP(B59,'PORTFOLIO RAW'!B:B,1,FALSE) -> 905818 | B59: 905818 | C59: WEYERHAEUSER CO - MARKET CAPITALIZATION | D59: 905818(WC08001) | E59: 15451957 | F59: 6467561 | G59: 9117973 | H59: 10146017 | I59: 10015062 | J59: 15089363 | K59: 18422624 | L59: 18823383 | M59: 15304289 | N59: 22523211 | O59: 26629153 | P59: 16316107
A60: =VLOOKUP(B60,'PORTFOLIO RAW'!B:B,1,FALSE) -> 14361V | B60: 14361V | C60: ZIMMER BIOMET - MARKET CAPITALIZATION | D60: 14361V(WC08001) | E60: 15406335 | F60: 9037912 | G60: 12070262 | H60: 10499808 | I60: 9508760 | J60: 11438856 | K60: 15823662 | L60: 19247374 | M60: 20794993 | N60: 20701920 | O60: 24447742 | P60: 21158880
A61: =VLOOKUP(B61,'PORTFOLIO RAW'!B:B,1,FALSE) -> 545101 | B61: 545101 | C61: AES CORP - MARKET CAPITALIZATION | D61: 545101(WC08001) | E61: 14338569 | F61: 5461363 | G61: 8886820 | H61: 9593056 | I61: 9059806 | J61: 7963623 | K61: 10483596 | L61: 9692032 | M61: 6381360 | N61: 7659698 | O61: 7152003 | P61: 9576830
A62: =VLOOKUP(B62,'PORTFOLIO RAW'!B:B,1,FALSE) -> 903749 | B62: 903749 | C62: EATON CORP PLC - MARKET CAPITALIZATION | D62: 903749(WC08001) | E62: 14154700 | F62: 8202150 | G62: 10573644 | H62: 17251625 | I62: 14556432 | J62: 25502526 | K62: 36164612 | L62: 31798484 | M62: 23875952 | N62: 30150246 | O62: 34756499 | P62: 29084376
A63: =VLOOKUP(B63,'PORTFOLIO RAW'!B:B,1,FALSE) -> 26599V | B63: 26599V | C63: SEAGATE TECHNOLOGY - MARKET CAPITALIZATION | D63: 26599V(WC08001) | E63: 13642027 | F63: 2149115 | G63: 8967830 | H63: 7067719 | I63: 6963630 | J63: 12047321 | K63: 20185984 | L63: 21714865 | M63: 11564233 | N63: 11396502 | O63: 12208894 | P63: 11081904
...

Sheet NI
A1: Net Income
B2: Code | C2: Name | D2: Code | E2: 2007 | F2: 2008 | G2: 2009 | H2: 2010 | I2: 2011 | J2: 2012 | K2: 2013 | L2: 2014 | M2: 2015 | N2: 2016 | O2: 2017
A3: =VLOOKUP(B3,'PORTFOLIO RAW'!B:B,1,FALSE) -> 902172 | B3: 902172 | C3: 3M COMPANY - NET INCOME - BASIC | D3: 902172(WC01706) | E3: 4096000 | F3: 3460000 | G3: 3193000 | H3: 4085000 | I3: 4283000 | J3: 4444000 | K3: 4659000 | L3: 4956000 | M3: 4833000 | N3: 5050000 | O3: 5620000
A4: =VLOOKUP(B4,'PORTFOLIO RAW'!B:B,1,FALSE) -> 916328 | B4: 916328 | C4: ABBOTT LABORATORIES - NET INCOME - BASIC | D4: 916328(WC01706) | E4: 3606314 | F4: 4734216 | G4: 5745838 | H4: 4626172 | I4: 4728449 | J4: 5962920 | K4: 2576000 | L4: 2284000 | M4: 2671000 | N4: 1384000 | O4: 1937000
A5: =VLOOKUP(B5,'PORTFOLIO RAW'!B:B,1,FALSE) -> 14352P | B5: 14352P | C5: ACCENTURE PLC - NET INCOME - BASIC | D5: 14352P(WC01706) | E5: 1243148 | F5: 1691751 | G5: 1589963 | H5: 1780656 | I5: 2277677 | J5: 2553510 | K5: 3281878 | L5: 2941498 | M5: 3053581 | N5: 4111892 | O5: 3445149
A6: =VLOOKUP(B6,'PORTFOLIO RAW'!B:B,1,FALSE) -> 312367 | B6: 312367 | C6: ACTIVISION BLIZZARD - NET INCOME - BASIC | D6: 312367(WC01706) | E6: 227000 | F6: -107000 | G6: 113000 | H6: 414000 | I6: 1069000 | J6: 1125000 | K6: 998000 | L6: 847000 | M6: 881000 | N6: 962000 | O6: 909000
A7: =VLOOKUP(B7,'PORTFOLIO RAW'!B:B,1,FALSE) -> 749382 | B7: 749382 | C7: ADOBE INC - NET INCOME - BASIC | D7: 749382(WC01706) | E7: 723807 | F7: 871814 | G7: 386508 | H7: 774680 | I7: 832847 | J7: 832775 | K7: 289985 | L7: 268395 | M7: 629551 | N7: 1168782 | O7: 1693954
A8: =VLOOKUP(B8,'PORTFOLIO RAW'!B:B,1,FALSE) -> 14806F | B8: 14806F | C8: ADVANCE AUTO PARTS - NET INCOME - BASIC | D8: 14806F(WC01706) | E8: 238317 | F8: 238038 | G8: 270373 | H8: 344501 | I8: 393627 | J8: 386800 | K8: 390863 | L8: 492270 | M8: 471745 | N8: 457677 | O8: 331705
A9: =VLOOKUP(B9,'PORTFOLIO RAW'!B:B,1,FALSE) -> 936365 | B9: 936365 | C9: ADVANCED MICRO - NET INCOME - BASIC | D9: 936365(WC01706) | E9: -3379000 | F9: -3098000 | G9: 304000 | H9: 471000 | I9: 491000 | J9: -1183000 | K9: -83000 | L9: -403000 | M9: -660000 | N9: -497000 | O9: -1087000
A10: =VLOOKUP(B10,'PORTFOLIO RAW'!B:B,1,FALSE) -> 545101 | B10: 545101 | C10: AES CORP - NET INCOME - BASIC | D10: 545101(WC01706) | E10: 495000 | F10: 1228000 | G10: 808000 | H10: -55000 | I10: -28000 | J10: -928000 | K10: 266000 | L10: 825000 | M10: 306000 | N10: -11000 | O10: -511000
A11: =VLOOKUP(B11,'PORTFOLIO RAW'!B:B,1,FALSE) -> 933185 | B11: 933185 | C11: AFLAC INCORPORATED - NET INCOME - BASIC | D11: 933185(WC01706) | E11: 1634000 | F11: 1254000 | G11: 1497000 | H11: 2344000 | I11: 1964000 | J11: 2866000 | K11: 3158000 | L11: 2951000 | M11: 2533000 | N11: 2659000 | O11: 2671000
A12: =VLOOKUP(B12,'PORTFOLIO RAW'!B:B,1,FALSE) -> 277642 | B12: 277642 | C12: AGILENT TECHNOLOGIES - NET INCOME - BASIC | D12: 277642(WC01706) | E12: 638000 | F12: 693000 | G12: -31000 | H12: 684000 | I12: 1012000 | J12: 1153000 | K12: 724000 | L12: 504000 | M12: 401000 | N12: 462000 | O12: 684000
A13: =VLOOKUP(B13,'PORTFOLIO RAW'!B:B,1,FALSE) -> 905271 | B13: 905271 | C13: AIR PRODUCTS & CHEMS - NET INCOME - BASIC | D13: 905271(WC01706) | E13: 1042700 | F13: 1090500 | G13: 631400 | H13: 1029100 | I13: 1224200 | J13: 1046500 | K13: 994200 | L13: 991700 | M13: 1277900 | N13: 631100 | O13: 1219900
A14: =VLOOKUP(B14,'PORTFOLIO RAW'!B:B,1,FALSE) -> 277355 | B14: 277355 | C14: AKAMAI TECHNOLOGIES - NET INCOME - BASIC | D14: 277355(WC01706) | E14: 100967 | F14: 145138 | G14: 145913 | H14: 171220 | I14: 200904 | J14: 203989 | K14: 293487 | L14: 333948 | M14: 321406 | N14: 316132 | O14: 244321
A15: =VLOOKUP(B15,'PORTFOLIO RAW'!B:B,1,FALSE) -> 130298 | B15: 130298 | C15: ALBEMARLE CORP - NET INCOME - BASIC | D15: 130298(WC01706) | E15: 229690 | F15: 194202 | G15: 178368 | H15: 323720 | I15: 436280 | J15: 311536 | K15: 413171 | L15: 133316 | M15: 334906 | N15: 643675 | O15: 474350
A16: =VLOOKUP(B16,'PORTFOLIO RAW'!B:B,1,FALSE) -> 325596 | B16: 325596 | C16: ALLERGAN PLC - NET INCOME - BASIC | D16: 325596(WC01706) | E16: 141030 | F16: 238379 | G16: 222000 | H16: 184400 | I16: 260900 | J16: 97300 | K16: -750400 | L16: -1630500 | M16: 3683200 | N16: 14695000 | O16: -7203900
A17: =VLOOKUP(B17,'PORTFOLIO RAW'!B:B,1,FALSE) -> 906979 | B17: 906979 | C17: ALLIANT ENERGY CORP - NET INCOME - BASIC | D17: 906979(WC01706) | E17: 424700 | F17: 288000 | G17: 111000 | H17: 287600 | I17: 303600 | J17: 319800 | K17: 358300 | L17: 383100 | M17: 378200 | N17: 371500 | O17: 439200
A18: =VLOOKUP(B18,'PORTFOLIO RAW'!B:B,1,FALSE) -> 322677 | B18: 322677 | C18: ALLSTATE CORP - NET INCOME - BASIC | D18: 322677(WC01706) | E18: 4636000 | F18: -1679000 | G18: 854000 | H18: 928000 | I18: 788000 | J18: 2306000 | K18: 2263000 | L18: 2746000 | M18: 2055000 | N18: 1761000 | O18: 2567000
A19: =VLOOKUP(B19,'PORTFOLIO RAW'!B:B,1,FALSE) -> 29026M | B19: 29026M | C19: ALPHABET INC - NET INCOME - BASIC | D19: 29026M(WC01706) | E19: 4203720 | F19: 4226858 | G19: 6520448 | H19: 8505000 | I19: 9737000 | J19: 10737000 | K19: 12920000 | L19: 14444000 | M19: 15826000 | N19: 19478000 | O19: 22486000
A20: =VLOOKUP(B20,'PORTFOLIO RAW'!B:B,1,FALSE) -> 904853 | B20: 904853 | C20: ALTRIA GROUP INC - NET INCOME - BASIC | D20: 904853(WC01706) | E20: 9786000 | F20: 3090000 | G20: 3206000 | H20: 3890000 | I20: 3377000 | J20: 4167000 | K20: 4523000 | L20: 5058000 | M20: 5231000 | N20: 14215000 | O20: 6841000
A21: =VLOOKUP(B21,'PORTFOLIO RAW'!B:B,1,FALSE) -> 891399 | B21: 891399 | C21: AMAZON.COM INC - NET INCOME - BASIC | D21: 891399(WC01706) | E21: 476000 | F21: 645000 | G21: 902000 | H21: 1152000 | I21: 631000 | J21: -39000 | K21: 274000 | L21: -241000 | M21: 596000 | N21: 2371000 | O21: 2244000
A22: =VLOOKUP(B22,'PORTFOLIO RAW'!B:B,1,FALSE) -> 670942 | B22: 670942 | C22: AMEREN CORPORATION - NET INCOME - BASIC | D22: 670942(WC01706) | E22: 618000 | F22: 607000 | G22: 612000 | H22: 139000 | I22: 519000 | J22: -974000 | K22: 289000 | L22: 586000 | M22: 630000 | N22: 653000 | O22: 677000
A23: =VLOOKUP(B23,'PORTFOLIO RAW'!B:B,1,FALSE) -> 905425 | B23: 905425 | C23: AMERICAN ELECTRIC - NET INCOME - BASIC | D23: 905425(WC01706) | E23: 1144000 | F23: 1380000 | G23: 1362000 | H23: 1211000 | I23: 1568000 | J23: 1259000 | K23: 1480000 | L23: 1634000 | M23: 2047100 | N23: 610900 | O23: 1885900
A24: =VLOOKUP(B24,'PORTFOLIO RAW'!B:B,1,FALSE) -> 906156 | B24: 906156 | C24: AMERICAN EXPRESS CO - NET INCOME - BASIC | D24: 906156(WC01706) | E24: 4012000 | F24: 2688000 | G24: 1802000 | H24: 4006000 | I24: 4877000 | J24: 4433000 | K24: 5312000 | L24: 5839000 | M24: 5063000 | N24: 5285000 | O24: 5234000
A25: =VLOOKUP(B25,'PORTFOLIO RAW'!B:B,1,FALSE) -> 916305 | B25: 916305 | C25: AMERICAN INT'L GROUP - NET INCOME - BASIC | D25: 916305(WC01706) | E25: 6200000 | F25: -99689000 | G25: -12244000 | H25: 1583000 | I25: 16986000 | J25: 3438000 | K25: 9085000 | L25: 7529000 | M25: 2196000 | N25: -849000 | O25: 616000
A26: =VLOOKUP(B26,'PORTFOLIO RAW'!B:B,1,FALSE) -> 680902 | B26: 680902 | C26: AMERICAN TOWER CORP - NET INCOME - BASIC | D26: 680902(WC01706) | E26: 56316 | F26: 347246 | G26: 246595 | H26: 372936 | I26: 396462 | J26: 637283 | K26: 551333 | L26: 801022 | M26: 594911 | N26: 849300 | O26: 1151500
A27: =VLOOKUP(B27,'PORTFOLIO RAW'!B:B,1,FALSE) -> 31604H | B27: 31604H | C27: AMERIPRISE FIN - NET INCOME - BASIC | D27: 31604H(WC01706) | E27: 814000 | F27: -38000 | G27: 722000 | H27: 1097000 | I27: 1050000 | J27: 1036000 | K27: 1334000 | L27: 1619000 | M27: 1562000 | N27: 1314000 | O27: 1766000
A28: =VLOOKUP(B28,'PORTFOLIO RAW'!B:B,1,FALSE) -> 154680 | B28: 154680 | C28: AMERISOURCEBERGEN - NET INCOME - BASIC | D28: 154680(WC01706) | E28: 493768 | F28: 469064 | G28: 511852 | H28: 636748 | I28: 706624 | J28: 718986 | K28: 433707 | L28: 276484 | M28: -134887 | N28: 1427929 | O28: 364484
A29: =VLOOKUP(B29,'PORTFOLIO RAW'!B:B,1,FALSE) -> 938692 | B29: 938692 | C29: AMGEN INC - NET INCOME - BASIC | D29: 938692(WC01706) | E29: 3166000 | F29: 4196000 | G29: 4605000 | H29: 4627000 | I29: 3683000 | J29: 4345000 | K29: 5081000 | L29: 5158000 | M29: 6939000 | N29: 7722000 | O29: 8079000
A30: =VLOOKUP(B30,'PORTFOLIO RAW'!B:B,1,FALSE) -> 546075 | B30: 546075 | C30: AMPHENOL CORP - NET INCOME - BASIC | D30: 546075(WC01706) | E30: 353194 | F30: 419151 | G30: 317834 | H30: 496405 | I30: 524191 | J30: 555317 | K30: 635672 | L30: 709100 | M30: 763500 | N30: 822900 | O30: 1049000
A31: =VLOOKUP(B31,'PORTFOLIO RAW'!B:B,1,FALSE) -> 905276 | B31: 905276 | C31: ANALOG DEVICES, INC. - NET INCOME - BASIC | D31: 905276(WC01706) | E31: 496907 | F31: 525177 | G31: 247772 | H31: 711225 | I31: 860894 | J31: 651236 | K31: 673487 | L31: 629320 | M31: 696878 | N31: 861664 | O31: 725016
A32: =VLOOKUP(B32,'PORTFOLIO RAW'!B:B,1,FALSE) -> 14737P | B32: 14737P | C32: ANTHEM INC - NET INCOME - BASIC | D32: 14737P(WC01706) | E32: 3345400 | F32: 2490700 | G32: 4745900 | H32: 2887100 | I32: 2646700 | J32: 2655500 | K32: 2489700 | L32: 2569700 | M32: 2560000 | N32: 2469800 | O32: 2734500
A33: =VLOOKUP(B33,'PORTFOLIO RAW'!B:B,1,FALSE) -> 922817 | B33: 922817 | C33: AON PLC - NET INCOME - BASIC | D33: 922817(WC01706) | E33: 864000 | F33: 651000 | G33: 639000 | H33: 733000 | I33: 975000 | J33: 993000 | K33: 1113000 | L33: 1397000 | M33: 1385000 | N33: 1396000 | O33: 1576000
A34: =VLOOKUP(B34,'PORTFOLIO RAW'!B:B,1,FALSE) -> 921983 | B34: 921983 | C34: APACHE CORPORATION - NET INCOME - BASIC | D34: 921983(WC01706) | E34: 2806678 | F34: 706274 | G34: -291692 | H34: 3000000 | I34: 4508000 | J34: 1925000 | K34: 2188000 | L34: -5403000 | M34: -23119000 | N34: -1405000 | O34: 1417000
A35: =VLOOKUP(B35,'PORTFOLIO RAW'!B:B,1,FALSE) -> 992816 | B35: 992816 | C35: APPLE INC - NET INCOME - BASIC | D35: 992816(WC01706) | E35: 3496000 | F35: 4834000 | G35: 8235000 | H35: 14013000 | I35: 25922000 | J35: 41733000 | K35: 37037000 | L35: 39510000 | M35: 53394000 | N35: 45687000 | O35: 48351000
A36: =VLOOKUP(B36,'PORTFOLIO RAW'!B:B,1,FALSE) -> 905296 | B36: 905296 | C36: APPLIED MATERIALS - NET INCOME - BASIC | D36: 905296(WC01706) | E36: 1710196 | F36: 960746 | G36: -305327 | H36: 937866 | I36: 1926000 | J36: 109000 | K36: 256000 | L36: 1072000 | M36: 1377000 | N36: 1721000 | O36: 3434000
A37: =VLOOKUP(B37,'PORTFOLIO RAW'!B:B,1,FALSE) -> 132808 | B37: 132808 | C37: APT INVESTMENT & MGT - NET INCOME - BASIC | D37: 132808(WC01706) | E37: -114070 | F37: 361755 | G37: -114840 | H37: -125318 | I37: -103161 | J37: 82146 | K37: 203673 | L37: 11584 | M37: 55373 | N37: 23991 | O37: -8592
A38: =VLOOKUP(B38,'PORTFOLIO RAW'!B:B,1,FALSE) -> 921093 | B38: 921093 | C38: ARCHER DANIELS MIDL. - NET INCOME - BASIC | D38: 921093(WC01706) | E38: 2162000 | F38: 1802000 | G38: 1707000 | H38: 1930000 | I38: 2036000 | J38: 1146000 | K38: 1342000 | L38: 2248000 | M38: 1849000 | N38: 1279000 | O38: 1216000
A39: =VLOOKUP(B39,'PORTFOLIO RAW'!B:B,1,FALSE) -> 905113 | B39: 905113 | C39: ARCONIC INC - NET INCOME - BASIC | D39: 905113(WC01706) | E39: 2569000 | F39: -76000 | G39: -1153000 | H39: 253000 | I39: 608000 | J39: 189000 | K39: -2287000 | L39: 247000 | M39: -391000 | N39: -1010000 | O39: 145000
A40: =VLOOKUP(B40,'PORTFOLIO RAW'!B:B,1,FALSE) -> 28341F | B40: 28341F | C40: ASSURANT INC - NET INCOME - BASIC | D40: 28341F(WC01706) | E40: 653746 | F40: 447796 | G40: 430574 | H40: 279177 | I40: 545839 | J40: 483705 | K40: 488907 | L40: 470907 | M40: 141555 | N40: 565350 | O40: 342600
...

Sheet EBITDA
A1: EBITDA
B2: Code | C2: Name | D2: Code | E2: 2007 | F2: 2008 | G2: 2009 | H2: 2010 | I2: 2011 | J2: 2012 | K2: 2013 | L2: 2014 | M2: 2015 | N2: 2016 | O2: 2017
A3: =VLOOKUP(B3,'PORTFOLIO RAW'!B:B,1,FALSE) -> 891399 | B3: 891399 | C3: AMAZON.COM INC - EBIT & DEPRECIATION | D3: 891399(WC18198) | E3: 1008000 | F3: 1312000 | G3: 1627000 | H3: 2193000 | I3: 2148000 | J3: 2795000 | K3: 3900000 | L3: 4845000 | M3: 8308000 | N3: 12492000 | O3: 16132000
A4: =VLOOKUP(B4,'PORTFOLIO RAW'!B:B,1,FALSE) -> 916328 | B4: 916328 | C4: ABBOTT LABORATORIES - EBIT & DEPRECIATION | D4: 916328(WC18198) | E4: 6419660 | F4: 8104592 | G4: 9493940 | H4: 9138274 | I4: 9260677 | J4: 9638224 | K4: 4299000 | L4: 4216000 | M4: 4818000 | N4: 3197000 | O4: 6156000
A5: =VLOOKUP(B5,'PORTFOLIO RAW'!B:B,1,FALSE) -> 545101 | B5: 545101 | C5: AES CORP - EBIT & DEPRECIATION | D5: 545101(WC18198) | E5: 4268000 | F5: 5596000 | G5: 4790000 | H5: 3622000 | I5: 5044000 | J5: 3280000 | K5: 3783000 | L5: 4294000 | M5: 3705000 | N5: 2744000 | O5: 3110000
A6: =VLOOKUP(B6,'PORTFOLIO RAW'!B:B,1,FALSE) -> 906187 | B6: 906187 | C6: INT'L BUSINESS MACHS - EBIT & DEPRECIATION | D6: 906187(WC18198) | E6: 20301000 | F6: 22838000 | G6: 23630000 | H6: 25025000 | I6: 26328000 | J6: 27048000 | K6: 24533000 | L6: 25168000 | M6: 20375000 | N6: 17449000 | O6: 16590000
A7: =VLOOKUP(B7,'PORTFOLIO RAW'!B:B,1,FALSE) -> 936365 | B7: 936365 | C7: ADVANCED MICRO - EBIT & DEPRECIATION | D7: 936365(WC18198) | E7: -1494000 | F7: -671000 | G7: 1974000 | H7: 1553000 | I7: 496000 | J7: -782000 | K7: 339000 | L7: -18000 | M7: -319000 | N7: -159000 | O7: 339000
A8: =VLOOKUP(B8,'PORTFOLIO RAW'!B:B,1,FALSE) -> 749382 | B8: 749382 | C8: ADOBE INC - EBIT & DEPRECIATION | D8: 749382(WC18198) | E8: 1262907 | F8: 1358796 | G8: 987350 | H8: 1264303 | I8: 1372387 | J8: 1486047 | K8: 744876 | L8: 734698 | M8: 1277438 | N8: 1837115 | O8: 2538040
A9: =VLOOKUP(B9,'PORTFOLIO RAW'!B:B,1,FALSE) -> 905271 | B9: 905271 | C9: AIR PRODUCTS & CHEMS - EBIT & DEPRECIATION | D9: 905271(WC18198) | E9: 2247700 | F9: 2364800 | G9: 1686600 | H9: 2252400 | I9: 2504300 | J9: 2129000 | K9: 2231400 | L9: 2280100 | M9: 2610900 | N9: 3016200 | O9: 2307700
A10: =VLOOKUP(B10,'PORTFOLIO RAW'!B:B,1,FALSE) -> 894371 | B10: 894371 | C10: BOSTON PROPERTIES - EBIT & DEPRECIATION | D10: 894371(WC18198) | E10: 1717571 | F10: 907372 | G10: 906955 | H10: 870003 | I10: 1061245 | J10: 1111776 | K10: 1640851 | L10: 1597604 | M10: 1848886 | N10: 1669155 | O10: 1543277
A11: =VLOOKUP(B11,'PORTFOLIO RAW'!B:B,1,FALSE) -> 322677 | B11: 322677 | C11: ALLSTATE CORP - EBIT & DEPRECIATION | D11: 322677(WC18198) | E11: 6917000 | F11: -2496000 | G11: 1879000 | H11: 1692000 | I11: 1491000 | J11: 3719000 | K11: 4131000 | L11: 4924000 | M11: 3945000 | N11: 3431000 | O11: 4809000
A12: =VLOOKUP(B12,'PORTFOLIO RAW'!B:B,1,FALSE) -> 906191 | B12: 906191 | C12: HONEYWELL INTERNATNL - EBIT & DEPRECIATION | D12: 906191(WC18198) | E12: 4604000 | F12: 5097000 | G12: 4368000 | H12: 4211000 | I12: 3676000 | J12: 5119000 | K12: 6711000 | L12: 7045000 | M12: 7779000 | N12: 7806000 | O12: 8294000
A13: =VLOOKUP(B13,'PORTFOLIO RAW'!B:B,1,FALSE) -> 938692 | B13: 938692 | C13: AMGEN INC - EBIT & DEPRECIATION | D13: 938692(WC18198) | E13: 5437000 | F13: 6567000 | G13: 6830000 | H13: 6937000 | I13: 5819000 | J13: 7150000 | K13: 8595000 | L13: 9809000 | M13: 11184000 | N13: 12542000 | O13: 12856000
A14: =VLOOKUP(B14,'PORTFOLIO RAW'!B:B,1,FALSE) -> 905802 | B14: 905802 | C14: HESS CORPORATION - EBIT & DEPRECIATION | D14: 905802(WC18198) | E14: 5360000 | F14: 6952000 | G14: 4313000 | H14: 6511000 | I14: 6323000 | J14: 7106000 | K14: 7669000 | L14: 5983000 | M14: 38000 | N14: -272000 | O14: -2570000
... A28: =VLOOKUP(B28,'PORTFOLIO RAW'!B:B,1,FALSE) -> 670942 | B28: 670942 | C28: AMEREN CORPORATION - EBIT & DEPRECIATION | D28: 670942(WC18198) | E28: 2176000 | F28: 2125000 | G28: 2229000 | H28: 1758000 | I28: 2061000 | J28: -424000 | K28: 1933000 | L28: 2056000 | M28: 2099000 | N28: 2268000 | O28: 2392000
A29: =VLOOKUP(B29,'PORTFOLIO RAW'!B:B,1,FALSE) -> 702259 | B29: 702259 | C29: AUTODESK INC - EBIT & DEPRECIATION | D29: 702259(WC18198) | E29: 534700 | F29: 344300 | G29: 196200 | H29: 377400 | I29: 478400 | J29: NA | K29: 418600 | L29: 242100 | M29: 159400 | N29: -337400 | O29: -395100
A30: =VLOOKUP(B30,'PORTFOLIO RAW'!B:B,1,FALSE) -> 912669 | B30: 912669 | C30: AUTOMATIC DATA PROC - EBIT & DEPRECIATION | D30: 912669(WC18198) | E30: 2007200 | F30: 2211600 | G30: 2246100 | H30: 2181000 | I30: 2259500 | J30: 2453100 | K30: 2410400 | L30: 2616900 | M30: 2355100 | N30: 2579500 | O30: 2927200
A31: =VLOOKUP(B31,'PORTFOLIO RAW'!B:B,1,FALSE) -> 544616 | B31: 544616 | C31: AUTOZONE INC - EBIT & DEPRECIATION | D31: 544616(WC18198) | E31: 1217496 | F31: 1297428 | G31: 1360382 | H31: 1514124 | I31: 1693070 | J31: 1842119 | K31: 2001955 | L31: 2083340 | M31: 2224575 | N31: 2360163 | O31: 2406622
A32: =VLOOKUP(B32,'PORTFOLIO RAW'!B:B,1,FALSE) -> 921161 | B32: 921161 | C32: AVERY DENNISON CORP - EBIT & DEPRECIATION | D32: 921161(WC18198) | E32: 715100 | F32: 664900 | G32: -445200 | H32: 670700 | I32: 546200 | J32: 548900 | K32: 626800 | L32: 629400 | M32: 657800 | N32: 713500 | O32: 826300
A33: =VLOOKUP(B33,'PORTFOLIO RAW'!B:B,1,FALSE) -> 932060 | B33: 932060 | C33: BALL CORPORATION - EBIT & DEPRECIATION | D33: 932060(WC18198) | E33: 794900 | F33: 887900 | G33: 931700 | H33: 1016400 | I33: 1138000 | J33: 1073400 | K33: 1067300 | L33: 1086400 | M33: 774200 | N33: 807000 | O33: 1528000
A34: =VLOOKUP(B34,'PORTFOLIO RAW'!B:B,1,FALSE) -> 874227 | B34: 874227 | C34: BERKSHIRE HATHAWAY - EBIT & DEPRECIATION | D34: 874227(WC18198) | E34: 24478000 | F34: 12347000 | G34: 16671000 | H34: 25888000 | I34: 22661000 | J34: 30126000 | K34: 38105000 | L34: 38728000 | M34: 46240000 | N34: 45142000 | O34: 35482000
A35: =VLOOKUP(B35,'PORTFOLIO RAW'!B:B,1,FALSE) -> 916365 | B35: 916365 | C35: BAXTER INTERNATIONAL - EBIT & DEPRECIATION | D35: 916365(WC18198) | E35: 2846000 | F35: 3255000 | G35: 3418000 | H35: 2779000 | I35: 3637000 | J35: 3698000 | K35: 3503000 | L35: 3611000 | M35: 1333000 | N35: 5843000 | O35: 2063000
A36: =VLOOKUP(B36,'PORTFOLIO RAW'!B:B,1,FALSE) -> 905876 | B36: 905876 | C36: BECTON, DICKINSON - EBIT & DEPRECIATION | D36: 905876(WC18198) | E36: 1691706 | F36: 2067372 | G36: 2143456 | H36: 2207692 | I36: 2299698 | J36: 2105920 | K36: 1850000 | L36: 2219000 | M36: 2001000 | N36: 2576000 | O36: 2588000
A37: =VLOOKUP(B37,'PORTFOLIO RAW'!B:B,1,FALSE) -> 945384 | B37: 945384 | C37: VERIZON COMMUNICATNS - EBIT & DEPRECIATION | D37: 945384(WC18198) | E37: 30166000 | F37: 31731000 | G37: 30649000 | H37: 31002000 | I37: 29362000 | J37: 28604000 | K37: 48408000 | L37: 34938000 | M37: 49263000 | N37: 41388000 | O37: 42134000
A38: =VLOOKUP(B38,'PORTFOLIO RAW'!B:B,1,FALSE) -> 929302 | B38: 929302 | C38: BEST BUY CO INC - EBIT & DEPRECIATION | D38: 929302(WC18198) | E38: 2670000 | F38: 2870000 | G38: 2587000 | H38: 3215000 | I38: 3143000 | J38: 940820 | K38: 1903000 | L38: 2133000 | M38: 2047000 | N38: 2542000 | O38: 2575000
A39: =VLOOKUP(B39,'PORTFOLIO RAW'!B:B,1,FALSE) -> 895784 | B39: 895784 | C39: SL GREEN REALTY CORP - EBIT & DEPRECIATION | D39: 895784(WC18198) | E39: 598725 | F39: 547709 | G39: 500310 | H39: 724810 | I39: 1218024 | J39: 783663 | K39: 816231 | L39: 933469 | M39: 1216001 | N39: 1417949 | O39: 758011
A40: =VLOOKUP(B40,'PORTFOLIO RAW'!B:B,1,FALSE) -> 878574 | B40: 878574 | C40: YUM! BRANDS INC - EBIT & DEPRECIATION | D40: 878574(WC18198) | E40: 1881000 | F40: 2119000 | G40: 2084000 | H40: 2369000 | I40: 2448000 | J40: 2932000 | K40: 2516000 | L40: 2288000 | M40: 2648000 | N40: 1960000 | O40: 3000000
A41: =VLOOKUP(B41,'PORTFOLIO RAW'!B:B,1,FALSE) -> 905159 | B41: 905159 | C41: FIRSTENERGY CORP - EBIT & DEPRECIATION | D41: 905159(WC18198) | E41: 3573000 | F41: 3498000 | G41: 2819000 | H41: 2657000 | I41: 3502000 | J41: 3377000 | K41: 2813000 | L41: 2426000 | M41: 3884000 | N41: -6751000 | O41: 1423000
... A43: =VLOOKUP(B43,'PORTFOLIO RAW'!B:B,1,FALSE) -> 904818 | B43: 904818 | C43: BOEING CO - EBIT & DEPRECIATION | D43: 904818(WC18198) | E43: 7908000 | F43: 5670000 | G43: 3662000 | H43: 6643000 | I43: 7401000 | J43: 8004000 | K43: 8462000 | L43: 9376000 | M43: 9263000 | N43: 7784000 | O43: 12476000
A44: =VLOOKUP(B44,'PORTFOLIO RAW'!B:B,1,FALSE) -> 923649 | B44: 923649 | C44: ROBERT HALF INTL INC - EBIT & DEPRECIATION | D44: 923649(WC18198) | E44: 565945 | F44: 497786 | G44: 132529 | H44: 171726 | I44: 301631 | J44: 392969 | K44: NA | L44: NA | M44: NA | N44: NA | O44: NA
A45: =VLOOKUP(B45,'PORTFOLIO RAW'!B:B,1,FALSE) -> 325824 | B45: 325824 | C45: BOSTON SCIENTIFIC - EBIT & DEPRECIATION | D45: 325824(WC18198) | E45: 940000 | F45: -699000 | G45: -61000 | H45: 146000 | I45: 1641000 | J45: -3161000 | K45: 790000 | L45: 432000 | M45: 403000 | N45: 1225000 | O45: 2006000
A46: =VLOOKUP(B46,'PORTFOLIO RAW'!B:B,1,FALSE) -> 879628 | B46: 879628 | C46: C.H. ROBINSON - EBIT & DEPRECIATION | D46: 879628(WC18198) | E46: 550880 | F46: 609551 | G46: 617575 | H46: 653471 | I46: 727202 | J46: NA | K46: 741343 | L46: 805427 | M46: 931919 | N46: 912200 | O46: 868096
A47: =VLOOKUP(B47,'PORTFOLIO RAW'!B:B,1,FALSE) -> 905080 | B47: 905080 | C47: BRISTOL-MYERS SQUIBB - EBIT & DEPRECIATION | D47: 905080(WC18198) | E47: 4324000 | F47: 5980000 | G47: 6086000 | H47: 6808000 | I47: 7646000 | J47: 3328000 | K47: 4235000 | L47: 3306000 | M47: 2861000 | N47: 6675000 | O47: 6109000
A48: =VLOOKUP(B48,'PORTFOLIO RAW'!B:B,1,FALSE) -> 130502 | B48: 130502 | C48: AVALONBAY COMMUNITIE - EBIT & DEPRECIATION | D48: 130502(WC18198) | E48: 467178 | F48: 418099 | G48: 435041 | H48: 505086 | I48: 575663 | J48: 636788 | K48: 801598 | L48: 1143050 | M48: 1327114 | N48: 1687995 | O48: 1589868
A49: =VLOOKUP(B49,'PORTFOLIO RAW'!B:B,1,FALSE) -> 902103 | B49: 902103 | C49: SEMPRA ENERGY - EBIT & DEPRECIATION | D49: 902103(WC18198) | E49: 2517000 | F49: 2018000 | G49: 2618000 | H49: 2381000 | I49: 3155000 | J49: 2845000 | K49: 3063000 | L49: 3161000 | M49: 3421000 | N49: 3072000 | O49: 3699000
A50: =VLOOKUP(B50,'PORTFOLIO RAW'!B:B,1,FALSE) -> 951849 | B50: 951849 | C50: FEDEX CORP - EBIT & DEPRECIATION | D50: 951849(WC18198) | E50: 5093000 | F50: 4060000 | G50: 2737000 | H50: 3931000 | I50: 4324000 | J50: 5306000 | K50: 4923000 | L50: 6072000 | M50: 4473000 | N50: 5707000 | O50: 8086000
A51: =VLOOKUP(B51,'PORTFOLIO RAW'!B:B,1,FALSE) -> 674693 | B51: 674693 | C51: VERISIGN, INC. - EBIT & DEPRECIATION | D51: 674693(WC18198) | E51: 121127 | F51: 292344 | G51: 414907 | H51: 320676 | I51: 396625 | J51: 517710 | K51: 609988 | L51: 632995 | M51: 670902 | N51: 754904 | O51: 786119
A52: =VLOOKUP(B52,'PORTFOLIO RAW'!B:B,1,FALSE) -> 546075 | B52: 546075 | C52: AMPHENOL CORP - EBIT & DEPRECIATION | D52: 546075(WC18198) | E52: 630726 | F52: 723509 | G52: 581637 | H52: 807275 | I52: 879220 | J52: 960233 | K52: 1046680 | L52: 1221000 | M52: 1292700 | N52: 1430700 | O52: 1671500
A53: =VLOOKUP(B53,'PORTFOLIO RAW'!B:B,1,FALSE) -> 912216 | B53: 912216 | C53: BROWN FORMAN CORP - EBIT & DEPRECIATION | D53: 912216(WC18198) | E53: 664000 | F53: 745000 | G53: 722000 | H53: 772000 | I53: 917000 | J53: 843000 | K53: 952000 | L53: 1023000 | M53: 1080000 | N53: 1591000 | O53: 1050000
A54: =VLOOKUP(B54,'PORTFOLIO RAW'!B:B,1,FALSE) -> 993189 | B54: 993189 | C54: CSX CORPORATION - EBIT & DEPRECIATION | D54: 993189(WC18198) | E54: 3239000 | F54: 3583000 | G54: 3226000 | H54: 4050000 | I54: 4416000 | J54: 4589000 | K54: 4588000 | L54: 4740000 | M54: 4890000 | N54: 4621000 | O54: 4784000
...

Sheet EQIT
A1: Equity
B2: Code | C2: Name | D2: Code | E2: 2007 | F2: 2008 | G2: 2009 | H2: 2010 | I2: 2011 | J2: 2012 | K2: 2013 | L2: 2014 | M2: 2015 | N2: 2016 | O2: 2017
A3: =VLOOKUP(B3,'PORTFOLIO RAW'!B:B,1,FALSE) -> 891399 | B3: 891399 | C3: AMAZON.COM INC - COMMON SHAREHOLDERS' EQUITY | D3: 891399(WC03501) | E3: 1197000 | F3: 2672000 | G3: 5257000 | H3: 6864000 | I3: 7757000 | J3: 8192000 | K3: 9746000 | L3: 10741000 | M3: 13384000 | N3: 19285000 | O3: 27709000
A4: =VLOOKUP(B4,'PORTFOLIO RAW'!B:B,1,FALSE) -> 916328 | B4: 916328 | C4: ABBOTT LABORATORIES - COMMON SHAREHOLDERS' EQUITY | D4: 916328(WC03501) | E4: 17778540 | F4: 17479551 | G4: 22855627 | H4: 22388135 | I4: 24439833 | J4: 26720961 | K4: 25171000 | L4: 21526000 | M4: 21211000 | N4: 20538000 | O4: 30897000
A5: =VLOOKUP(B5,'PORTFOLIO RAW'!B:B,1,FALSE) -> 545101 | B5: 545101 | C5: AES CORP - COMMON SHAREHOLDERS' EQUITY | D5: 545101(WC03501) | E5: 3164000 | F5: 3669000 | G5: 4675000 | H5: 6473000 | I5: 5946000 | J5: 4569000 | K5: 4330000 | L5: 4272000 | M5: 3149000 | N5: 2794000 | O5: 2465000
A6: =VLOOKUP(B6,'PORTFOLIO RAW'!B:B,1,FALSE) -> 906187 | B6: 906187 | C6: INT'L BUSINESS MACHS - COMMON SHAREHOLDERS' EQUITY | D6: 906187(WC03501) | E6: 28469000 | F6: 13465000 | G6: 22637000 | H6: 23046000 | I6: 20139000 | J6: 18860000 | K6: 22792000 | L6: 11869000 | M6: 14262000 | N6: 18246000 | O6: 17594000
A7: =VLOOKUP(B7,'PORTFOLIO RAW'!B:B,1,FALSE) -> 936365 | B7: 936365 | C7: ADVANCED MICRO - COMMON SHAREHOLDERS' EQUITY | D7: 936365(WC03501) | E7: 2990000 | F7: -82000 | G7: 648000 | H7: 1013000 | I7: 1590000 | J7: 538000 | K7: 544000 | L7: 187000 | M7: -412000 | N7: 416000 | O7: 611000
A8: =VLOOKUP(B8,'PORTFOLIO RAW'!B:B,1,FALSE) -> 749382 | B8: 749382 | C8: ADOBE INC - COMMON SHAREHOLDERS' EQUITY | D8: 749382(WC03501) | E8: 4649982 | F8: 4410354 | G8: 4890568 | H8: 5192387 | I8: 5783113 | J8: 6665182 | K8: 6724634 | L8: 6775905 | M8: 7001580 | N8: 7424835 | O8: 8459869
A9: =VLOOKUP(B9,'PORTFOLIO RAW'!B:B,1,FALSE) -> 905271 | B9: 905271 | C9: AIR PRODUCTS & CHEMS - COMMON SHAREHOLDERS' EQUITY | D9: 905271(WC03501) | E9: 5495600 | F9: 5030700 | G9: 4791900 | H9: 5546900 | I9: 5795800 | J9: 6477200 | K9: 7042100 | L9: 7365800 | M9: 7249000 | N9: 7079600 | O9: 10086200
A10: =VLOOKUP(B10,'PORTFOLIO RAW'!B:B,1,FALSE) -> 894371 | B10: 894371 | C10: BOSTON PROPERTIES - COMMON SHAREHOLDERS' EQUITY | D10: 894371(WC03501) | E10: 3668825 | F10: 3531267 | G10: 4446002 | H10: 4372643 | I10: 4865998 | J10: 5097065 | K10: 5541153 | L10: 5697298 | M10: 5709435 | N10: 5586295 | O10: 5613957
A11: =VLOOKUP(B11,'PORTFOLIO RAW'!B:B,1,FALSE) -> 322677 | B11: 322677 | C11: ALLSTATE CORP - COMMON SHAREHOLDERS' EQUITY | D11: 322677(WC03501) | E11: 20963000 | F11: 16379000 | G11: 17562000 | H11: 18081000 | I11: 17311000 | J11: 17746000 | K11: 19054000 | L11: 18632000 | M11: 17600000 | N11: 17715000 | O11: 19084000
A12: =VLOOKUP(B12,'PORTFOLIO RAW'!B:B,1,FALSE) -> 906191 | B12: 906191 | C12: HONEYWELL INTERNATNL - COMMON SHAREHOLDERS' EQUITY | D12: 906191(WC03501) | E12: 9222000 | F12: 7187000 | G12: 8844000 | H12: 10666000 | I12: 10806000 | J12: 12975000 | K12: 17467000 | L12: 17657000 | M12: 18283000 | N12: 19369000 | O12: 17276000
A13: =VLOOKUP(B13,'PORTFOLIO RAW'!B:B,1,FALSE) -> 938692 | B13: 938692 | C13: AMGEN INC - COMMON SHAREHOLDERS' EQUITY | D13: 938692(WC03501) | E13: 17869000 | F13: 20386000 | G13: 22667000 | H13: 23944000 | I13: 19029000 | J13: 19060000 | K13: 22096000 | L13: 25778000 | M13: 28083000 | N13: 29875000 | O13: 25241000
A14: =VLOOKUP(B14,'PORTFOLIO RAW'!B:B,1,FALSE) -> 905802 | B14: 905802 | C14: HESS CORPORATION - COMMON SHAREHOLDERS' EQUITY | D14: 905802(WC03501) | E14: 9760000 | F14: 12307000 | G14: 13384000 | H14: 16689000 | I14: 18516000 | J14: 21090000 | K14: 24720000 | L14: 22205000 | M14: 19386000 | N14: 14533000 | O14: 11050000
... A109: =VLOOKUP(B109,'PORTFOLIO RAW'!B:B,1,FALSE) -> 905016 | B109: 905016 | C109: NEXTERA ENERGY - COMMON SHAREHOLDERS' EQUITY | D109: 905016(WC03501) | E109: 10735000 | F109: 11681000 | G109: 12967000 | H109: 14461000 | I109: 14943000 | J109: 16068000 | K109: 18040000 | L109: 19916000 | M109: 22574000 | N109: 24341000 | O109: 28208000
A110: =VLOOKUP(B110,'PORTFOLIO RAW'!B:B,1,FALSE) -> 28341F | B110: 28341F | C110: ASSURANT INC - COMMON SHAREHOLDERS' EQUITY | D110: 28341F(WC03501) | E110: 4065519 | F110: 4187905 | G110: 4658699 | H110: 4367282 | I110: 4313163 | J110: 5185366 | K110: 4280981 | L110: 4361631 | M110: 4006090 | N110: 3618201 | O110: 3671500
A111: =VLOOKUP(B111,'PORTFOLIO RAW'!B:B,1,FALSE) -> 755980 | B111: 755980 | C111: FASTENAL COMPANY - COMMON SHAREHOLDERS' EQUITY | D111: 755980(WC03501) | E111: 1010161 | F111: 1142259 | G111: 1190843 | H111: 1282512 | I111: 1458976 | J111: 1560360 | K111: 1772697 | L111: 1915217 | M111: 1801289 | N111: 1933094 | O111: 2096900
A112: =VLOOKUP(B112,'PORTFOLIO RAW'!B:B,1,FALSE) -> 905994 | B112: 905994 | C112: FEDERAL REALTY INVST - COMMON SHAREHOLDERS' EQUITY | D112: 905994(WC03501) | E112: 1105438 | F112: 1104605 | G112: 1167340 | H112: 1139836 | I112: 1206095 | J112: 1276815 | K112: 1438163 | L112: 1594404 | M112: 1653752 | N112: 1966736 | O112: 2106709
A113: =VLOOKUP(B113,'PORTFOLIO RAW'!B:B,1,FALSE) -> 997198 | B113: 997198 | C113: FIFTH THIRD BANCORP - COMMON SHAREHOLDERS' EQUITY | D113: 997198(WC03501) | E113: 9152000 | F113: 7836000 | G113: 9678000 | H113: 10232000 | I113: 12790000 | J113: 13305000 | K113: 13555000 | L113: 14295000 | M113: 14508000 | N113: 14874000 | O113: 15034000
A114: =VLOOKUP(B114,'PORTFOLIO RAW'!B:B,1,FALSE) -> 951503 | B114: 951503 | C114: M&T BANK CORPORATION - COMMON SHAREHOLDERS' EQUITY | D114: 951503(WC03501) | E114: 6485256 | F114: 6184731 | G114: 6974907 | H114: 7579695 | I114: 8406624 | J114: 9321093 | K114: 10424032 | L114: 11104396 | M114: 14941789 | N114: 15255122 | O114: 15019319
A115: =VLOOKUP(B115,'PORTFOLIO RAW'!B:B,1,FALSE) -> 741123 | B115: 741123 | C115: FISERV INC - COMMON SHAREHOLDERS' EQUITY | D115: 741123(WC03501) | E115: 2467000 | F115: 2594000 | G115: 3026000 | H115: 3229000 | I115: 3258000 | J115: 3417000 | K115: 3585000 | L115: 3295000 | M115: 2660000 | N115: 2541000 | O115: 2731000
A116: =VLOOKUP(B116,'PORTFOLIO RAW'!B:B,1,FALSE) -> 546814 | B116: 546814 | C116: MACY'S INC - COMMON SHAREHOLDERS' EQUITY | D116: 546814(WC03501) | E116: 9907000 | F116: 4646000 | G116: 4701000 | H116: 5530000 | I116: 5933000 | J116: 6051000 | K116: 6249000 | L116: 5378000 | M116: 4250000 | N116: 4323000 | O116: 5673000
A117: =VLOOKUP(B117,'PORTFOLIO RAW'!B:B,1,FALSE) -> 938076 | B117: 938076 | C117: FRANKLIN RESOURCES - COMMON SHAREHOLDERS' EQUITY | D117: 938076(WC03501) | E117: 7332275 | F117: 7074364 | G117: 7632173 | H117: 7726994 | I117: 8524731 | J117: 9201300 | K117: 10073100 | L117: 11584100 | M117: 11841000 | N117: 11935800 | O117: 12620000
A118: =VLOOKUP(B118,'PORTFOLIO RAW'!B:B,1,FALSE) -> 152594 | B118: 152594 | C118: FREEPORT-MCMORAN INC - COMMON SHAREHOLDERS' EQUITY | D118: 152594(WC03501) | E118: 14259000 | F118: 2066000 | G118: 6244000 | H118: 12504000 | I118: 15642000 | J118: 17543000 | K118: 20934000 | L118: 18287000 | M118: 7828000 | N118: 6051000 | O118: 7977000
A119: =VLOOKUP(B119,'PORTFOLIO RAW'!B:B,1,FALSE) -> 951018 | B119: 951018 | C119: GAP INC - COMMON SHAREHOLDERS' EQUITY | D119: 951018(WC03501) | E119: 4274000 | F119: 4387000 | G119: 4891000 | H119: 4080000 | I119: 2755000 | J119: 2894000 | K119: 3062000 | L119: 2983000 | M119: 2545000 | N119: 2904000 | O119: 3144000
A120: =VLOOKUP(B120,'PORTFOLIO RAW'!B:B,1,FALSE) -> 907652 | B120: 907652 | C120: GENERAL DYNAMICS - COMMON SHAREHOLDERS' EQUITY | D120: 907652(WC03501) | E120: 11768000 | F120: 10053000 | G120: 12423000 | H120: 13316000 | I120: 13232000 | J120: 11390000 | K120: 14501000 | L120: 11829000 | M120: 10738000 | N120: 10976000 | O120: 11435000
A121: =VLOOKUP(B121,'PORTFOLIO RAW'!B:B,1,FALSE) -> 905801 | B121: 905801 | C121: GENERAL MILLS, INC. - COMMON SHAREHOLDERS' EQUITY | D121: 905801(WC03501) | E121: 5319000 | F121: 6215800 | G121: 5174700 | H121: 5402900 | I121: 6365500 | J121: 6421700 | K121: 6672200 | L121: 6534800 | M121: 4996700 | N121: 4930200 | O121: 4327900
A122: =VLOOKUP(B122,'PORTFOLIO RAW'!B:B,1,FALSE) -> 906511 | B122: 906511 | C122: GENUINE PARTS CO - COMMON SHAREHOLDERS' EQUITY | D122: 906511(WC03501) | E122: 2716716 | F122: 2324332 | G122: 2621330 | H122: 2793819 | I122: 2783235 | J122: 2997887 | K122: 3349074 | L122: 3301248 | M122: 3146567 | N122: 3193728 | O122: 3412152
... A236: =VLOOKUP(B236,'PORTFOLIO RAW'!B:B,1,FALSE) -> 933974 | B236: 933974 | C236: TRAVELERS COS - COMMON SHAREHOLDERS' EQUITY | D236: 933974(WC03501) | E236: 25885000 | F236: 25374000 | G236: 25475000 | H236: 23549000 | I236: 21606000 | J236: 22302000 | K236: 23474000 | L236: 22870000 | M236: 22309000 | N236: 22491000 | O236: 22777000
A237: =VLOOKUP(B237,'PORTFOLIO RAW'!B:B,1,FALSE) -> 14015T | B237: 14015T | C237: FIDELITY NATNL INF - COMMON SHAREHOLDERS' EQUITY | D237: 14015T(WC03501) | E237: 3781179 | F237: 3532800 | G237: 8308900 | H237: 6403200 | I237: 6503000 | J237: 6640900 | K237: 6580500 | L237: 6556700 | M237: 9321000 | N237: 9741000 | O237: 10835000
A238: =VLOOKUP(B238,'PORTFOLIO RAW'!B:B,1,FALSE) -> 905019 | B238: 905019 | C238: MERCK & CO INC - COMMON SHAREHOLDERS' EQUITY | D238: 905019(WC03501) | E238: 18184700 | F238: 18758300 | G238: 59058000 | H238: 54376000 | I238: 54517000 | J238: 53020000 | K238: 49765000 | L238: 48647000 | M238: 44676000 | N238: 40088000 | O238: 34336000
A239: =VLOOKUP(B239,'PORTFOLIO RAW'!B:B,1,FALSE) -> 912090 | B239: 912090 | C239: SCHLUMBERGER LIMITED - COMMON SHAREHOLDERS' EQUITY | D239: 912090(WC03501) | E239: 14876000 | F239: 16863000 | G239: 19120000 | H239: 31226000 | I239: 31263000 | J239: 34751000 | K239: 39469000 | L239: 37850000 | M239: 35633000 | N239: 41078000 | O239: 36842000
A240: =VLOOKUP(B240,'PORTFOLIO RAW'!B:B,1,FALSE) -> 755741 | B240: 755741 | C240: CHARLES SCHWAB CORP - COMMON SHAREHOLDERS' EQUITY | D240: 755741(WC03501) | E240: 3732000 | F240: 4061000 | G240: 5073000 | H240: 6226000 | I240: 7714000 | J240: 8704000 | K240: 9496000 | L240: 10918000 | M240: 11917000 | N240: 13586000 | O240: 15675000
A241: =VLOOKUP(B241,'PORTFOLIO RAW'!B:B,1,FALSE) -> 14361V | B241: 14361V | C241: ZIMMER BIOMET - COMMON SHAREHOLDERS' EQUITY | D241: 14361V(WC03501) | E241: 5449600 | F241: 5650300 | G241: 5638700 | H241: 5771300 | I241: 5507200 | J241: 5860900 | K241: 6297300 | L241: 6520800 | M241: 9887900 | N241: 9668900 | O241: 11735800
A242: =VLOOKUP(B242,'PORTFOLIO RAW'!B:B,1,FALSE) -> 154680 | B242: 154680 | C242: AMERISOURCEBERGEN - COMMON SHAREHOLDERS' EQUITY | D242: 154680(WC03501) | E242: 3099720 | F242: 2710045 | G242: 2716469 | H242: 2954297 | I242: 2866858 | J242: 2456712 | K242: 2319745 | L242: 1956899 | M242: 633520 | N242: 2129404 | O242: 2064461
A243: =VLOOKUP(B243,'PORTFOLIO RAW'!B:B,1,FALSE) -> 14698C | B243: 14698C | C243: PRINCIPAL FINL GROUP - COMMON SHAREHOLDERS' EQUITY | D243: 14698C(WC03501) | E243: 6854600 | F243: 6393600 | G243: 8284000 | H243: 9045100 | I243: 8709200 | J243: 8267500 | K243: 9434200 | L243: 10183900 | M243: 9311600 | N243: 10227300 | O243: 11335900
A244: =VLOOKUP(B244,'PORTFOLIO RAW'!B:B,1,FALSE) -> 905361 | B244: 905361 | C244: SHERWIN-WILLIAMS CO - COMMON SHAREHOLDERS' EQUITY | D244: 905361(WC03501) | E244: 1785727 | F244: 1605648 | G244: 1490950 | H244: 1609440 | I244: 1516919 | J244: 1690718 | K244: 1734129 | L244: 996470 | M244: 867910 | N244: 1878441 | O244: 3692188
